Workbook

Sheet PL
A1: Date | B1: Day | C1: CRUDEOIL DTE | D1: NATURALGAS DTE | E1: CRUDEOIL B120_1 | F1: CRUDEOIL B120_2 | G1: CRUDEOIL SRE_SEPARATE_LEG_SL_1 | H1: CRUDEOIL SRE_SEPARATE_LEG_SL_2 | I1: NATURALGAS B120_1 | J1: NATURALGAS B120_2 | K1: NATURALGAS SRE_SEPARATE_LEG_SL_1 | L1: NATURALGAS SRE_SEPARATE_LEG_SL_2
A2: 44928 | B2: Monday | C2: 8 | D2: 12 | E2: 66831.35 | F2: 66831.35 | G2: 66831.35 | H2: 66831.35 | I2: 0 | J2: 0 | K2: 0 | L2: 0
A3: 44929 | B3: Tuesday | C3: 7 | D3: 11 | E3: 10149.734 | F3: 10149.734 | G3: 10149.734 | H3: 10149.734 | I3: 0 | J3: 0 | K3: 0 | L3: 0
A4: 44930 | B4: Wednesday | C4: 6 | D4: 10 | E4: 31445.557 | F4: 31445.557 | G4: 31445.557 | H4: 31445.557 | I4: 0 | J4: 0 | K4: 0 | L4: 0
A5: 44932 | B5: Friday | C5: 5 | D5: 9 | E5: 108759.65 | F5: 108759.65 | G5: 108759.65 | H5: 108759.65 | I5: 0 | J5: 0 | K5: 0 | L5: 0
A6: 44938 | B6: Thursday | C6: 4 | D6: 8 | E6: 165217.62 | F6: 165217.62 | G6: 165217.62 | H6: 165217.62 | I6: 0 | J6: 0 | K6: 0 | L6: 0
A7: 44939 | B7: Friday | C7: 3 | D7: 7 | E7: 139881.68 | F7: 139881.68 | G7: 139881.68 | H7: 139881.68 | I7: 0 | J7: 0 | K7: 0 | L7: 0
A8: 44942 | B8: Monday | C8: 2 | D8: 6 | E8: 20363.493 | F8: 100244.16 | G8: 100244.16 | H8: 100244.16 | I8: 84224.599 | J8: 84224.599 | K8: 84224.599 | L8: 84224.599
A9: 44943 | B9: Tuesday | C9: 1 | D9: 5 | E9: 195988.11 | F9: 250473.75 | G9: 248507.64 | H9: 248507.64 | I9: -17276.7 | J9: -17276.7 | K9: -17276.7 | L9: -17276.7
A10: 44944 | B10: Wednesday | C10: 20 | D10: 4 | E10: 0 | F10: 0 | G10: 0 | H10: 0 | I10: 90329.992 | J10: 90329.992 | K10: 90329.992 | L10: 90329.992
A11: 44945 | B11: Thursday | C11: 19 | D11: 3 | E11: 0 | F11: 0 | G11: 0 | H11: 0 | I11: 55846.154 | J11: 55846.154 | K11: 55846.154 | L11: 55846.154
A12: 44946 | B12: Friday | C12: 18 | D12: 2 | E12: 0 | F12: 0 | G12: 0 | H12: 0 | I12: -131800.48 | J12: -138135.93 | K12: -138135.93 | L12: -138135.93
A13: 44949 | B13: Monday | C13: 17 | D13: 1 | E13: 0 | F13: 0 | G13: 0 | H13: 0 | I13: -125813.74 | J13: 152426.16 | K13: 68392.104 | L13: 68392.104
... A722: 46034 | B722: Monday | C722: 3 | D722: 9 | E722: -44002.454 | F722: 10586.963 | G722: 10586.963 | H722: 10586.963 | I722: 0 | J722: 0 | K722: 0 | L722: 0

Sheet Exit Times
A1: Date | B1: CRUDEOIL | C1: CRUDEOIL B120_1 | D1: CRUDEOIL B120_2 | E1: CRUDEOIL SRE_SEPARATE_LEG_SL_1 | F1: CRUDEOIL SRE_SEPARATE_LEG_SL_2 | G1: NATURALGAS | H1: NATURALGAS B120_1 | I1: NATURALGAS B120_2 | J1: NATURALGAS SRE_SEPARATE_LEG_SL_1 | K1: NATURALGAS SRE_SEPARATE_LEG_SL_2
A2: 44928 | B2: 23:30:00 | C2: 23:30:00 | D2: 23:30:00 | E2: 23:30:00 | F2: 23:30:00 | G2: 23:30:00 | H2: 0 | I2: 0 | J2: 0 | K2: 0
A3: 44929 | B3: 23:30:00 | C3: 23:30:00 | D3: 23:30:00 | E3: 23:30:00 | F3: 23:30:00 | G3: 23:30:00 | H3: 0 | I3: 0 | J3: 0 | K3: 0
A4: 44930 | B4: 23:30:00 | C4: 23:30:00 | D4: 23:30:00 | E4: 23:30:00 | F4: 23:30:00 | G4: 23:30:00 | H4: 0 | I4: 0 | J4: 0 | K4: 0
A5: 44932 | B5: 23:30:00 | C5: 23:30:00 | D5: 23:30:00 | E5: 23:30:00 | F5: 23:30:00 | G5: 23:30:00 | H5: 0 | I5: 0 | J5: 0 | K5: 0
A6: 44938 | B6: 23:30:00 | C6: 23:30:00 | D6: 23:30:00 | E6: 23:30:00 | F6: 23:30:00 | G6: 23:30:00 | H6: 0 | I6: 0 | J6: 0 | K6: 0
A7: 44939 | B7: 23:30:00 | C7: 23:30:00 | D7: 23:30:00 | E7: 23:30:00 | F7: 23:30:00 | G7: 23:30:00 | H7: 0 | I7: 0 | J7: 0 | K7: 0
A8: 44942 | B8: 23:30:00 | C8: 23:30:00 | D8: 23:30:00 | E8: 23:30:00 | F8: 23:30:00 | G8: 23:30:00 | H8: 23:30:00 | I8: 23:30:00 | J8: 23:30:00 | K8: 23:30:00
A9: 44943 | B9: 23:30:00 | C9: 19:53:00 | D9: 21:22:00 | E9: 20:50:00 | F9: 20:50:00 | G9: 23:30:00 | H9: 23:30:00 | I9: 23:30:00 | J9: 23:30:00 | K9: 23:30:00
A10: 44944 | B10: 23:30:00 | C10: 0 | D10: 0 | E10: 0 | F10: 0 | G10: 23:30:00 | H10: 21:48:00 | I10: 21:48:00 | J10: 21:48:00 | K10: 21:48:00
A11: 44945 | B11: 23:30:00 | C11: 0 | D11: 0 | E11: 0 | F11: 0 | G11: 23:30:00 | H11: 23:30:00 | I11: 23:30:00 | J11: 23:30:00 | K11: 23:30:00
A12: 44946 | B12: 23:30:00 | C12: 0 | D12: 0 | E12: 0 | F12: 0 | G12: 23:30:00 | H12: 19:40:00 | I12: 19:39:00 | J12: 19:39:00 | K12: 19:39:00
A13: 44949 | B13: 23:30:00 | C13: 0 | D13: 0 | E13: 0 | F13: 0 | G13: 23:30:00 | H13: 18:41:00 | I13: 19:44:00 | J13: 19:35:00 | K13: 19:35:00
A14: 44950 | B14: 23:30:00 | C14: 0 | D14: 0 | E14: 0 | F14: 0 | G14: 23:30:00 | H14: 0 | I14: 0 | J14: 0 | K14: 0
A15: 44951 | B15: 23:30:00 | C15: 0 | D15: 0 | E15: 0 | F15: 0 | G15: 23:30:00 | H15: 0 | I15: 0 | J15: 0 | K15: 0
A16: 44953 | B16: 23:30:00 | C16: 0 | D16: 0 | E16: 0 | F16: 0 | G16: 23:30:00 | H16: 0 | I16: 0 | J16: 0 | K16: 0
A17: 44956 | B17: 23:30:00 | C17: 0 | D17: 0 | E17: 0 | F17: 0 | G17: 23:30:00 | H17: 0 | I17: 0 | J17: 0 | K17: 0
A18: 44957 | B18: 23:30:00 | C18: 0 | D18: 0 | E18: 0 | F18: 0 | G18: 23:30:00 | H18: 0 | I18: 0 | J18: 0 | K18: 0
A19: 44958 | B19: 23:30:00 | C19: 0 | D19: 0 | E19: 0 | F19: 0 | G19: 23:30:00 | H19: 0 | I19: 0 | J19: 0 | K19: 0
A20: 44959 | B20: 23:30:00 | C20: 23:30:00 | D20: 23:30:00 | E20: 23:30:00 | F20: 23:30:00 | G20: 23:30:00 | H20: 0 | I20: 0 | J20: 0 | K20: 0
A21: 44960 | B21: 23:30:00 | C21: 21:46:00 | D21: 23:30:00 | E21: 23:30:00 | F21: 23:30:00 | G21: 23:30:00 | H21: 0 | I21: 0 | J21: 0 | K21: 0
A22: 44963 | B22: 23:30:00 | C22: 23:30:00 | D22: 23:30:00 | E22: 23:30:00 | F22: 23:30:00 | G22: 23:30:00 | H22: 0 | I22: 0 | J22: 0 | K22: 0
A23: 44964 | B23: 23:30:00 | C23: 21:47:00 | D23: 21:47:00 | E23: 21:47:00 | F23: 21:47:00 | G23: 23:30:00 | H23: 0 | I23: 0 | J23: 0 | K23: 0
A24: 44965 | B24: 23:30:00 | C24: 23:30:00 | D24: 23:30:00 | E24: 23:30:00 | F24: 23:30:00 | G24: 23:30:00 | H24: 0 | I24: 0 | J24: 0 | K24: 0
A25: 44966 | B25: 23:30:00 | C25: 23:30:00 | D25: 23:30:00 | E25: 23:30:00 | F25: 23:30:00 | G25: 23:30:00 | H25: 0 | I25: 0 | J25: 0 | K25: 0
A26: 44967 | B26: 23:30:00 | C26: 23:30:00 | D26: 23:30:00 | E26: 23:30:00 | F26: 23:30:00 | G26: 23:30:00 | H26: 0 | I26: 0 | J26: 0 | K26: 0
A27: 44970 | B27: 23:30:00 | C27: 23:30:00 | D27: 23:30:00 | E27: 23:30:00 | F27: 23:30:00 | G27: 23:30:00 | H27: 0 | I27: 0 | J27: 0 | K27: 0
A28: 44971 | B28: 23:30:00 | C28: 23:30:00 | D28: 23:30:00 | E28: 23:30:00 | F28: 23:30:00 | G28: 23:30:00 | H28: 23:30:00 | I28: 23:30:00 | J28: 23:30:00 | K28: 23:30:00
A29: 44972 | B29: 23:30:00 | C29: 23:30:00 | D29: 23:30:00 | E29: 23:13:00 | F29: 23:13:00 | G29: 23:30:00 | H29: 23:30:00 | I29: 23:30:00 | J29: 23:30:00 | K29: 23:30:00
A30: 44973 | B30: 23:30:00 | C30: 0 | D30: 0 | E30: 0 | F30: 0 | G30: 23:30:00 | H30: 22:42:00 | I30: 22:42:00 | J30: 22:42:00 | K30: 22:42:00
A31: 44974 | B31: 23:30:00 | C31: 0 | D31: 0 | E31: 0 | F31: 0 | G31: 23:30:00 | H31: 21:18:00 | I31: 21:18:00 | J31: 21:18:00 | K31: 21:18:00
A32: 44977 | B32: 23:30:00 | C32: 0 | D32: 0 | E32: 0 | F32: 0 | G32: 23:30:00 | H32: 20:32:00 | I32: 20:32:00 | J32: 20:32:00 | K32: 20:32:00
A33: 44978 | B33: 23:30:00 | C33: 0 | D33: 0 | E33: 0 | F33: 0 | G33: 23:30:00 | H33: 23:30:00 | I33: 23:30:00 | J33: 23:30:00 | K33: 20:30:00
A34: 44979 | B34: 23:30:00 | C34: 0 | D34: 0 | E34: 0 | F34: 0 | G34: 23:30:00 | H34: 0 | I34: 0 | J34: 0 | K34: 0
A35: 44980 | B35: 23:30:00 | C35: 0 | D35: 0 | E35: 0 | F35: 0 | G35: 23:30:00 | H35: 0 | I35: 0 | J35: 0 | K35: 0
A36: 44981 | B36: 23:30:00 | C36: 0 | D36: 0 | E36: 0 | F36: 0 | G36: 23:30:00 | H36: 0 | I36: 0 | J36: 0 | K36: 0
A37: 44984 | B37: 23:30:00 | C37: 0 | D37: 0 | E37: 0 | F37: 0 | G37: 23:30:00 | H37: 0 | I37: 0 | J37: 0 | K37: 0
A38: 44985 | B38: 23:30:00 | C38: 0 | D38: 0 | E38: 0 | F38: 0 | G38: 23:30:00 | H38: 0 | I38: 0 | J38: 0 | K38: 0
A39: 44986 | B39: 23:30:00 | C39: 0 | D39: 0 | E39: 0 | F39: 0 | G39: 23:30:00 | H39: 0 | I39: 0 | J39: 0 | K39: 0
A40: 44987 | B40: 23:30:00 | C40: 23:30:00 | D40: 23:30:00 | E40: 23:30:00 | F40: 23:30:00 | G40: 23:30:00 | H40: 0 | I40: 0 | J40: 0 | K40: 0
...

Sheet StgWiseDD
A1: Date | B1: Day | C1: CRUDEOIL DTE | D1: NATURALGAS DTE | E1: CRUDEOIL B120_1 | F1: DD CRUDEOIL B120_1 | G1: CRUDEOIL B120_2 | H1: DD CRUDEOIL B120_2 | I1: CRUDEOIL SRE_SEPARATE_LEG_SL_1 | J1: DD CRUDEOIL SRE_SEPARATE_LEG_SL_1 | K1: CRUDEOIL SRE_SEPARATE_LEG_SL_2 | L1: DD CRUDEOIL SRE_SEPARATE_LEG_SL_2 | M1: NATURALGAS B120_1 | N1: DD NATURALGAS B120_1 | O1: NATURALGAS B120_2 | P1: DD NATURALGAS B120_2 | Q1: NATURALGAS SRE_SEPARATE_LEG_SL_1 | R1: DD NATURALGAS SRE_SEPARATE_LEG_SL_1 | S1: NATURALGAS SRE_SEPARATE_LEG_SL_2 | T1: DD NATURALGAS SRE_SEPARATE_LEG_SL_2
A2: 44928 | B2: Monday | C2: 8 | D2: 12 | E2: 66831.35 | F2: =IF(E2 < 0, E2, 0) -> 0 | G2: 66831.35 | H2: =IF(G2 < 0, G2, 0) -> 0 | I2: 66831.35 | J2: =IF(I2 < 0, I2, 0) -> 0 | K2: 66831.35 | L2: =IF(K2 < 0, K2, 0) -> 0 | M2: 0 | N2: =IF(M2 < 0, M2, 0) -> 0 | O2: 0 | P2: =IF(O2 < 0, O2, 0) -> 0 | Q2: 0 | R2: =IF(Q2 < 0, Q2, 0) -> 0 | S2: 0 | T2: =IF(S2 < 0, S2, 0) -> 0
A3: 44929 | B3: Tuesday | C3: 7 | D3: 11 | E3: 10149.734 | F3: =IF(E3 + F2 < 0, E3 + F2, 0) -> 0 | G3: 10149.734 | H3: =IF(G3 + H2 < 0, G3 + H2, 0) -> 0 | I3: 10149.734 | J3: =IF(I3 + J2 < 0, I3 + J2, 0) -> 0 | K3: 10149.734 | L3: =IF(K3 + L2 < 0, K3 + L2, 0) -> 0 | M3: 0 | N3: =IF(M3 + N2 < 0, M3 + N2, 0) -> 0 | O3: 0 | P3: =IF(O3 + P2 < 0, O3 + P2, 0) -> 0 | Q3: 0 | R3: =IF(Q3 + R2 < 0, Q3 + R2, 0) -> 0 | S3: 0 | T3: =IF(S3 + T2 < 0, S3 + T2, 0) -> 0
A4: 44930 | B4: Wednesday | C4: 6 | D4: 10 | E4: 31445.557 | F4: =IF(E4 + F3 < 0, E4 + F3, 0) -> 0 | G4: 31445.557 | H4: =IF(G4 + H3 < 0, G4 + H3, 0) -> 0 | I4: 31445.557 | J4: =IF(I4 + J3 < 0, I4 + J3, 0) -> 0 | K4: 31445.557 | L4: =IF(K4 + L3 < 0, K4 + L3, 0) -> 0 | M4: 0 | N4: =IF(M4 + N3 < 0, M4 + N3, 0) -> 0 | O4: 0 | P4: =IF(O4 + P3 < 0, O4 + P3, 0) -> 0 | Q4: 0 | R4: =IF(Q4 + R3 < 0, Q4 + R3, 0) -> 0 | S4: 0 | T4: =IF(S4 + T3 < 0, S4 + T3, 0) -> 0
A5: 44932 | B5: Friday | C5: 5 | D5: 9 | E5: 108759.65 | F5: =IF(E5 + F4 < 0, E5 + F4, 0) -> 0 | G5: 108759.65 | H5: =IF(G5 + H4 < 0, G5 + H4, 0) -> 0 | I5: 108759.65 | J5: =IF(I5 + J4 < 0, I5 + J4, 0) -> 0 | K5: 108759.65 | L5: =IF(K5 + L4 < 0, K5 + L4, 0) -> 0 | M5: 0 | N5: =IF(M5 + N4 < 0, M5 + N4, 0) -> 0 | O5: 0 | P5: =IF(O5 + P4 < 0, O5 + P4, 0) -> 0 | Q5: 0 | R5: =IF(Q5 + R4 < 0, Q5 + R4, 0) -> 0 | S5: 0 | T5: =IF(S5 + T4 < 0, S5 + T4, 0) -> 0
A6: 44938 | B6: Thursday | C6: 4 | D6: 8 | E6: 165217.62 | F6: =IF(E6 + F5 < 0, E6 + F5, 0) -> 0 | G6: 165217.62 | H6: =IF(G6 + H5 < 0, G6 + H5, 0) -> 0 | I6: 165217.62 | J6: =IF(I6 + J5 < 0, I6 + J5, 0) -> 0 | K6: 165217.62 | L6: =IF(K6 + L5 < 0, K6 + L5, 0) -> 0 | M6: 0 | N6: =IF(M6 + N5 < 0, M6 + N5, 0) -> 0 | O6: 0 | P6: =IF(O6 + P5 < 0, O6 + P5, 0) -> 0 | Q6: 0 | R6: =IF(Q6 + R5 < 0, Q6 + R5, 0) -> 0 | S6: 0 | T6: =IF(S6 + T5 < 0, S6 + T5, 0) -> 0
A7: 44939 | B7: Friday | C7: 3 | D7: 7 | E7: 139881.68 | F7: =IF(E7 + F6 < 0, E7 + F6, 0) -> 0 | G7: 139881.68 | H7: =IF(G7 + H6 < 0, G7 + H6, 0) -> 0 | I7: 139881.68 | J7: =IF(I7 + J6 < 0, I7 + J6, 0) -> 0 | K7: 139881.68 | L7: =IF(K7 + L6 < 0, K7 + L6, 0) -> 0 | M7: 0 | N7: =IF(M7 + N6 < 0, M7 + N6, 0) -> 0 | O7: 0 | P7: =IF(O7 + P6 < 0, O7 + P6, 0) -> 0 | Q7: 0 | R7: =IF(Q7 + R6 < 0, Q7 + R6, 0) -> 0 | S7: 0 | T7: =IF(S7 + T6 < 0, S7 + T6, 0) -> 0
A8: 44942 | B8: Monday | C8: 2 | D8: 6 | E8: 20363.493 | F8: =IF(E8 + F7 < 0, E8 + F7, 0) -> 0 | G8: 100244.16 | H8: =IF(G8 + H7 < 0, G8 + H7, 0) -> 0 | I8: 100244.16 | J8: =IF(I8 + J7 < 0, I8 + J7, 0) -> 0 | K8: 100244.16 | L8: =IF(K8 + L7 < 0, K8 + L7, 0) -> 0 | M8: 84224.599 | N8: =IF(M8 + N7 < 0, M8 + N7, 0) -> 0 | O8: 84224.599 | P8: =IF(O8 + P7 < 0, O8 + P7, 0) -> 0 | Q8: 84224.599 | R8: =IF(Q8 + R7 < 0, Q8 + R7, 0) -> 0 | S8: 84224.599 | T8: =IF(S8 + T7 < 0, S8 + T7, 0) -> 0
A9: 44943 | B9: Tuesday | C9: 1 | D9: 5 | E9: 195988.11 | F9: =IF(E9 + F8 < 0, E9 + F8, 0) -> 0 | G9: 250473.75 | H9: =IF(G9 + H8 < 0, G9 + H8, 0) -> 0 | I9: 248507.64 | J9: =IF(I9 + J8 < 0, I9 + J8, 0) -> 0 | K9: 248507.64 | L9: =IF(K9 + L8 < 0, K9 + L8, 0) -> 0 | M9: -17276.7 | N9: =IF(M9 + N8 < 0, M9 + N8, 0) -> 0 | O9: -17276.7 | P9: =IF(O9 + P8 < 0, O9 + P8, 0) -> 0 | Q9: -17276.7 | R9: =IF(Q9 + R8 < 0, Q9 + R8, 0) -> 0 | S9: -17276.7 | T9: =IF(S9 + T8 < 0, S9 + T8, 0) -> 0
A10: 44944 | B10: Wednesday | C10: 20 | D10: 4 | E10: 0 | F10: =IF(E10 + F9 < 0, E10 + F9, 0) -> 0 | G10: 0 | H10: =IF(G10 + H9 < 0, G10 + H9, 0) -> 0 | I10: 0 | J10: =IF(I10 + J9 < 0, I10 + J9, 0) -> 0 | K10: 0 | L10: =IF(K10 + L9 < 0, K10 + L9, 0) -> 0 | M10: 90329.992 | N10: =IF(M10 + N9 < 0, M10 + N9, 0) -> 0 | O10: 90329.992 | P10: =IF(O10 + P9 < 0, O10 + P9, 0) -> 0 | Q10: 90329.992 | R10: =IF(Q10 + R9 < 0, Q10 + R9, 0) -> 0 | S10: 90329.992 | T10: =IF(S10 + T9 < 0, S10 + T9, 0) -> 0
A11: 44945 | B11: Thursday | C11: 19 | D11: 3 | E11: 0 | F11: =IF(E11 + F10 < 0, E11 + F10, 0) -> 0 | G11: 0 | H11: =IF(G11 + H10 < 0, G11 + H10, 0) -> 0 | I11: 0 | J11: =IF(I11 + J10 < 0, I11 + J10, 0) -> 0 | K11: 0 | L11: =IF(K11 + L10 < 0, K11 + L10, 0) -> 0 | M11: 55846.154 | N11: =IF(M11 + N10 < 0, M11 + N10, 0) -> 0 | O11: 55846.154 | P11: =IF(O11 + P10 < 0, O11 + P10, 0) -> 0 | Q11: 55846.154 | R11: =IF(Q11 + R10 < 0, Q11 + R10, 0) -> 0 | S11: 55846.154 | T11: =IF(S11 + T10 < 0, S11 + T10, 0) -> 0
A12: 44946 | B12: Friday | C12: 18 | D12: 2 | E12: 0 | F12: =IF(E12 + F11 < 0, E12 + F11, 0) -> 0 | G12: 0 | H12: =IF(G12 + H11 < 0, G12 + H11, 0) -> 0 | I12: 0 | J12: =IF(I12 + J11 < 0, I12 + J11, 0) -> 0 | K12: 0 | L12: =IF(K12 + L11 < 0, K12 + L11, 0) -> 0 | M12: -131800.48 | N12: =IF(M12 + N11 < 0, M12 + N11, 0) -> 0 | O12: -138135.93 | P12: =IF(O12 + P11 < 0, O12 + P11, 0) -> 0 | Q12: -138135.93 | R12: =IF(Q12 + R11 < 0, Q12 + R11, 0) -> 0 | S12: -138135.93 | T12: =IF(S12 + T11 < 0, S12 + T11, 0) -> 0
A13: 44949 | B13: Monday | C13: 17 | D13: 1 | E13: 0 | F13: =IF(E13 + F12 < 0, E13 + F12, 0) -> 0 | G13: 0 | H13: =IF(G13 + H12 < 0, G13 + H12, 0) -> 0 | I13: 0 | J13: =IF(I13 + J12 < 0, I13 + J12, 0) -> 0 | K13: 0 | L13: =IF(K13 + L12 < 0, K13 + L12, 0) -> 0 | M13: -125813.74 | N13: =IF(M13 + N12 < 0, M13 + N12, 0) -> 0 | O13: 152426.16 | P13: =IF(O13 + P12 < 0, O13 + P12, 0) -> 0 | Q13: 68392.104 | R13: =IF(Q13 + R12 < 0, Q13 + R12, 0) -> 0 | S13: 68392.104 | T13: =IF(S13 + T12 < 0, S13 + T12, 0) -> 0
A14: 44950 | B14: Tuesday | C14: 16 | D14: 20 | E14: 0 | F14: =IF(E14 + F13 < 0, E14 + F13, 0) -> 0 | G14: 0 | H14: =IF(G14 + H13 < 0, G14 + H13, 0) -> 0 | I14: 0 | J14: =IF(I14 + J13 < 0, I14 + J13, 0) -> 0 | K14: 0 | L14: =IF(K14 + L13 < 0, K14 + L13, 0) -> 0 | M14: 0 | N14: =IF(M14 + N13 < 0, M14 + N13, 0) -> 0 | O14: 0 | P14: =IF(O14 + P13 < 0, O14 + P13, 0) -> 0 | Q14: 0 | R14: =IF(Q14 + R13 < 0, Q14 + R13, 0) -> 0 | S14: 0 | T14: =IF(S14 + T13 < 0, S14 + T13, 0) -> 0
... A722: 46034 | B722: Monday | C722: 3 | D722: 9 | E722: -44002.454 | F722: =IF(E722 + F721 < 0, E722 + F721, 0) -> 0 | G722: 10586.963 | H722: =IF(G722 + H721 < 0, G722 + H721, 0) -> 0 | I722: 10586.963 | J722: =IF(I722 + J721 < 0, I722 + J721, 0) -> 0 | K722: 10586.963 | L722: =IF(K722 + L721 < 0, K722 + L721, 0) -> 0 | M722: 0 | N722: =IF(M722 + N721 < 0, M722 + N721, 0) -> 0 | O722: 0 | P722: =IF(O722 + P721 < 0, O722 + P721, 0) -> 0 | Q722: 0 | R722: =IF(Q722 + R721 < 0, Q722 + R721, 0) -> 0 | S722: 0 | T722: =IF(S722 + T721 < 0, S722 + T721, 0) -> 0

Sheet CombinedDD
A1: Date | B1: Day | C1: CRUDEOIL DTE | D1: NATURALGAS DTE | E1: CRUDEOIL B120 | F1: DD CRUDEOIL B120 | G1: CRUDEOIL SRE_SEPARATE_LEG_SL | H1: DD CRUDEOIL SRE_SEPARATE_LEG_SL | I1: NATURALGAS B120 | J1: DD NATURALGAS B120 | K1: NATURALGAS SRE_SEPARATE_LEG_SL | L1: DD NATURALGAS SRE_SEPARATE_LEG_SL
A2: 44928 | B2: Monday | C2: 8 | D2: 12 | E2: 133662.7 | F2: =IF(E2 < 0, E2, 0) -> 0 | G2: 133662.7 | H2: =IF(G2 < 0, G2, 0) -> 0 | I2: 0 | J2: =IF(I2 < 0, I2, 0) -> 0 | K2: 0 | L2: =IF(K2 < 0, K2, 0) -> 0
A3: 44929 | B3: Tuesday | C3: 7 | D3: 11 | E3: 20299.467 | F3: =IF(E3 + F2 < 0, E3 + F2, 0) -> 0 | G3: 20299.467 | H3: =IF(G3 + H2 < 0, G3 + H2, 0) -> 0 | I3: 0 | J3: =IF(I3 + J2 < 0, I3 + J2, 0) -> 0 | K3: 0 | L3: =IF(K3 + L2 < 0, K3 + L2, 0) -> 0
A4: 44930 | B4: Wednesday | C4: 6 | D4: 10 | E4: 62891.114 | F4: =IF(E4 + F3 < 0, E4 + F3, 0) -> 0 | G4: 62891.114 | H4: =IF(G4 + H3 < 0, G4 + H3, 0) -> 0 | I4: 0 | J4: =IF(I4 + J3 < 0, I4 + J3, 0) -> 0 | K4: 0 | L4: =IF(K4 + L3 < 0, K4 + L3, 0) -> 0
A5: 44932 | B5: Friday | C5: 5 | D5: 9 | E5: 217519.3 | F5: =IF(E5 + F4 < 0, E5 + F4, 0) -> 0 | G5: 217519.3 | H5: =IF(G5 + H4 < 0, G5 + H4, 0) -> 0 | I5: 0 | J5: =IF(I5 + J4 < 0, I5 + J4, 0) -> 0 | K5: 0 | L5: =IF(K5 + L4 < 0, K5 + L4, 0) -> 0
A6: 44938 | B6: Thursday | C6: 4 | D6: 8 | E6: 330435.24 | F6: =IF(E6 + F5 < 0, E6 + F5, 0) -> 0 | G6: 330435.24 | H6: =IF(G6 + H5 < 0, G6 + H5, 0) -> 0 | I6: 0 | J6: =IF(I6 + J5 < 0, I6 + J5, 0) -> 0 | K6: 0 | L6: =IF(K6 + L5 < 0, K6 + L5, 0) -> 0
A7: 44939 | B7: Friday | C7: 3 | D7: 7 | E7: 279763.36 | F7: =IF(E7 + F6 < 0, E7 + F6, 0) -> 0 | G7: 279763.36 | H7: =IF(G7 + H6 < 0, G7 + H6, 0) -> 0 | I7: 0 | J7: =IF(I7 + J6 < 0, I7 + J6, 0) -> 0 | K7: 0 | L7: =IF(K7 + L6 < 0, K7 + L6, 0) -> 0
A8: 44942 | B8: Monday | C8: 2 | D8: 6 | E8: 120607.66 | F8: =IF(E8 + F7 < 0, E8 + F7, 0) -> 0 | G8: 200488.32 | H8: =IF(G8 + H7 < 0, G8 + H7, 0) -> 0 | I8: 168449.2 | J8: =IF(I8 + J7 < 0, I8 + J7, 0) -> 0 | K8: 168449.2 | L8: =IF(K8 + L7 < 0, K8 + L7, 0) -> 0
A9: 44943 | B9: Tuesday | C9: 1 | D9: 5 | E9: 446461.86 | F9: =IF(E9 + F8 < 0, E9 + F8, 0) -> 0 | G9: 497015.28 | H9: =IF(G9 + H8 < 0, G9 + H8, 0) -> 0 | I9: -34553.401 | J9: =IF(I9 + J8 < 0, I9 + J8, 0) -> 0 | K9: -34553.401 | L9: =IF(K9 + L8 < 0, K9 + L8, 0) -> 0
A10: 44944 | B10: Wednesday | C10: 20 | D10: 4 | E10: 0 | F10: =IF(E10 + F9 < 0, E10 + F9, 0) -> 0 | G10: 0 | H10: =IF(G10 + H9 < 0, G10 + H9, 0) -> 0 | I10: 180659.98 | J10: =IF(I10 + J9 < 0, I10 + J9, 0) -> 0 | K10: 180659.98 | L10: =IF(K10 + L9 < 0, K10 + L9, 0) -> 0
A11: 44945 | B11: Thursday | C11: 19 | D11: 3 | E11: 0 | F11: =IF(E11 + F10 < 0, E11 + F10, 0) -> 0 | G11: 0 | H11: =IF(G11 + H10 < 0, G11 + H10, 0) -> 0 | I11: 111692.31 | J11: =IF(I11 + J10 < 0, I11 + J10, 0) -> 0 | K11: 111692.31 | L11: =IF(K11 + L10 < 0, K11 + L10, 0) -> 0
A12: 44946 | B12: Friday | C12: 18 | D12: 2 | E12: 0 | F12: =IF(E12 + F11 < 0, E12 + F11, 0) -> 0 | G12: 0 | H12: =IF(G12 + H11 < 0, G12 + H11, 0) -> 0 | I12: -269936.41 | J12: =IF(I12 + J11 < 0, I12 + J11, 0) -> 0 | K12: -276271.86 | L12: =IF(K12 + L11 < 0, K12 + L11, 0) -> 0
A13: 44949 | B13: Monday | C13: 17 | D13: 1 | E13: 0 | F13: =IF(E13 + F12 < 0, E13 + F12, 0) -> 0 | G13: 0 | H13: =IF(G13 + H12 < 0, G13 + H12, 0) -> 0 | I13: 26612.417 | J13: =IF(I13 + J12 < 0, I13 + J12, 0) -> 0 | K13: 136784.21 | L13: =IF(K13 + L12 < 0, K13 + L12, 0) -> 0
A14: 44950 | B14: Tuesday | C14: 16 | D14: 20 | E14: 0 | F14: =IF(E14 + F13 < 0, E14 + F13, 0) -> 0 | G14: 0 | H14: =IF(G14 + H13 < 0, G14 + H13, 0) -> 0 | I14: 0 | J14: =IF(I14 + J13 < 0, I14 + J13, 0) -> 0 | K14: 0 | L14: =IF(K14 + L13 < 0, K14 + L13, 0) -> 0
... A722: 46034 | B722: Monday | C722: 3 | D722: 9 | E722: -33415.491 | F722: =IF(E722 + F721 < 0, E722 + F721, 0) -> 0 | G722: 21173.926 | H722: =IF(G722 + H721 < 0, G722 + H721, 0) -> 0 | I722: 0 | J722: =IF(I722 + J721 < 0, I722 + J721, 0) -> 0 | K722: 0 | L722: =IF(K722 + L721 < 0, K722 + L721, 0) -> 0

Sheet MTM
A1: Date | B1: Day | C1: CRUDEOIL | D1: NATURALGAS | E1: Total | F1: CRUDEOIL-DD | G1: NATURALGAS-DD | H1: Total-DD | I1: DD-Days | J1: CRUDEOIL-Hedge | K1: NATURALGAS-Hedge | L1: Total-Hedge | M1: CRUDEOIL-Hedge-DD | N1: NATURALGAS-Hedge-DD | O1: Total-Hedge-DD | P1: Hedge-DD-Days | Q1: Loss-Days | R1: Loss-Amount | S1: Profit-Days | T1: Profit-Amount | U1: Loss-Greater-1% | V1: Profit-Greater-1% | W1: Hedge-Loss-Days | X1: Hedge-Loss-Amount | Y1: Hedge-Profit-Days | Z1: Hedge-Profit-Amount | AA1: Hedge-Loss-Greater-1% | AB1: Hedge-Profit-Greater-1%
A2: 44928 | B2: Monday | C2: =SUM(PL!E2:H2) -> 0 | D2: =SUM(PL!I2:L2) -> 0 | E2: =SUM(C2:D2) -> 0 | F2: =IF(C2 < 0, C2, 0) -> 0 | G2: =IF(D2 < 0, D2, 0) -> 0 | H2: =IF(E2 < 0, E2, 0) -> 0 | I2: =IF(H2 < 0, 1, 0) -> 0 | J2: =C2-((ABS(SUM(PL!E2:H2)))*0.125) -> 0 | K2: =D2-((ABS(SUM(PL!I2:L2)))*0.125) -> 0 | L2: =J2 + K2 -> 0 | M2: =IF(J2 < 0, J2, 0) -> 0 | N2: =IF(K2 < 0, K2, 0) -> 0 | O2: =IF(L2 < 0, L2, 0) -> 0 | P2: =IF(O2 < 0, 1, 0) -> 0 | Q2: =IF(E2<0,1,0) -> 0 | R2: =IF(Q2=1,E2,0) -> 0 | S2: =IF(E2>0,1,0) -> 0 | T2: =IF(S2=1,E2,0) -> 0 | U2: =IF(R2<-100000000/100,1,0) -> 0 | V2: =IF(T2>100000000/100,1,0) -> 0 | W2: =IF(L2<0,1,0) -> 0 | X2: =IF(W2=1,L2,0) -> 0 | Y2: =IF(L2>0,1,0) -> 0 | Z2: =IF(Y2=1,L2,0) -> 0 | AA2: =IF(X2<-100000000/100,1,0) -> 0 | AB2: =IF(Z2>100000000/100,1,0) -> 0
A3: 44929 | B3: Tuesday | C3: =SUM(PL!E3:H3) -> 0 | D3: =SUM(PL!I3:L3) -> 0 | E3: =SUM(C3:D3) -> 0 | F3: =IF(C3 + F2 < 0, C3 + F2, 0) -> 0 | G3: =IF(D3 + G2 < 0, D3 + G2, 0) -> 0 | H3: =IF(E3 + H2 < 0, E3 + H2, 0) -> 0 | I3: =IF(H3 < 0, 1 + I2, 0) -> 0 | J3: =C3-((ABS(SUM(PL!E3:H3)))*0.125) -> 0 | K3: =D3-((ABS(SUM(PL!I3:L3)))*0.125) -> 0 | L3: =J3 + K3 -> 0 | M3: =IF(J3 + M2 < 0, J3 + M2, 0) -> 0 | N3: =IF(K3 + N2 < 0, K3 + N2, 0) -> 0 | O3: =IF(L3 + O2 < 0, L3 + O2, 0) -> 0 | P3: =IF(O3 < 0, 1 + P2, 0) -> 0 | Q3: =IF(E3<0,1,0) -> 0 | R3: =IF(Q3=1,E3,0) -> 0 | S3: =IF(E3>0,1,0) -> 0 | T3: =IF(S3=1,E3,0) -> 0 | U3: =IF(R3<-100000000/100,1,0) -> 0 | V3: =IF(T3>100000000/100,1,0) -> 0 | W3: =IF(L3<0,1,0) -> 0 | X3: =IF(W3=1,L3,0) -> 0 | Y3: =IF(L3>0,1,0) -> 0 | Z3: =IF(Y3=1,L3,0) -> 0 | AA3: =IF(X3<-100000000/100,1,0) -> 0 | AB3: =IF(Z3>100000000/100,1,0) -> 0
A4: 44930 | B4: Wednesday | C4: =SUM(PL!E4:H4) -> 0 | D4: =SUM(PL!I4:L4) -> 0 | E4: =SUM(C4:D4) -> 0 | F4: =IF(C4 + F3 < 0, C4 + F3, 0) -> 0 | G4: =IF(D4 + G3 < 0, D4 + G3, 0) -> 0 | H4: =IF(E4 + H3 < 0, E4 + H3, 0) -> 0 | I4: =IF(H4 < 0, 1 + I3, 0) -> 0 | J4: =C4-((ABS(SUM(PL!E4:H4)))*0.125) -> 0 | K4: =D4-((ABS(SUM(PL!I4:L4)))*0.125) -> 0 | L4: =J4 + K4 -> 0 | M4: =IF(J4 + M3 < 0, J4 + M3, 0) -> 0 | N4: =IF(K4 + N3 < 0, K4 + N3, 0) -> 0 | O4: =IF(L4 + O3 < 0, L4 + O3, 0) -> 0 | P4: =IF(O4 < 0, 1 + P3, 0) -> 0 | Q4: =IF(E4<0,1,0) -> 0 | R4: =IF(Q4=1,E4,0) -> 0 | S4: =IF(E4>0,1,0) -> 0 | T4: =IF(S4=1,E4,0) -> 0 | U4: =IF(R4<-100000000/100,1,0) -> 0 | V4: =IF(T4>100000000/100,1,0) -> 0 | W4: =IF(L4<0,1,0) -> 0 | X4: =IF(W4=1,L4,0) -> 0 | Y4: =IF(L4>0,1,0) -> 0 | Z4: =IF(Y4=1,L4,0) -> 0 | AA4: =IF(X4<-100000000/100,1,0) -> 0 | AB4: =IF(Z4>100000000/100,1,0) -> 0
A5: 44932 | B5: Friday | C5: =SUM(PL!E5:H5) -> 0 | D5: =SUM(PL!I5:L5) -> 0 | E5: =SUM(C5:D5) -> 0 | F5: =IF(C5 + F4 < 0, C5 + F4, 0) -> 0 | G5: =IF(D5 + G4 < 0, D5 + G4, 0) -> 0 | H5: =IF(E5 + H4 < 0, E5 + H4, 0) -> 0 | I5: =IF(H5 < 0, 1 + I4, 0) -> 0 | J5: =C5-((ABS(SUM(PL!E5:H5)))*0.125) -> 0 | K5: =D5-((ABS(SUM(PL!I5:L5)))*0.125) -> 0 | L5: =J5 + K5 -> 0 | M5: =IF(J5 + M4 < 0, J5 + M4, 0) -> 0 | N5: =IF(K5 + N4 < 0, K5 + N4, 0) -> 0 | O5: =IF(L5 + O4 < 0, L5 + O4, 0) -> 0 | P5: =IF(O5 < 0, 1 + P4, 0) -> 0 | Q5: =IF(E5<0,1,0) -> 0 | R5: =IF(Q5=1,E5,0) -> 0 | S5: =IF(E5>0,1,0) -> 0 | T5: =IF(S5=1,E5,0) -> 0 | U5: =IF(R5<-100000000/100,1,0) -> 0 | V5: =IF(T5>100000000/100,1,0) -> 0 | W5: =IF(L5<0,1,0) -> 0 | X5: =IF(W5=1,L5,0) -> 0 | Y5: =IF(L5>0,1,0) -> 0 | Z5: =IF(Y5=1,L5,0) -> 0 | AA5: =IF(X5<-100000000/100,1,0) -> 0 | AB5: =IF(Z5>100000000/100,1,0) -> 0
A6: 44938 | B6: Thursday | C6: =SUM(PL!E6:H6) -> 0 | D6: =SUM(PL!I6:L6) -> 0 | E6: =SUM(C6:D6) -> 0 | F6: =IF(C6 + F5 < 0, C6 + F5, 0) -> 0 | G6: =IF(D6 + G5 < 0, D6 + G5, 0) -> 0 | H6: =IF(E6 + H5 < 0, E6 + H5, 0) -> 0 | I6: =IF(H6 < 0, 1 + I5, 0) -> 0 | J6: =C6-((ABS(SUM(PL!E6:H6)))*0.125) -> 0 | K6: =D6-((ABS(SUM(PL!I6:L6)))*0.125) -> 0 | L6: =J6 + K6 -> 0 | M6: =IF(J6 + M5 < 0, J6 + M5, 0) -> 0 | N6: =IF(K6 + N5 < 0, K6 + N5, 0) -> 0 | O6: =IF(L6 + O5 < 0, L6 + O5, 0) -> 0 | P6: =IF(O6 < 0, 1 + P5, 0) -> 0 | Q6: =IF(E6<0,1,0) -> 0 | R6: =IF(Q6=1,E6,0) -> 0 | S6: =IF(E6>0,1,0) -> 0 | T6: =IF(S6=1,E6,0) -> 0 | U6: =IF(R6<-100000000/100,1,0) -> 0 | V6: =IF(T6>100000000/100,1,0) -> 0 | W6: =IF(L6<0,1,0) -> 0 | X6: =IF(W6=1,L6,0) -> 0 | Y6: =IF(L6>0,1,0) -> 0 | Z6: =IF(Y6=1,L6,0) -> 0 | AA6: =IF(X6<-100000000/100,1,0) -> 0 | AB6: =IF(Z6>100000000/100,1,0) -> 0
A7: 44939 | B7: Friday | C7: =SUM(PL!E7:H7) -> 0 | D7: =SUM(PL!I7:L7) -> 0 | E7: =SUM(C7:D7) -> 0 | F7: =IF(C7 + F6 < 0, C7 + F6, 0) -> 0 | G7: =IF(D7 + G6 < 0, D7 + G6, 0) -> 0 | H7: =IF(E7 + H6 < 0, E7 + H6, 0) -> 0 | I7: =IF(H7 < 0, 1 + I6, 0) -> 0 | J7: =C7-((ABS(SUM(PL!E7:H7)))*0.125) -> 0 | K7: =D7-((ABS(SUM(PL!I7:L7)))*0.125) -> 0 | L7: =J7 + K7 -> 0 | M7: =IF(J7 + M6 < 0, J7 + M6, 0) -> 0 | N7: =IF(K7 + N6 < 0, K7 + N6, 0) -> 0 | O7: =IF(L7 + O6 < 0, L7 + O6, 0) -> 0 | P7: =IF(O7 < 0, 1 + P6, 0) -> 0 | Q7: =IF(E7<0,1,0) -> 0 | R7: =IF(Q7=1,E7,0) -> 0 | S7: =IF(E7>0,1,0) -> 0 | T7: =IF(S7=1,E7,0) -> 0 | U7: =IF(R7<-100000000/100,1,0) -> 0 | V7: =IF(T7>100000000/100,1,0) -> 0 | W7: =IF(L7<0,1,0) -> 0 | X7: =IF(W7=1,L7,0) -> 0 | Y7: =IF(L7>0,1,0) -> 0 | Z7: =IF(Y7=1,L7,0) -> 0 | AA7: =IF(X7<-100000000/100,1,0) -> 0 | AB7: =IF(Z7>100000000/100,1,0) -> 0
A8: 44942 | B8: Monday | C8: =SUM(PL!E8:H8) -> 0 | D8: =SUM(PL!I8:L8) -> 0 | E8: =SUM(C8:D8) -> 0 | F8: =IF(C8 + F7 < 0, C8 + F7, 0) -> 0 | G8: =IF(D8 + G7 < 0, D8 + G7, 0) -> 0 | H8: =IF(E8 + H7 < 0, E8 + H7, 0) -> 0 | I8: =IF(H8 < 0, 1 + I7, 0) -> 0 | J8: =C8-((ABS(SUM(PL!E8:H8)))*0.125) -> 0 | K8: =D8-((ABS(SUM(PL!I8:L8)))*0.125) -> 0 | L8: =J8 + K8 -> 0 | M8: =IF(J8 + M7 < 0, J8 + M7, 0) -> 0 | N8: =IF(K8 + N7 < 0, K8 + N7, 0) -> 0 | O8: =IF(L8 + O7 < 0, L8 + O7, 0) -> 0 | P8: =IF(O8 < 0, 1 + P7, 0) -> 0 | Q8: =IF(E8<0,1,0) -> 0 | R8: =IF(Q8=1,E8,0) -> 0 | S8: =IF(E8>0,1,0) -> 0 | T8: =IF(S8=1,E8,0) -> 0 | U8: =IF(R8<-100000000/100,1,0) -> 0 | V8: =IF(T8>100000000/100,1,0) -> 0 | W8: =IF(L8<0,1,0) -> 0 | X8: =IF(W8=1,L8,0) -> 0 | Y8: =IF(L8>0,1,0) -> 0 | Z8: =IF(Y8=1,L8,0) -> 0 | AA8: =IF(X8<-100000000/100,1,0) -> 0 | AB8: =IF(Z8>100000000/100,1,0) -> 0
A9: 44943 | B9: Tuesday | C9: =SUM(PL!E9:H9) -> 0 | D9: =SUM(PL!I9:L9) -> 0 | E9: =SUM(C9:D9) -> 0 | F9: =IF(C9 + F8 < 0, C9 + F8, 0) -> 0 | G9: =IF(D9 + G8 < 0, D9 + G8, 0) -> 0 | H9: =IF(E9 + H8 < 0, E9 + H8, 0) -> 0 | I9: =IF(H9 < 0, 1 + I8, 0) -> 0 | J9: =C9-((ABS(SUM(PL!E9:H9)))*0.125) -> 0 | K9: =D9-((ABS(SUM(PL!I9:L9)))*0.125) -> 0 | L9: =J9 + K9 -> 0 | M9: =IF(J9 + M8 < 0, J9 + M8, 0) -> 0 | N9: =IF(K9 + N8 < 0, K9 + N8, 0) -> 0 | O9: =IF(L9 + O8 < 0, L9 + O8, 0) -> 0 | P9: =IF(O9 < 0, 1 + P8, 0) -> 0 | Q9: =IF(E9<0,1,0) -> 0 | R9: =IF(Q9=1,E9,0) -> 0 | S9: =IF(E9>0,1,0) -> 0 | T9: =IF(S9=1,E9,0) -> 0 | U9: =IF(R9<-100000000/100,1,0) -> 0 | V9: =IF(T9>100000000/100,1,0) -> 0 | W9: =IF(L9<0,1,0) -> 0 | X9: =IF(W9=1,L9,0) -> 0 | Y9: =IF(L9>0,1,0) -> 0 | Z9: =IF(Y9=1,L9,0) -> 0 | AA9: =IF(X9<-100000000/100,1,0) -> 0 | AB9: =IF(Z9>100000000/100,1,0) -> 0
A10: 44944 | B10: Wednesday | C10: =SUM(PL!E10:H10) -> 0 | D10: =SUM(PL!I10:L10) -> 0 | E10: =SUM(C10:D10) -> 0 | F10: =IF(C10 + F9 < 0, C10 + F9, 0) -> 0 | G10: =IF(D10 + G9 < 0, D10 + G9, 0) -> 0 | H10: =IF(E10 + H9 < 0, E10 + H9, 0) -> 0 | I10: =IF(H10 < 0, 1 + I9, 0) -> 0 | J10: =C10-((ABS(SUM(PL!E10:H10)))*0.125) -> 0 | K10: =D10-((ABS(SUM(PL!I10:L10)))*0.125) -> 0 | L10: =J10 + K10 -> 0 | M10: =IF(J10 + M9 < 0, J10 + M9, 0) -> 0 | N10: =IF(K10 + N9 < 0, K10 + N9, 0) -> 0 | O10: =IF(L10 + O9 < 0, L10 + O9, 0) -> 0 | P10: =IF(O10 < 0, 1 + P9, 0) -> 0 | Q10: =IF(E10<0,1,0) -> 0 | R10: =IF(Q10=1,E10,0) -> 0 | S10: =IF(E10>0,1,0) -> 0 | T10: =IF(S10=1,E10,0) -> 0 | U10: =IF(R10<-100000000/100,1,0) -> 0 | V10: =IF(T10>100000000/100,1,0) -> 0 | W10: =IF(L10<0,1,0) -> 0 | X10: =IF(W10=1,L10,0) -> 0 | Y10: =IF(L10>0,1,0) -> 0 | Z10: =IF(Y10=1,L10,0) -> 0 | AA10: =IF(X10<-100000000/100,1,0) -> 0 | AB10: =IF(Z10>100000000/100,1,0) -> 0
A11: 44945 | B11: Thursday | C11: =SUM(PL!E11:H11) -> 0 | D11: =SUM(PL!I11:L11) -> 0 | E11: =SUM(C11:D11) -> 0 | F11: =IF(C11 + F10 < 0, C11 + F10, 0) -> 0 | G11: =IF(D11 + G10 < 0, D11 + G10, 0) -> 0 | H11: =IF(E11 + H10 < 0, E11 + H10, 0) -> 0 | I11: =IF(H11 < 0, 1 + I10, 0) -> 0 | J11: =C11-((ABS(SUM(PL!E11:H11)))*0.125) -> 0 | K11: =D11-((ABS(SUM(PL!I11:L11)))*0.125) -> 0 | L11: =J11 + K11 -> 0 | M11: =IF(J11 + M10 < 0, J11 + M10, 0) -> 0 | N11: =IF(K11 + N10 < 0, K11 + N10, 0) -> 0 | O11: =IF(L11 + O10 < 0, L11 + O10, 0) -> 0 | P11: =IF(O11 < 0, 1 + P10, 0) -> 0 | Q11: =IF(E11<0,1,0) -> 0 | R11: =IF(Q11=1,E11,0) -> 0 | S11: =IF(E11>0,1,0) -> 0 | T11: =IF(S11=1,E11,0) -> 0 | U11: =IF(R11<-100000000/100,1,0) -> 0 | V11: =IF(T11>100000000/100,1,0) -> 0 | W11: =IF(L11<0,1,0) -> 0 | X11: =IF(W11=1,L11,0) -> 0 | Y11: =IF(L11>0,1,0) -> 0 | Z11: =IF(Y11=1,L11,0) -> 0 | AA11: =IF(X11<-100000000/100,1,0) -> 0 | AB11: =IF(Z11>100000000/100,1,0) -> 0
A12: 44946 | B12: Friday | C12: =SUM(PL!E12:H12) -> 0 | D12: =SUM(PL!I12:L12) -> 0 | E12: =SUM(C12:D12) -> 0 | F12: =IF(C12 + F11 < 0, C12 + F11, 0) -> 0 | G12: =IF(D12 + G11 < 0, D12 + G11, 0) -> 0 | H12: =IF(E12 + H11 < 0, E12 + H11, 0) -> 0 | I12: =IF(H12 < 0, 1 + I11, 0) -> 0 | J12: =C12-((ABS(SUM(PL!E12:H12)))*0.125) -> 0 | K12: =D12-((ABS(SUM(PL!I12:L12)))*0.125) -> 0 | L12: =J12 + K12 -> 0 | M12: =IF(J12 + M11 < 0, J12 + M11, 0) -> 0 | N12: =IF(K12 + N11 < 0, K12 + N11, 0) -> 0 | O12: =IF(L12 + O11 < 0, L12 + O11, 0) -> 0 | P12: =IF(O12 < 0, 1 + P11, 0) -> 0 | Q12: =IF(E12<0,1,0) -> 0 | R12: =IF(Q12=1,E12,0) -> 0 | S12: =IF(E12>0,1,0) -> 0 | T12: =IF(S12=1,E12,0) -> 0 | U12: =IF(R12<-100000000/100,1,0) -> 0 | V12: =IF(T12>100000000/100,1,0) -> 0 | W12: =IF(L12<0,1,0) -> 0 | X12: =IF(W12=1,L12,0) -> 0 | Y12: =IF(L12>0,1,0) -> 0 | Z12: =IF(Y12=1,L12,0) -> 0 | AA12: =IF(X12<-100000000/100,1,0) -> 0 | AB12: =IF(Z12>100000000/100,1,0) -> 0
A13: 44949 | B13: Monday | C13: =SUM(PL!E13:H13) -> 0 | D13: =SUM(PL!I13:L13) -> 0 | E13: =SUM(C13:D13) -> 0 | F13: =IF(C13 + F12 < 0, C13 + F12, 0) -> 0 | G13: =IF(D13 + G12 < 0, D13 + G12, 0) -> 0 | H13: =IF(E13 + H12 < 0, E13 + H12, 0) -> 0 | I13: =IF(H13 < 0, 1 + I12, 0) -> 0 | J13: =C13-((ABS(SUM(PL!E13:H13)))*0.125) -> 0 | K13: =D13-((ABS(SUM(PL!I13:L13)))*0.125) -> 0 | L13: =J13 + K13 -> 0 | M13: =IF(J13 + M12 < 0, J13 + M12, 0) -> 0 | N13: =IF(K13 + N12 < 0, K13 + N12, 0) -> 0 | O13: =IF(L13 + O12 < 0, L13 + O12, 0) -> 0 | P13: =IF(O13 < 0, 1 + P12, 0) -> 0 | Q13: =IF(E13<0,1,0) -> 0 | R13: =IF(Q13=1,E13,0) -> 0 | S13: =IF(E13>0,1,0) -> 0 | T13: =IF(S13=1,E13,0) -> 0 | U13: =IF(R13<-100000000/100,1,0) -> 0 | V13: =IF(T13>100000000/100,1,0) -> 0 | W13: =IF(L13<0,1,0) -> 0 | X13: =IF(W13=1,L13,0) -> 0 | Y13: =IF(L13>0,1,0) -> 0 | Z13: =IF(Y13=1,L13,0) -> 0 | AA13: =IF(X13<-100000000/100,1,0) -> 0 | AB13: =IF(Z13>100000000/100,1,0) -> 0
A14: 44950 | B14: Tuesday | C14: =SUM(PL!E14:H14) -> 0 | D14: =SUM(PL!I14:L14) -> 0 | E14: =SUM(C14:D14) -> 0 | F14: =IF(C14 + F13 < 0, C14 + F13, 0) -> 0 | G14: =IF(D14 + G13 < 0, D14 + G13, 0) -> 0 | H14: =IF(E14 + H13 < 0, E14 + H13, 0) -> 0 | I14: =IF(H14 < 0, 1 + I13, 0) -> 0 | J14: =C14-((ABS(SUM(PL!E14:H14)))*0.125) -> 0 | K14: =D14-((ABS(SUM(PL!I14:L14)))*0.125) -> 0 | L14: =J14 + K14 -> 0 | M14: =IF(J14 + M13 < 0, J14 + M13, 0) -> 0 | N14: =IF(K14 + N13 < 0, K14 + N13, 0) -> 0 | O14: =IF(L14 + O13 < 0, L14 + O13, 0) -> 0 | P14: =IF(O14 < 0, 1 + P13, 0) -> 0 | Q14: =IF(E14<0,1,0) -> 0 | R14: =IF(Q14=1,E14,0) -> 0 | S14: =IF(E14>0,1,0) -> 0 | T14: =IF(S14=1,E14,0) -> 0 | U14: =IF(R14<-100000000/100,1,0) -> 0 | V14: =IF(T14>100000000/100,1,0) -> 0 | W14: =IF(L14<0,1,0) -> 0 | X14: =IF(W14=1,L14,0) -> 0 | Y14: =IF(L14>0,1,0) -> 0 | Z14: =IF(Y14=1,L14,0) -> 0 | AA14: =IF(X14<-100000000/100,1,0) -> 0 | AB14: =IF(Z14>100000000/100,1,0) -> 0
... A722: 46034 | B722: Monday | C722: =SUM(PL!E722:H722) -> 0 | D722: =SUM(PL!I722:L722) -> 0 | E722: =SUM(C722:D722) -> 0 | F722: =IF(C722 + F721 < 0, C722 + F721, 0) -> 0 | G722: =IF(D722 + G721 < 0, D722 + G721, 0) -> 0 | H722: =IF(E722 + H721 < 0, E722 + H721, 0) -> 0 | I722: =IF(H722 < 0, 1 + I721, 0) -> 0 | J722: =C722-((ABS(SUM(PL!E722:H722)))*0.125) -> 0 | K722: =D722-((ABS(SUM(PL!I722:L722)))*0.125) -> 0 | L722: =J722 + K722 -> 0 | M722: =IF(J722 + M721 < 0, J722 + M721, 0) -> 0 | N722: =IF(K722 + N721 < 0, K722 + N721, 0) -> 0 | O722: =IF(L722 + O721 < 0, L722 + O721, 0) -> 0 | P722: =IF(O722 < 0, 1 + P721, 0) -> 0 | Q722: =IF(E722<0,1,0) -> 0 | R722: =IF(Q722=1,E722,0) -> 0 | S722: =IF(E722>0,1,0) -> 0 | T722: =IF(S722=1,E722,0) -> 0 | U722: =IF(R722<-100000000/100,1,0) -> 0 | V722: =IF(T722>100000000/100,1,0) -> 0 | W722: =IF(L722<0,1,0) -> 0 | X722: =IF(W722=1,L722,0) -> 0 | Y722: =IF(L722>0,1,0) -> 0 | Z722: =IF(Y722=1,L722,0) -> 0 | AA722: =IF(X722<-100000000/100,1,0) -> 0 | AB722: =IF(Z722>100000000/100,1,0) -> 0
A723: Total | C723: =SUM(C2:C722) -> 0 | D723: =SUM(D2:D722) -> 0 | E723: =SUM(E2:E722) -> 0 | F723: =MIN(F2:F722) -> 0 | G723: =MIN(G2:G722) -> 0 | H723: =MIN(H2:H722) -> 0 | I723: =MAX(I2:I722) -> 0 | J723: =SUM(J2:J722) -> 0 | K723: =SUM(K2:K722) -> 0 | L723: =SUM(L2:L722) -> 0 | M723: =MIN(M2:M722) -> 0 | N723: =MIN(N2:N722) -> 0 | O723: =MIN(O2:O722) -> 0 | P723: =MAX(P2:P722) -> 0 | Q723: =SUM(Q2:Q722) -> 0 | R723: =SUM(R2:R722) -> 0 | S723: =SUM(S2:S722) -> 0 | T723: =SUM(T2:T722) -> 0 | U723: =SUM(U2:U722) -> 0 | V723: =SUM(V2:V722) -> 0 | W723: =SUM(W2:W722) -> 0 | X723: =SUM(X2:X722) -> 0 | ... AB723: =SUM(AB2:AB722) -> 0
A724: Months | C724: 36.36 | D724: 36.36 | J724: 36.36 | K724: 36.36 | R724: =R723/Q723 -> 0 | T724: =T723/S723 -> 0 | X724: =X723/W723 -> 0 | Z724: =Z723/Y723 -> 0
A725: Per Month | C725: =C723/C724 -> 0 | D725: =D723/D724 -> 0 | E725: =C725+D725 -> 0 | J725: =J723/J724 -> 0 | K725: =K723/K724 -> 0 | L725: =J725+K725 -> 0 | T725: =T724/R724*-1 -> 0 | Z725: =Z724/X724*-1 -> 0
