Workbook

Sheet PL
A1: Date | B1: Day | C1: BN DTE | D1: FN DTE | E1: MCN DTE | F1: NF DTE | G1: SX DTE | H1: BN SREW_RANGE_1 | I1: BN SREW_RANGE_2 | J1: BN SREW_RANGE_3 | K1: FN SREW_RANGE_1 | L1: FN SREW_RANGE_2 | M1: FN SREW_RANGE_3 | N1: MCN SREW_RANGE_1 | O1: MCN SREW_RANGE_2 | P1: MCN SREW_RANGE_3 | Q1: NF SREW_RANGE_1 | R1: NF SREW_RANGE_2 | S1: NF SREW_RANGE_3 | T1: SX SREW_RANGE_1 | U1: SX SREW_RANGE_2 | V1: SX SREW_RANGE_3
A2: 45292 | B2: Monday | C2: 22 | D2: 21 | E2: 20 | F2: 4 | G2: 5 | H2: 0 | I2: 0 | J2: 0 | K2: 0 | L2: 0 | M2: 0 | N2: 0 | O2: 0 | P2: 0 | Q2: 0 | R2: 0 | S2: 0 | T2: 0 | U2: 0 | V2: 0
A3: 45293 | B3: Tuesday | C3: 21 | D3: 20 | E3: 19 | F3: 3 | G3: 4 | H3: 0 | I3: 0 | J3: 0 | K3: 0 | L3: 0 | M3: 0 | N3: 0 | O3: 0 | P3: 0 | Q3: 0 | R3: 0 | S3: 0 | T3: 0 | U3: 0 | V3: 0
A4: 45294 | B4: Wednesday | C4: 20 | D4: 19 | E4: 18 | F4: 2 | G4: 3 | H4: 0 | I4: 0 | J4: 0 | K4: 0 | L4: 0 | M4: 0 | N4: 0 | O4: 0 | P4: 0 | Q4: 0 | R4: 0 | S4: 0 | T4: 0 | U4: 0 | V4: 0
A5: 45295 | B5: Thursday | C5: 19 | D5: 18 | E5: 17 | F5: 1 | G5: 2 | H5: 0 | I5: 0 | J5: 0 | K5: 0 | L5: 0 | M5: 0 | N5: 0 | O5: 0 | P5: 0 | Q5: 455690.9 | R5: 455690.9 | S5: 348728.05 | T5: 0 | U5: 0 | V5: 0
A6: 45296 | B6: Friday | C6: 18 | D6: 17 | E6: 16 | F6: 5 | G6: 1 | H6: 0 | I6: 0 | J6: 0 | K6: 0 | L6: 0 | M6: 0 | N6: 0 | O6: 0 | P6: 0 | Q6: 0 | R6: 0 | S6: 0 | T6: 478763.58 | U6: 628942.74 | V6: 373411.28
A7: 45299 | B7: Monday | C7: 17 | D7: 16 | E7: 15 | F7: 4 | G7: 5 | H7: 0 | I7: 0 | J7: 0 | K7: 0 | L7: 0 | M7: 0 | N7: 0 | O7: 0 | P7: 0 | Q7: 0 | R7: 0 | S7: 0 | T7: 0 | U7: 0 | V7: 0
A8: 45300 | B8: Tuesday | C8: 16 | D8: 15 | E8: 14 | F8: 3 | G8: 4 | H8: 0 | I8: 0 | J8: 0 | K8: 0 | L8: 0 | M8: 0 | N8: 0 | O8: 0 | P8: 0 | Q8: 0 | R8: 0 | S8: 0 | T8: 0 | U8: 0 | V8: 0
A9: 45301 | B9: Wednesday | C9: 15 | D9: 14 | E9: 13 | F9: 2 | G9: 3 | H9: 0 | I9: 0 | J9: 0 | K9: 0 | L9: 0 | M9: 0 | N9: 0 | O9: 0 | P9: 0 | Q9: 0 | R9: 0 | S9: 0 | T9: 0 | U9: 0 | V9: 0
A10: 45302 | B10: Thursday | C10: 14 | D10: 13 | E10: 12 | F10: 1 | G10: 2 | H10: 0 | I10: 0 | J10: 0 | K10: 0 | L10: 0 | M10: 0 | N10: 0 | O10: 0 | P10: 0 | Q10: -26527.928 | R10: 33178.176 | S10: -30199.266 | T10: 0 | U10: 0 | V10: 0
A11: 45303 | B11: Friday | C11: 13 | D11: 12 | E11: 11 | F11: 5 | G11: 1 | H11: 0 | I11: 0 | J11: 0 | K11: 0 | L11: 0 | M11: 0 | N11: 0 | O11: 0 | P11: 0 | Q11: 0 | R11: 0 | S11: 0 | T11: 180419.87 | U11: -383256.25 | V11: -337717.59
A12: 45306 | B12: Monday | C12: 12 | D12: 11 | E12: 10 | F12: 4 | G12: 5 | H12: 0 | I12: 0 | J12: 0 | K12: 0 | L12: 0 | M12: 0 | N12: 0 | O12: 0 | P12: 0 | Q12: 0 | R12: 0 | S12: 0 | T12: 0 | U12: 0 | V12: 0
A13: 45307 | B13: Tuesday | C13: 11 | D13: 10 | E13: 9 | F13: 3 | G13: 4 | H13: 0 | I13: 0 | J13: 0 | K13: 0 | L13: 0 | M13: 0 | N13: 0 | O13: 0 | P13: 0 | Q13: 0 | R13: 0 | S13: 0 | T13: 0 | U13: 0 | V13: 0
... A510: 46044 | B510: Thursday | C510: 3 | D510: 3 | E510: 3 | F510: 3 | G510: 1 | H510: 0 | I510: 0 | J510: 0 | K510: 0 | L510: 0 | M510: 0 | N510: 0 | O510: 0 | P510: 0 | Q510: 0 | R510: 0 | S510: 0 | T510: -1283735.5 | U510: -1008638.6 | V510: -1145294.3

Sheet Exit Times
A1: Date | B1: BANKNIFTY | C1: BANKNIFTY SREW_RANGE_1 5-1 | D1: BANKNIFTY SREW_RANGE_2 4-1 | E1: BANKNIFTY SREW_RANGE_3 3-1 | F1: FINNIFTY | G1: FINNIFTY SREW_RANGE_1 5-1 | H1: FINNIFTY SREW_RANGE_2 4-1 | I1: FINNIFTY SREW_RANGE_3 3-1 | J1: MIDCPNIFTY | K1: MIDCPNIFTY SREW_RANGE_1 5-1 | L1: MIDCPNIFTY SREW_RANGE_2 4-1 | M1: MIDCPNIFTY SREW_RANGE_3 3-1 | N1: NIFTY | O1: NIFTY SREW_RANGE_1 5-1 | P1: NIFTY SREW_RANGE_2 4-1 | Q1: NIFTY SREW_RANGE_3 3-1 | R1: SENSEX | S1: SENSEX SREW_RANGE_1 5-1 | T1: SENSEX SREW_RANGE_2 4-1 | U1: SENSEX SREW_RANGE_3 3-1
A2: 45292 | B2: 1 15:29:00 | C2: 0 | D2: 0 | E2: 0 | F2: 1 15:29:00 | G2: 0 | H2: 0 | I2: 0 | J2: 1 15:29:00 | K2: 0 | L2: 0 | M2: 0 | N2: 1 15:29:00 | O2: 1 15:29:00 | P2: 1 15:29:00 | Q2: 0 | R2: 1 15:29:00 | S2: 1 15:29:00 | T2: 0 | U2: 0
A3: 45293 | B3: 1 15:29:00 | C3: 0 | D3: 0 | E3: 0 | F3: 1 15:29:00 | G3: 0 | H3: 0 | I3: 0 | J3: 1 15:29:00 | K3: 0 | L3: 0 | M3: 0 | N3: 1 15:29:00 | O3: 0 | P3: 0 | Q3: 1 15:29:00 | R3: 1 15:29:00 | S3: 0 | T3: 1 15:29:00 | U3: 0
A4: 45294 | B4: 1 15:29:00 | C4: 0 | D4: 0 | E4: 0 | F4: 1 15:29:00 | G4: 0 | H4: 0 | I4: 0 | J4: 1 15:29:00 | K4: 0 | L4: 0 | M4: 0 | N4: 1 15:29:00 | O4: 0 | P4: 0 | Q4: 0 | R4: 1 15:29:00 | S4: 0 | T4: 0 | U4: 1 15:29:00
A5: 45295 | B5: 1 15:29:00 | C5: 0 | D5: 0 | E5: 0 | F5: 1 15:29:00 | G5: 0 | H5: 0 | I5: 0 | J5: 1 15:29:00 | K5: 0 | L5: 0 | M5: 0 | N5: 1 15:29:00 | O5: 0 | P5: 0 | Q5: 0 | R5: 1 15:29:00 | S5: 0 | T5: 0 | U5: 0
A6: 45296 | B6: 1 15:29:00 | C6: 0 | D6: 0 | E6: 0 | F6: 1 15:29:00 | G6: 0 | H6: 0 | I6: 0 | J6: 1 15:29:00 | K6: 0 | L6: 0 | M6: 0 | N6: 1 15:29:00 | O6: 1 15:29:00 | P6: 0 | Q6: 0 | R6: 1 15:29:00 | S6: 0 | T6: 0 | U6: 0
A7: 45299 | B7: 1 15:29:00 | C7: 0 | D7: 0 | E7: 0 | F7: 1 15:29:00 | G7: 0 | H7: 0 | I7: 0 | J7: 1 15:29:00 | K7: 0 | L7: 0 | M7: 0 | N7: 1 15:29:00 | O7: 0 | P7: 1 15:29:00 | Q7: 0 | R7: 1 15:29:00 | S7: 1 15:29:00 | T7: 0 | U7: 0
A8: 45300 | B8: 1 15:29:00 | C8: 0 | D8: 0 | E8: 0 | F8: 1 15:29:00 | G8: 0 | H8: 0 | I8: 0 | J8: 1 15:29:00 | K8: 0 | L8: 0 | M8: 0 | N8: 1 15:29:00 | O8: 0 | P8: 0 | Q8: 1 15:29:00 | R8: 1 15:29:00 | S8: 0 | T8: 1 15:29:00 | U8: 0
A9: 45301 | B9: 1 15:29:00 | C9: 0 | D9: 0 | E9: 0 | F9: 1 15:29:00 | G9: 0 | H9: 0 | I9: 0 | J9: 1 15:29:00 | K9: 0 | L9: 0 | M9: 0 | N9: 1 15:29:00 | O9: 0 | P9: 0 | Q9: 0 | R9: 1 15:29:00 | S9: 0 | T9: 0 | U9: 1 15:29:00
A10: 45302 | B10: 1 15:29:00 | C10: 0 | D10: 0 | E10: 0 | F10: 1 15:29:00 | G10: 0 | H10: 0 | I10: 0 | J10: 1 15:29:00 | K10: 0 | L10: 0 | M10: 0 | N10: 1 15:29:00 | O10: 0 | P10: 0 | Q10: 0 | R10: 1 15:29:00 | S10: 0 | T10: 0 | U10: 0
A11: 45303 | B11: 1 15:29:00 | C11: 0 | D11: 0 | E11: 0 | F11: 1 15:29:00 | G11: 0 | H11: 0 | I11: 0 | J11: 1 15:29:00 | K11: 0 | L11: 0 | M11: 0 | N11: 1 15:29:00 | O11: 1 15:29:00 | P11: 0 | Q11: 0 | R11: 1 15:29:00 | S11: 0 | T11: 0 | U11: 0
A12: 45306 | B12: 1 15:29:00 | C12: 0 | D12: 0 | E12: 0 | F12: 1 15:29:00 | G12: 0 | H12: 0 | I12: 0 | J12: 1 15:29:00 | K12: 0 | L12: 0 | M12: 0 | N12: 1 15:29:00 | O12: 0 | P12: 1 15:29:00 | Q12: 0 | R12: 1 15:29:00 | S12: 1 15:29:00 | T12: 0 | U12: 0
A13: 45307 | B13: 1 15:29:00 | C13: 0 | D13: 0 | E13: 0 | F13: 1 15:29:00 | G13: 0 | H13: 0 | I13: 0 | J13: 1 15:29:00 | K13: 0 | L13: 0 | M13: 0 | N13: 1 15:29:00 | O13: 0 | P13: 0 | Q13: 1 15:29:00 | R13: 1 15:29:00 | S13: 0 | T13: 1 15:29:00 | U13: 0
A14: 45308 | B14: 1 15:29:00 | C14: 0 | D14: 0 | E14: 0 | F14: 1 15:29:00 | G14: 0 | H14: 0 | I14: 0 | J14: 1 15:29:00 | K14: 0 | L14: 0 | M14: 0 | N14: 1 15:29:00 | O14: 0 | P14: 0 | Q14: 0 | R14: 1 15:29:00 | S14: 0 | T14: 0 | U14: 1 15:29:00
A15: 45309 | B15: 1 15:29:00 | C15: 0 | D15: 0 | E15: 0 | F15: 1 15:29:00 | G15: 0 | H15: 0 | I15: 0 | J15: 1 15:29:00 | K15: 0 | L15: 0 | M15: 0 | N15: 1 15:29:00 | O15: 0 | P15: 0 | Q15: 0 | R15: 1 15:29:00 | S15: 0 | T15: 0 | U15: 0
A16: 45310 | B16: 1 15:29:00 | C16: 0 | D16: 0 | E16: 0 | F16: 1 15:29:00 | G16: 0 | H16: 0 | I16: 0 | J16: 1 15:29:00 | K16: 0 | L16: 0 | M16: 0 | N16: 1 15:29:00 | O16: 1 15:29:00 | P16: 0 | Q16: 0 | R16: 1 15:29:00 | S16: 0 | T16: 0 | U16: 0
A17: 45311 | B17: 1 15:29:00 | C17: 0 | D17: 0 | E17: 0 | F17: 1 15:29:00 | G17: 0 | H17: 0 | I17: 0 | J17: 1 15:29:00 | K17: 1 15:29:00 | L17: 0 | M17: 0 | N17: 1 15:29:00 | O17: 0 | P17: 1 15:29:00 | Q17: 0 | R17: 1 15:29:00 | S17: 1 15:29:00 | T17: 1 15:29:00 | U17: 0
A18: 45314 | B18: 1 15:29:00 | C18: 0 | D18: 0 | E18: 0 | F18: 1 15:29:00 | G18: 1 15:29:00 | H18: 0 | I18: 0 | J18: 1 15:29:00 | K18: 0 | L18: 1 15:29:00 | M18: 0 | N18: 1 15:29:00 | O18: 0 | P18: 0 | Q18: 1 15:29:00 | R18: 1 15:29:00 | S18: 0 | T18: 0 | U18: 1 15:29:00
A19: 45315 | B19: 1 15:29:00 | C19: 1 15:29:00 | D19: 0 | E19: 0 | F19: 1 15:29:00 | G19: 0 | H19: 1 15:29:00 | I19: 0 | J19: 1 15:29:00 | K19: 0 | L19: 0 | M19: 1 15:29:00 | N19: 1 15:29:00 | O19: 0 | P19: 0 | Q19: 0 | R19: 1 15:29:00 | S19: 0 | T19: 0 | U19: 0
A20: 45316 | B20: 1 15:29:00 | C20: 0 | D20: 1 15:29:00 | E20: 0 | F20: 1 15:29:00 | G20: 0 | H20: 0 | I20: 1 15:29:00 | J20: 1 15:29:00 | K20: 0 | L20: 0 | M20: 0 | N20: 1 15:29:00 | O20: 0 | P20: 0 | Q20: 0 | R20: 1 09:23:00 | S20: 0 | T20: 0 | U20: 0
A21: 45320 | B21: 1 15:29:00 | C21: 0 | D21: 0 | E21: 1 15:29:00 | F21: 1 15:29:00 | G21: 0 | H21: 0 | I21: 0 | J21: 1 15:29:00 | K21: 0 | L21: 0 | M21: 0 | N21: 1 15:29:00 | O21: 1 15:29:00 | P21: 1 15:29:00 | Q21: 0 | R21: 1 15:29:00 | S21: 1 15:29:00 | T21: 0 | U21: 0
A22: 45321 | B22: 1 15:29:00 | C22: 0 | D22: 0 | E22: 0 | F22: 1 15:29:00 | G22: 0 | H22: 0 | I22: 0 | J22: 1 15:29:00 | K22: 0 | L22: 0 | M22: 0 | N22: 1 15:29:00 | O22: 0 | P22: 0 | Q22: 1 15:29:00 | R22: 1 15:29:00 | S22: 0 | T22: 1 15:29:00 | U22: 0
A23: 45322 | B23: 1 15:29:00 | C23: 0 | D23: 0 | E23: 0 | F23: 1 15:29:00 | G23: 0 | H23: 0 | I23: 0 | J23: 1 15:29:00 | K23: 0 | L23: 0 | M23: 0 | N23: 1 15:29:00 | O23: 0 | P23: 0 | Q23: 0 | R23: 1 15:29:00 | S23: 0 | T23: 0 | U23: 1 15:29:00
A24: 45323 | B24: 1 15:29:00 | C24: 0 | D24: 0 | E24: 0 | F24: 1 15:29:00 | G24: 0 | H24: 0 | I24: 0 | J24: 1 15:29:00 | K24: 0 | L24: 0 | M24: 0 | N24: 1 15:29:00 | O24: 0 | P24: 0 | Q24: 0 | R24: 1 15:29:00 | S24: 0 | T24: 0 | U24: 0
A25: 45324 | B25: 1 15:29:00 | C25: 0 | D25: 0 | E25: 0 | F25: 1 15:29:00 | G25: 0 | H25: 0 | I25: 0 | J25: 1 15:29:00 | K25: 0 | L25: 0 | M25: 0 | N25: 1 15:29:00 | O25: 1 15:29:00 | P25: 0 | Q25: 0 | R25: 2 12:18:00 | S25: 0 | T25: 0 | U25: 0
A26: 45327 | B26: 1 15:29:00 | C26: 0 | D26: 0 | E26: 0 | F26: 1 15:29:00 | G26: 0 | H26: 0 | I26: 0 | J26: 1 15:29:00 | K26: 0 | L26: 0 | M26: 0 | N26: 1 15:29:00 | O26: 0 | P26: 1 15:29:00 | Q26: 0 | R26: 1 15:29:00 | S26: 1 15:29:00 | T26: 0 | U26: 0
A27: 45328 | B27: 1 15:29:00 | C27: 0 | D27: 0 | E27: 0 | F27: 1 15:29:00 | G27: 0 | H27: 0 | I27: 0 | J27: 1 15:29:00 | K27: 0 | L27: 0 | M27: 0 | N27: 1 15:29:00 | O27: 0 | P27: 0 | Q27: 1 15:29:00 | R27: 1 15:29:00 | S27: 0 | T27: 1 15:29:00 | U27: 0
A28: 45329 | B28: 1 15:29:00 | C28: 0 | D28: 0 | E28: 0 | F28: 1 15:29:00 | G28: 0 | H28: 0 | I28: 0 | J28: 1 15:29:00 | K28: 0 | L28: 0 | M28: 0 | N28: 1 15:29:00 | O28: 0 | P28: 0 | Q28: 0 | R28: 1 15:29:00 | S28: 0 | T28: 0 | U28: 1 15:29:00
A29: 45330 | B29: 1 15:29:00 | C29: 0 | D29: 0 | E29: 0 | F29: 1 15:29:00 | G29: 0 | H29: 0 | I29: 0 | J29: 1 15:29:00 | K29: 0 | L29: 0 | M29: 0 | N29: 1 15:29:00 | O29: 0 | P29: 0 | Q29: 0 | R29: 1 15:29:00 | S29: 0 | T29: 0 | U29: 0
A30: 45331 | B30: 1 15:29:00 | C30: 0 | D30: 0 | E30: 0 | F30: 1 15:29:00 | G30: 0 | H30: 0 | I30: 0 | J30: 1 15:29:00 | K30: 0 | L30: 0 | M30: 0 | N30: 1 15:29:00 | O30: 1 15:29:00 | P30: 0 | Q30: 0 | R30: 1 14:08:00 | S30: 0 | T30: 0 | U30: 0
A31: 45334 | B31: 1 15:29:00 | C31: 0 | D31: 0 | E31: 0 | F31: 1 15:29:00 | G31: 0 | H31: 0 | I31: 0 | J31: 1 15:29:00 | K31: 0 | L31: 0 | M31: 0 | N31: 1 15:29:00 | O31: 0 | P31: 1 15:29:00 | Q31: 0 | R31: 1 15:29:00 | S31: 1 15:29:00 | T31: 0 | U31: 0
A32: 45335 | B32: 1 15:29:00 | C32: 0 | D32: 0 | E32: 0 | F32: 1 15:29:00 | G32: 0 | H32: 0 | I32: 0 | J32: 1 15:29:00 | K32: 0 | L32: 0 | M32: 0 | N32: 1 15:29:00 | O32: 0 | P32: 0 | Q32: 1 15:29:00 | R32: 1 15:29:00 | S32: 0 | T32: 1 15:29:00 | U32: 0
A33: 45336 | B33: 1 15:29:00 | C33: 0 | D33: 0 | E33: 0 | F33: 1 15:29:00 | G33: 0 | H33: 0 | I33: 0 | J33: 1 15:29:00 | K33: 0 | L33: 0 | M33: 0 | N33: 1 15:29:00 | O33: 0 | P33: 0 | Q33: 0 | R33: 1 15:29:00 | S33: 0 | T33: 0 | U33: 1 15:29:00
A34: 45337 | B34: 1 15:29:00 | C34: 0 | D34: 0 | E34: 0 | F34: 1 15:29:00 | G34: 0 | H34: 0 | I34: 0 | J34: 1 15:29:00 | K34: 0 | L34: 0 | M34: 0 | N34: 1 15:29:00 | O34: 0 | P34: 0 | Q34: 0 | R34: 1 15:29:00 | S34: 0 | T34: 0 | U34: 0
A35: 45338 | B35: 1 15:29:00 | C35: 0 | D35: 0 | E35: 0 | F35: 1 15:29:00 | G35: 0 | H35: 0 | I35: 0 | J35: 1 15:29:00 | K35: 0 | L35: 0 | M35: 0 | N35: 1 15:29:00 | O35: 1 15:29:00 | P35: 0 | Q35: 0 | R35: 1 15:29:00 | S35: 0 | T35: 0 | U35: 0
A36: 45341 | B36: 1 15:29:00 | C36: 0 | D36: 0 | E36: 0 | F36: 1 15:29:00 | G36: 0 | H36: 0 | I36: 0 | J36: 1 15:29:00 | K36: 0 | L36: 0 | M36: 0 | N36: 1 15:29:00 | O36: 0 | P36: 1 15:29:00 | Q36: 0 | R36: 1 15:29:00 | S36: 1 15:29:00 | T36: 0 | U36: 0
A37: 45342 | B37: 1 15:29:00 | C37: 0 | D37: 0 | E37: 0 | F37: 1 15:29:00 | G37: 0 | H37: 0 | I37: 0 | J37: 1 15:29:00 | K37: 1 15:29:00 | L37: 0 | M37: 0 | N37: 1 15:29:00 | O37: 0 | P37: 0 | Q37: 1 15:29:00 | R37: 1 15:29:00 | S37: 0 | T37: 1 15:29:00 | U37: 0
A38: 45343 | B38: 1 15:29:00 | C38: 0 | D38: 0 | E38: 0 | F38: 1 15:29:00 | G38: 1 15:29:00 | H38: 0 | I38: 0 | J38: 1 15:29:00 | K38: 0 | L38: 1 15:29:00 | M38: 0 | N38: 1 15:29:00 | O38: 0 | P38: 0 | Q38: 0 | R38: 1 15:29:00 | S38: 0 | T38: 0 | U38: 1 15:29:00
A39: 45344 | B39: 1 15:29:00 | C39: 0 | D39: 0 | E39: 0 | F39: 1 15:29:00 | G39: 0 | H39: 1 15:29:00 | I39: 0 | J39: 1 15:29:00 | K39: 0 | L39: 0 | M39: 1 15:29:00 | N39: 1 15:29:00 | O39: 0 | P39: 0 | Q39: 0 | R39: 1 15:29:00 | S39: 0 | T39: 0 | U39: 0
A40: 45345 | B40: 1 15:29:00 | C40: 1 15:29:00 | D40: 0 | E40: 0 | F40: 1 15:29:00 | G40: 0 | H40: 0 | I40: 1 15:29:00 | J40: 1 15:29:00 | K40: 0 | L40: 0 | M40: 0 | N40: 1 15:29:00 | O40: 1 15:29:00 | P40: 0 | Q40: 0 | R40: 1 15:29:00 | S40: 0 | T40: 0 | U40: 0
...

Sheet StgWiseDD
A1: Date | B1: Day | C1: BN DTE | D1: FN DTE | E1: MCN DTE | F1: NF DTE | G1: SX DTE | H1: BN SREW_RANGE_1 | I1: DD BN SREW_RANGE_1 | J1: BN SREW_RANGE_2 | K1: DD BN SREW_RANGE_2 | L1: BN SREW_RANGE_3 | M1: DD BN SREW_RANGE_3 | N1: FN SREW_RANGE_1 | O1: DD FN SREW_RANGE_1 | P1: FN SREW_RANGE_2 | Q1: DD FN SREW_RANGE_2 | R1: FN SREW_RANGE_3 | S1: DD FN SREW_RANGE_3 | T1: MCN SREW_RANGE_1 | U1: DD MCN SREW_RANGE_1 | V1: MCN SREW_RANGE_2 | W1: DD MCN SREW_RANGE_2 | X1: MCN SREW_RANGE_3 | Y1: DD MCN SREW_RANGE_3 | Z1: NF SREW_RANGE_1 | AA1: DD NF SREW_RANGE_1 | AB1: NF SREW_RANGE_2 | AC1: DD NF SREW_RANGE_2 | AD1: NF SREW_RANGE_3 | AE1: DD NF SREW_RANGE_3 | AF1: SX SREW_RANGE_1 | AG1: DD SX SREW_RANGE_1 | AH1: SX SREW_RANGE_2 | AI1: DD SX SREW_RANGE_2 | AJ1: SX SREW_RANGE_3 | AK1: DD SX SREW_RANGE_3
A2: 45292 | B2: Monday | C2: 22 | D2: 21 | E2: 20 | F2: 4 | G2: 5 | H2: 0 | I2: =IF(H2 < 0, H2, 0) -> 0 | J2: 0 | K2: =IF(J2 < 0, J2, 0) -> 0 | L2: 0 | M2: =IF(L2 < 0, L2, 0) -> 0 | N2: 0 | O2: =IF(N2 < 0, N2, 0) -> 0 | P2: 0 | Q2: =IF(P2 < 0, P2, 0) -> 0 | R2: 0 | S2: =IF(R2 < 0, R2, 0) -> 0 | T2: 0 | U2: =IF(T2 < 0, T2, 0) -> 0 | V2: 0 | W2: =IF(V2 < 0, V2, 0) -> 0 | X2: 0 | Y2: =IF(X2 < 0, X2, 0) -> 0 | Z2: 0 | AA2: =IF(Z2 < 0, Z2, 0) -> 0 | AB2: 0 | AC2: =IF(AB2 < 0, AB2, 0) -> 0 | AD2: 0 | AE2: =IF(AD2 < 0, AD2, 0) -> 0 | AF2: 0 | AG2: =IF(AF2 < 0, AF2, 0) -> 0 | AH2: 0 | AI2: =IF(AH2 < 0, AH2, 0) -> 0 | AJ2: 0 | AK2: =IF(AJ2 < 0, AJ2, 0) -> 0
A3: 45293 | B3: Tuesday | C3: 21 | D3: 20 | E3: 19 | F3: 3 | G3: 4 | H3: 0 | I3: =IF(H3 + I2 < 0, H3 + I2, 0) -> 0 | J3: 0 | K3: =IF(J3 + K2 < 0, J3 + K2, 0) -> 0 | L3: 0 | M3: =IF(L3 + M2 < 0, L3 + M2, 0) -> 0 | N3: 0 | O3: =IF(N3 + O2 < 0, N3 + O2, 0) -> 0 | P3: 0 | Q3: =IF(P3 + Q2 < 0, P3 + Q2, 0) -> 0 | R3: 0 | S3: =IF(R3 + S2 < 0, R3 + S2, 0) -> 0 | T3: 0 | U3: =IF(T3 + U2 < 0, T3 + U2, 0) -> 0 | V3: 0 | W3: =IF(V3 + W2 < 0, V3 + W2, 0) -> 0 | X3: 0 | Y3: =IF(X3 + Y2 < 0, X3 + Y2, 0) -> 0 | Z3: 0 | AA3: =IF(Z3 + AA2 < 0, Z3 + AA2, 0) -> 0 | AB3: 0 | AC3: =IF(AB3 + AC2 < 0, AB3 + AC2, 0) -> 0 | AD3: 0 | AE3: =IF(AD3 + AE2 < 0, AD3 + AE2, 0) -> 0 | AF3: 0 | AG3: =IF(AF3 + AG2 < 0, AF3 + AG2, 0) -> 0 | AH3: 0 | AI3: =IF(AH3 + AI2 < 0, AH3 + AI2, 0) -> 0 | AJ3: 0 | AK3: =IF(AJ3 + AK2 < 0, AJ3 + AK2, 0) -> 0
A4: 45294 | B4: Wednesday | C4: 20 | D4: 19 | E4: 18 | F4: 2 | G4: 3 | H4: 0 | I4: =IF(H4 + I3 < 0, H4 + I3, 0) -> 0 | J4: 0 | K4: =IF(J4 + K3 < 0, J4 + K3, 0) -> 0 | L4: 0 | M4: =IF(L4 + M3 < 0, L4 + M3, 0) -> 0 | N4: 0 | O4: =IF(N4 + O3 < 0, N4 + O3, 0) -> 0 | P4: 0 | Q4: =IF(P4 + Q3 < 0, P4 + Q3, 0) -> 0 | R4: 0 | S4: =IF(R4 + S3 < 0, R4 + S3, 0) -> 0 | T4: 0 | U4: =IF(T4 + U3 < 0, T4 + U3, 0) -> 0 | V4: 0 | W4: =IF(V4 + W3 < 0, V4 + W3, 0) -> 0 | X4: 0 | Y4: =IF(X4 + Y3 < 0, X4 + Y3, 0) -> 0 | Z4: 0 | AA4: =IF(Z4 + AA3 < 0, Z4 + AA3, 0) -> 0 | AB4: 0 | AC4: =IF(AB4 + AC3 < 0, AB4 + AC3, 0) -> 0 | AD4: 0 | AE4: =IF(AD4 + AE3 < 0, AD4 + AE3, 0) -> 0 | AF4: 0 | AG4: =IF(AF4 + AG3 < 0, AF4 + AG3, 0) -> 0 | AH4: 0 | AI4: =IF(AH4 + AI3 < 0, AH4 + AI3, 0) -> 0 | AJ4: 0 | AK4: =IF(AJ4 + AK3 < 0, AJ4 + AK3, 0) -> 0
A5: 45295 | B5: Thursday | C5: 19 | D5: 18 | E5: 17 | F5: 1 | G5: 2 | H5: 0 | I5: =IF(H5 + I4 < 0, H5 + I4, 0) -> 0 | J5: 0 | K5: =IF(J5 + K4 < 0, J5 + K4, 0) -> 0 | L5: 0 | M5: =IF(L5 + M4 < 0, L5 + M4, 0) -> 0 | N5: 0 | O5: =IF(N5 + O4 < 0, N5 + O4, 0) -> 0 | P5: 0 | Q5: =IF(P5 + Q4 < 0, P5 + Q4, 0) -> 0 | R5: 0 | S5: =IF(R5 + S4 < 0, R5 + S4, 0) -> 0 | T5: 0 | U5: =IF(T5 + U4 < 0, T5 + U4, 0) -> 0 | V5: 0 | W5: =IF(V5 + W4 < 0, V5 + W4, 0) -> 0 | X5: 0 | Y5: =IF(X5 + Y4 < 0, X5 + Y4, 0) -> 0 | Z5: 455690.9 | AA5: =IF(Z5 + AA4 < 0, Z5 + AA4, 0) -> 0 | AB5: 455690.9 | AC5: =IF(AB5 + AC4 < 0, AB5 + AC4, 0) -> 0 | AD5: 348728.05 | AE5: =IF(AD5 + AE4 < 0, AD5 + AE4, 0) -> 0 | AF5: 0 | AG5: =IF(AF5 + AG4 < 0, AF5 + AG4, 0) -> 0 | AH5: 0 | AI5: =IF(AH5 + AI4 < 0, AH5 + AI4, 0) -> 0 | AJ5: 0 | AK5: =IF(AJ5 + AK4 < 0, AJ5 + AK4, 0) -> 0
A6: 45296 | B6: Friday | C6: 18 | D6: 17 | E6: 16 | F6: 5 | G6: 1 | H6: 0 | I6: =IF(H6 + I5 < 0, H6 + I5, 0) -> 0 | J6: 0 | K6: =IF(J6 + K5 < 0, J6 + K5, 0) -> 0 | L6: 0 | M6: =IF(L6 + M5 < 0, L6 + M5, 0) -> 0 | N6: 0 | O6: =IF(N6 + O5 < 0, N6 + O5, 0) -> 0 | P6: 0 | Q6: =IF(P6 + Q5 < 0, P6 + Q5, 0) -> 0 | R6: 0 | S6: =IF(R6 + S5 < 0, R6 + S5, 0) -> 0 | T6: 0 | U6: =IF(T6 + U5 < 0, T6 + U5, 0) -> 0 | V6: 0 | W6: =IF(V6 + W5 < 0, V6 + W5, 0) -> 0 | X6: 0 | Y6: =IF(X6 + Y5 < 0, X6 + Y5, 0) -> 0 | Z6: 0 | AA6: =IF(Z6 + AA5 < 0, Z6 + AA5, 0) -> 0 | AB6: 0 | AC6: =IF(AB6 + AC5 < 0, AB6 + AC5, 0) -> 0 | AD6: 0 | AE6: =IF(AD6 + AE5 < 0, AD6 + AE5, 0) -> 0 | AF6: 478763.58 | AG6: =IF(AF6 + AG5 < 0, AF6 + AG5, 0) -> 0 | AH6: 628942.74 | AI6: =IF(AH6 + AI5 < 0, AH6 + AI5, 0) -> 0 | AJ6: 373411.28 | AK6: =IF(AJ6 + AK5 < 0, AJ6 + AK5, 0) -> 0
A7: 45299 | B7: Monday | C7: 17 | D7: 16 | E7: 15 | F7: 4 | G7: 5 | H7: 0 | I7: =IF(H7 + I6 < 0, H7 + I6, 0) -> 0 | J7: 0 | K7: =IF(J7 + K6 < 0, J7 + K6, 0) -> 0 | L7: 0 | M7: =IF(L7 + M6 < 0, L7 + M6, 0) -> 0 | N7: 0 | O7: =IF(N7 + O6 < 0, N7 + O6, 0) -> 0 | P7: 0 | Q7: =IF(P7 + Q6 < 0, P7 + Q6, 0) -> 0 | R7: 0 | S7: =IF(R7 + S6 < 0, R7 + S6, 0) -> 0 | T7: 0 | U7: =IF(T7 + U6 < 0, T7 + U6, 0) -> 0 | V7: 0 | W7: =IF(V7 + W6 < 0, V7 + W6, 0) -> 0 | X7: 0 | Y7: =IF(X7 + Y6 < 0, X7 + Y6, 0) -> 0 | Z7: 0 | AA7: =IF(Z7 + AA6 < 0, Z7 + AA6, 0) -> 0 | AB7: 0 | AC7: =IF(AB7 + AC6 < 0, AB7 + AC6, 0) -> 0 | AD7: 0 | AE7: =IF(AD7 + AE6 < 0, AD7 + AE6, 0) -> 0 | AF7: 0 | AG7: =IF(AF7 + AG6 < 0, AF7 + AG6, 0) -> 0 | AH7: 0 | AI7: =IF(AH7 + AI6 < 0, AH7 + AI6, 0) -> 0 | AJ7: 0 | AK7: =IF(AJ7 + AK6 < 0, AJ7 + AK6, 0) -> 0
A8: 45300 | B8: Tuesday | C8: 16 | D8: 15 | E8: 14 | F8: 3 | G8: 4 | H8: 0 | I8: =IF(H8 + I7 < 0, H8 + I7, 0) -> 0 | J8: 0 | K8: =IF(J8 + K7 < 0, J8 + K7, 0) -> 0 | L8: 0 | M8: =IF(L8 + M7 < 0, L8 + M7, 0) -> 0 | N8: 0 | O8: =IF(N8 + O7 < 0, N8 + O7, 0) -> 0 | P8: 0 | Q8: =IF(P8 + Q7 < 0, P8 + Q7, 0) -> 0 | R8: 0 | S8: =IF(R8 + S7 < 0, R8 + S7, 0) -> 0 | T8: 0 | U8: =IF(T8 + U7 < 0, T8 + U7, 0) -> 0 | V8: 0 | W8: =IF(V8 + W7 < 0, V8 + W7, 0) -> 0 | X8: 0 | Y8: =IF(X8 + Y7 < 0, X8 + Y7, 0) -> 0 | Z8: 0 | AA8: =IF(Z8 + AA7 < 0, Z8 + AA7, 0) -> 0 | AB8: 0 | AC8: =IF(AB8 + AC7 < 0, AB8 + AC7, 0) -> 0 | AD8: 0 | AE8: =IF(AD8 + AE7 < 0, AD8 + AE7, 0) -> 0 | AF8: 0 | AG8: =IF(AF8 + AG7 < 0, AF8 + AG7, 0) -> 0 | AH8: 0 | AI8: =IF(AH8 + AI7 < 0, AH8 + AI7, 0) -> 0 | AJ8: 0 | AK8: =IF(AJ8 + AK7 < 0, AJ8 + AK7, 0) -> 0
A9: 45301 | B9: Wednesday | C9: 15 | D9: 14 | E9: 13 | F9: 2 | G9: 3 | H9: 0 | I9: =IF(H9 + I8 < 0, H9 + I8, 0) -> 0 | J9: 0 | K9: =IF(J9 + K8 < 0, J9 + K8, 0) -> 0 | L9: 0 | M9: =IF(L9 + M8 < 0, L9 + M8, 0) -> 0 | N9: 0 | O9: =IF(N9 + O8 < 0, N9 + O8, 0) -> 0 | P9: 0 | Q9: =IF(P9 + Q8 < 0, P9 + Q8, 0) -> 0 | R9: 0 | S9: =IF(R9 + S8 < 0, R9 + S8, 0) -> 0 | T9: 0 | U9: =IF(T9 + U8 < 0, T9 + U8, 0) -> 0 | V9: 0 | W9: =IF(V9 + W8 < 0, V9 + W8, 0) -> 0 | X9: 0 | Y9: =IF(X9 + Y8 < 0, X9 + Y8, 0) -> 0 | Z9: 0 | AA9: =IF(Z9 + AA8 < 0, Z9 + AA8, 0) -> 0 | AB9: 0 | AC9: =IF(AB9 + AC8 < 0, AB9 + AC8, 0) -> 0 | AD9: 0 | AE9: =IF(AD9 + AE8 < 0, AD9 + AE8, 0) -> 0 | AF9: 0 | AG9: =IF(AF9 + AG8 < 0, AF9 + AG8, 0) -> 0 | AH9: 0 | AI9: =IF(AH9 + AI8 < 0, AH9 + AI8, 0) -> 0 | AJ9: 0 | AK9: =IF(AJ9 + AK8 < 0, AJ9 + AK8, 0) -> 0
A10: 45302 | B10: Thursday | C10: 14 | D10: 13 | E10: 12 | F10: 1 | G10: 2 | H10: 0 | I10: =IF(H10 + I9 < 0, H10 + I9, 0) -> 0 | J10: 0 | K10: =IF(J10 + K9 < 0, J10 + K9, 0) -> 0 | L10: 0 | M10: =IF(L10 + M9 < 0, L10 + M9, 0) -> 0 | N10: 0 | O10: =IF(N10 + O9 < 0, N10 + O9, 0) -> 0 | P10: 0 | Q10: =IF(P10 + Q9 < 0, P10 + Q9, 0) -> 0 | R10: 0 | S10: =IF(R10 + S9 < 0, R10 + S9, 0) -> 0 | T10: 0 | U10: =IF(T10 + U9 < 0, T10 + U9, 0) -> 0 | V10: 0 | W10: =IF(V10 + W9 < 0, V10 + W9, 0) -> 0 | X10: 0 | Y10: =IF(X10 + Y9 < 0, X10 + Y9, 0) -> 0 | Z10: -26527.928 | AA10: =IF(Z10 + AA9 < 0, Z10 + AA9, 0) -> 0 | AB10: 33178.176 | AC10: =IF(AB10 + AC9 < 0, AB10 + AC9, 0) -> 0 | AD10: -30199.266 | AE10: =IF(AD10 + AE9 < 0, AD10 + AE9, 0) -> 0 | AF10: 0 | AG10: =IF(AF10 + AG9 < 0, AF10 + AG9, 0) -> 0 | AH10: 0 | AI10: =IF(AH10 + AI9 < 0, AH10 + AI9, 0) -> 0 | AJ10: 0 | AK10: =IF(AJ10 + AK9 < 0, AJ10 + AK9, 0) -> 0
A11: 45303 | B11: Friday | C11: 13 | D11: 12 | E11: 11 | F11: 5 | G11: 1 | H11: 0 | I11: =IF(H11 + I10 < 0, H11 + I10, 0) -> 0 | J11: 0 | K11: =IF(J11 + K10 < 0, J11 + K10, 0) -> 0 | L11: 0 | M11: =IF(L11 + M10 < 0, L11 + M10, 0) -> 0 | N11: 0 | O11: =IF(N11 + O10 < 0, N11 + O10, 0) -> 0 | P11: 0 | Q11: =IF(P11 + Q10 < 0, P11 + Q10, 0) -> 0 | R11: 0 | S11: =IF(R11 + S10 < 0, R11 + S10, 0) -> 0 | T11: 0 | U11: =IF(T11 + U10 < 0, T11 + U10, 0) -> 0 | V11: 0 | W11: =IF(V11 + W10 < 0, V11 + W10, 0) -> 0 | X11: 0 | Y11: =IF(X11 + Y10 < 0, X11 + Y10, 0) -> 0 | Z11: 0 | AA11: =IF(Z11 + AA10 < 0, Z11 + AA10, 0) -> 0 | AB11: 0 | AC11: =IF(AB11 + AC10 < 0, AB11 + AC10, 0) -> 0 | AD11: 0 | AE11: =IF(AD11 + AE10 < 0, AD11 + AE10, 0) -> 0 | AF11: 180419.87 | AG11: =IF(AF11 + AG10 < 0, AF11 + AG10, 0) -> 0 | AH11: -383256.25 | AI11: =IF(AH11 + AI10 < 0, AH11 + AI10, 0) -> 0 | AJ11: -337717.59 | AK11: =IF(AJ11 + AK10 < 0, AJ11 + AK10, 0) -> 0
A12: 45306 | B12: Monday | C12: 12 | D12: 11 | E12: 10 | F12: 4 | G12: 5 | H12: 0 | I12: =IF(H12 + I11 < 0, H12 + I11, 0) -> 0 | J12: 0 | K12: =IF(J12 + K11 < 0, J12 + K11, 0) -> 0 | L12: 0 | M12: =IF(L12 + M11 < 0, L12 + M11, 0) -> 0 | N12: 0 | O12: =IF(N12 + O11 < 0, N12 + O11, 0) -> 0 | P12: 0 | Q12: =IF(P12 + Q11 < 0, P12 + Q11, 0) -> 0 | R12: 0 | S12: =IF(R12 + S11 < 0, R12 + S11, 0) -> 0 | T12: 0 | U12: =IF(T12 + U11 < 0, T12 + U11, 0) -> 0 | V12: 0 | W12: =IF(V12 + W11 < 0, V12 + W11, 0) -> 0 | X12: 0 | Y12: =IF(X12 + Y11 < 0, X12 + Y11, 0) -> 0 | Z12: 0 | AA12: =IF(Z12 + AA11 < 0, Z12 + AA11, 0) -> 0 | AB12: 0 | AC12: =IF(AB12 + AC11 < 0, AB12 + AC11, 0) -> 0 | AD12: 0 | AE12: =IF(AD12 + AE11 < 0, AD12 + AE11, 0) -> 0 | AF12: 0 | AG12: =IF(AF12 + AG11 < 0, AF12 + AG11, 0) -> 0 | AH12: 0 | AI12: =IF(AH12 + AI11 < 0, AH12 + AI11, 0) -> 0 | AJ12: 0 | AK12: =IF(AJ12 + AK11 < 0, AJ12 + AK11, 0) -> 0
A13: 45307 | B13: Tuesday | C13: 11 | D13: 10 | E13: 9 | F13: 3 | G13: 4 | H13: 0 | I13: =IF(H13 + I12 < 0, H13 + I12, 0) -> 0 | J13: 0 | K13: =IF(J13 + K12 < 0, J13 + K12, 0) -> 0 | L13: 0 | M13: =IF(L13 + M12 < 0, L13 + M12, 0) -> 0 | N13: 0 | O13: =IF(N13 + O12 < 0, N13 + O12, 0) -> 0 | P13: 0 | Q13: =IF(P13 + Q12 < 0, P13 + Q12, 0) -> 0 | R13: 0 | S13: =IF(R13 + S12 < 0, R13 + S12, 0) -> 0 | T13: 0 | U13: =IF(T13 + U12 < 0, T13 + U12, 0) -> 0 | V13: 0 | W13: =IF(V13 + W12 < 0, V13 + W12, 0) -> 0 | X13: 0 | Y13: =IF(X13 + Y12 < 0, X13 + Y12, 0) -> 0 | Z13: 0 | AA13: =IF(Z13 + AA12 < 0, Z13 + AA12, 0) -> 0 | AB13: 0 | AC13: =IF(AB13 + AC12 < 0, AB13 + AC12, 0) -> 0 | AD13: 0 | AE13: =IF(AD13 + AE12 < 0, AD13 + AE12, 0) -> 0 | AF13: 0 | AG13: =IF(AF13 + AG12 < 0, AF13 + AG12, 0) -> 0 | AH13: 0 | AI13: =IF(AH13 + AI12 < 0, AH13 + AI12, 0) -> 0 | AJ13: 0 | AK13: =IF(AJ13 + AK12 < 0, AJ13 + AK12, 0) -> 0
A14: 45308 | B14: Wednesday | C14: 10 | D14: 9 | E14: 8 | F14: 2 | G14: 3 | H14: 0 | I14: =IF(H14 + I13 < 0, H14 + I13, 0) -> 0 | J14: 0 | K14: =IF(J14 + K13 < 0, J14 + K13, 0) -> 0 | L14: 0 | M14: =IF(L14 + M13 < 0, L14 + M13, 0) -> 0 | N14: 0 | O14: =IF(N14 + O13 < 0, N14 + O13, 0) -> 0 | P14: 0 | Q14: =IF(P14 + Q13 < 0, P14 + Q13, 0) -> 0 | R14: 0 | S14: =IF(R14 + S13 < 0, R14 + S13, 0) -> 0 | T14: 0 | U14: =IF(T14 + U13 < 0, T14 + U13, 0) -> 0 | V14: 0 | W14: =IF(V14 + W13 < 0, V14 + W13, 0) -> 0 | X14: 0 | Y14: =IF(X14 + Y13 < 0, X14 + Y13, 0) -> 0 | Z14: 0 | AA14: =IF(Z14 + AA13 < 0, Z14 + AA13, 0) -> 0 | AB14: 0 | AC14: =IF(AB14 + AC13 < 0, AB14 + AC13, 0) -> 0 | AD14: 0 | AE14: =IF(AD14 + AE13 < 0, AD14 + AE13, 0) -> 0 | AF14: 0 | AG14: =IF(AF14 + AG13 < 0, AF14 + AG13, 0) -> 0 | AH14: 0 | AI14: =IF(AH14 + AI13 < 0, AH14 + AI13, 0) -> 0 | AJ14: 0 | AK14: =IF(AJ14 + AK13 < 0, AJ14 + AK13, 0) -> 0
... A510: 46044 | B510: Thursday | C510: 3 | D510: 3 | E510: 3 | F510: 3 | G510: 1 | H510: 0 | I510: =IF(H510 + I509 < 0, H510 + I509, 0) -> 0 | J510: 0 | K510: =IF(J510 + K509 < 0, J510 + K509, 0) -> 0 | L510: 0 | M510: =IF(L510 + M509 < 0, L510 + M509, 0) -> 0 | N510: 0 | O510: =IF(N510 + O509 < 0, N510 + O509, 0) -> 0 | P510: 0 | Q510: =IF(P510 + Q509 < 0, P510 + Q509, 0) -> 0 | R510: 0 | S510: =IF(R510 + S509 < 0, R510 + S509, 0) -> 0 | T510: 0 | U510: =IF(T510 + U509 < 0, T510 + U509, 0) -> 0 | V510: 0 | W510: =IF(V510 + W509 < 0, V510 + W509, 0) -> 0 | X510: 0 | Y510: =IF(X510 + Y509 < 0, X510 + Y509, 0) -> 0 | Z510: 0 | AA510: =IF(Z510 + AA509 < 0, Z510 + AA509, 0) -> 0 | AB510: 0 | AC510: =IF(AB510 + AC509 < 0, AB510 + AC509, 0) -> 0 | AD510: 0 | AE510: =IF(AD510 + AE509 < 0, AD510 + AE509, 0) -> 0 | AF510: -1283735.5 | AG510: =IF(AF510 + AG509 < 0, AF510 + AG509, 0) -> 0 | AH510: -1008638.6 | AI510: =IF(AH510 + AI509 < 0, AH510 + AI509, 0) -> 0 | AJ510: -1145294.3 | AK510: =IF(AJ510 + AK509 < 0, AJ510 + AK509, 0) -> 0

Sheet CombinedDD
A1: Date | B1: Day | C1: BN DTE | D1: FN DTE | E1: BN SREW_RANGE | F1: FN SREW_RANGE | G1: MCN DTE | H1: MCN SREW_RANGE | I1: DD MCN SREW_RANGE | J1: NF DTE | K1: DD NF DTE | L1: NF SREW_RANGE | M1: DD NF SREW_RANGE | N1: SX DTE | O1: DD SX DTE | P1: SX SREW_RANGE | Q1: DD SX SREW_RANGE
A2: 45292 | B2: Monday | C2: 22 | D2: 21 | E2: 0 | F2: 0 | G2: 0 | H2: 0 | I2: =IF(H2 < 0, H2, 0) -> 0 | J2: 0 | K2: =IF(J2 < 0, J2, 0) -> 0 | L2: 0 | M2: =IF(L2 < 0, L2, 0) -> 0 | N2: 0 | O2: =IF(N2 < 0, N2, 0) -> 0 | P2: 0 | Q2: =IF(P2 < 0, P2, 0) -> 0
A3: 45293 | B3: Tuesday | C3: 21 | D3: 20 | E3: 0 | F3: 0 | G3: 0 | H3: 0 | I3: =IF(H3 + I2 < 0, H3 + I2, 0) -> 0 | J3: 0 | K3: =IF(J3 + K2 < 0, J3 + K2, 0) -> 0 | L3: 0 | M3: =IF(L3 + M2 < 0, L3 + M2, 0) -> 0 | N3: 0 | O3: =IF(N3 + O2 < 0, N3 + O2, 0) -> 0 | P3: 0 | Q3: =IF(P3 + Q2 < 0, P3 + Q2, 0) -> 0
A4: 45294 | B4: Wednesday | C4: 20 | D4: 19 | E4: 0 | F4: 0 | G4: 0 | H4: 0 | I4: =IF(H4 + I3 < 0, H4 + I3, 0) -> 0 | J4: 0 | K4: =IF(J4 + K3 < 0, J4 + K3, 0) -> 0 | L4: 0 | M4: =IF(L4 + M3 < 0, L4 + M3, 0) -> 0 | N4: 0 | O4: =IF(N4 + O3 < 0, N4 + O3, 0) -> 0 | P4: 0 | Q4: =IF(P4 + Q3 < 0, P4 + Q3, 0) -> 0
A5: 45295 | B5: Thursday | C5: 19 | D5: 18 | E5: 0 | F5: 0 | G5: 0 | H5: 0 | I5: =IF(H5 + I4 < 0, H5 + I4, 0) -> 0 | J5: 0 | K5: =IF(J5 + K4 < 0, J5 + K4, 0) -> 0 | L5: 1260109.9 | M5: =IF(L5 + M4 < 0, L5 + M4, 0) -> 0 | N5: 0 | O5: =IF(N5 + O4 < 0, N5 + O4, 0) -> 0 | P5: 0 | Q5: =IF(P5 + Q4 < 0, P5 + Q4, 0) -> 0
A6: 45296 | B6: Friday | C6: 18 | D6: 17 | E6: 0 | F6: 0 | G6: 0 | H6: 0 | I6: =IF(H6 + I5 < 0, H6 + I5, 0) -> 0 | J6: 0 | K6: =IF(J6 + K5 < 0, J6 + K5, 0) -> 0 | L6: 0 | M6: =IF(L6 + M5 < 0, L6 + M5, 0) -> 0 | N6: 0 | O6: =IF(N6 + O5 < 0, N6 + O5, 0) -> 0 | P6: 1481117.6 | Q6: =IF(P6 + Q5 < 0, P6 + Q5, 0) -> 0
A7: 45299 | B7: Monday | C7: 17 | D7: 16 | E7: 0 | F7: 0 | G7: 0 | H7: 0 | I7: =IF(H7 + I6 < 0, H7 + I6, 0) -> 0 | J7: 0 | K7: =IF(J7 + K6 < 0, J7 + K6, 0) -> 0 | L7: 0 | M7: =IF(L7 + M6 < 0, L7 + M6, 0) -> 0 | N7: 0 | O7: =IF(N7 + O6 < 0, N7 + O6, 0) -> 0 | P7: 0 | Q7: =IF(P7 + Q6 < 0, P7 + Q6, 0) -> 0
A8: 45300 | B8: Tuesday | C8: 16 | D8: 15 | E8: 0 | F8: 0 | G8: 0 | H8: 0 | I8: =IF(H8 + I7 < 0, H8 + I7, 0) -> 0 | J8: 0 | K8: =IF(J8 + K7 < 0, J8 + K7, 0) -> 0 | L8: 0 | M8: =IF(L8 + M7 < 0, L8 + M7, 0) -> 0 | N8: 0 | O8: =IF(N8 + O7 < 0, N8 + O7, 0) -> 0 | P8: 0 | Q8: =IF(P8 + Q7 < 0, P8 + Q7, 0) -> 0
A9: 45301 | B9: Wednesday | C9: 15 | D9: 14 | E9: 0 | F9: 0 | G9: 0 | H9: 0 | I9: =IF(H9 + I8 < 0, H9 + I8, 0) -> 0 | J9: 0 | K9: =IF(J9 + K8 < 0, J9 + K8, 0) -> 0 | L9: 0 | M9: =IF(L9 + M8 < 0, L9 + M8, 0) -> 0 | N9: 0 | O9: =IF(N9 + O8 < 0, N9 + O8, 0) -> 0 | P9: 0 | Q9: =IF(P9 + Q8 < 0, P9 + Q8, 0) -> 0
A10: 45302 | B10: Thursday | C10: 14 | D10: 13 | E10: 0 | F10: 0 | G10: 0 | H10: 0 | I10: =IF(H10 + I9 < 0, H10 + I9, 0) -> 0 | J10: 0 | K10: =IF(J10 + K9 < 0, J10 + K9, 0) -> 0 | L10: -23549.018 | M10: =IF(L10 + M9 < 0, L10 + M9, 0) -> 0 | N10: 0 | O10: =IF(N10 + O9 < 0, N10 + O9, 0) -> 0 | P10: 0 | Q10: =IF(P10 + Q9 < 0, P10 + Q9, 0) -> 0
A11: 45303 | B11: Friday | C11: 13 | D11: 12 | E11: 0 | F11: 0 | G11: 0 | H11: 0 | I11: =IF(H11 + I10 < 0, H11 + I10, 0) -> 0 | J11: 0 | K11: =IF(J11 + K10 < 0, J11 + K10, 0) -> 0 | L11: 0 | M11: =IF(L11 + M10 < 0, L11 + M10, 0) -> 0 | N11: 0 | O11: =IF(N11 + O10 < 0, N11 + O10, 0) -> 0 | P11: -540553.97 | Q11: =IF(P11 + Q10 < 0, P11 + Q10, 0) -> 0
A12: 45306 | B12: Monday | C12: 12 | D12: 11 | E12: 0 | F12: 0 | G12: 0 | H12: 0 | I12: =IF(H12 + I11 < 0, H12 + I11, 0) -> 0 | J12: 0 | K12: =IF(J12 + K11 < 0, J12 + K11, 0) -> 0 | L12: 0 | M12: =IF(L12 + M11 < 0, L12 + M11, 0) -> 0 | N12: 0 | O12: =IF(N12 + O11 < 0, N12 + O11, 0) -> 0 | P12: 0 | Q12: =IF(P12 + Q11 < 0, P12 + Q11, 0) -> 0
A13: 45307 | B13: Tuesday | C13: 11 | D13: 10 | E13: 0 | F13: 0 | G13: 0 | H13: 0 | I13: =IF(H13 + I12 < 0, H13 + I12, 0) -> 0 | J13: 0 | K13: =IF(J13 + K12 < 0, J13 + K12, 0) -> 0 | L13: 0 | M13: =IF(L13 + M12 < 0, L13 + M12, 0) -> 0 | N13: 0 | O13: =IF(N13 + O12 < 0, N13 + O12, 0) -> 0 | P13: 0 | Q13: =IF(P13 + Q12 < 0, P13 + Q12, 0) -> 0
A14: 45308 | B14: Wednesday | C14: 10 | D14: 9 | E14: 0 | F14: 0 | G14: 0 | H14: 0 | I14: =IF(H14 + I13 < 0, H14 + I13, 0) -> 0 | J14: 0 | K14: =IF(J14 + K13 < 0, J14 + K13, 0) -> 0 | L14: 0 | M14: =IF(L14 + M13 < 0, L14 + M13, 0) -> 0 | N14: 0 | O14: =IF(N14 + O13 < 0, N14 + O13, 0) -> 0 | P14: 0 | Q14: =IF(P14 + Q13 < 0, P14 + Q13, 0) -> 0
... A510: 46044 | B510: Thursday | C510: 3 | D510: 3 | E510: 0 | F510: 0 | G510: 0 | H510: 0 | I510: =IF(H510 + I509 < 0, H510 + I509, 0) -> 0 | J510: 0 | K510: =IF(J510 + K509 < 0, J510 + K509, 0) -> 0 | L510: 0 | M510: =IF(L510 + M509 < 0, L510 + M509, 0) -> 0 | N510: 0 | O510: =IF(N510 + O509 < 0, N510 + O509, 0) -> 0 | P510: -3437668.4 | Q510: =IF(P510 + Q509 < 0, P510 + Q509, 0) -> 0

Sheet MTM
A1: Date | B1: Day | C1: BANKNIFTY | D1: FINNIFTY | E1: MIDCPNIFTY | F1: NIFTY | G1: SENSEX | H1: Total | I1: BANKNIFTY-DD | J1: FINNIFTY-DD | K1: MIDCPNIFTY-DD | L1: NIFTY-DD | M1: SENSEX-DD | N1: Total-DD | O1: DD-Days | P1: BANKNIFTY-Hedge | Q1: FINNIFTY-Hedge | R1: MIDCPNIFTY-Hedge | S1: NIFTY-Hedge | T1: SENSEX-Hedge | U1: Total-Hedge | V1: BANKNIFTY-Hedge-DD | W1: FINNIFTY-Hedge-DD | X1: MIDCPNIFTY-Hedge-DD | Y1: NIFTY-Hedge-DD | Z1: SENSEX-Hedge-DD | AA1: Total-Hedge-DD | AB1: Hedge-DD-Days | AC1: Loss-Days | AD1: Loss-Amount | AE1: Profit-Days | AF1: Profit-Amount | AG1: Loss-Greater-1% | AH1: Profit-Greater-1% | AI1: Hedge-Loss-Days | AJ1: Hedge-Loss-Amount | AK1: Hedge-Profit-Days | AL1: Hedge-Profit-Amount | AM1: Hedge-Loss-Greater-1% | AN1: Hedge-Profit-Greater-1%
A2: 45292 | B2: Monday | C2: =SUM(PL!H2:J2) -> 0 | D2: =SUM(PL!K2:M2) -> 0 | E2: =SUM(PL!N2:P2) -> 0 | F2: =SUM(PL!Q2:S2) -> 0 | G2: =SUM(PL!T2:V2) -> 0 | H2: =SUM(C2:G2) -> 0 | I2: =IF(C2 < 0, C2, 0) -> 0 | J2: =IF(D2 < 0, D2, 0) -> 0 | K2: =IF(E2 < 0, E2, 0) -> 0 | L2: =IF(F2 < 0, F2, 0) -> 0 | M2: =IF(G2 < 0, G2, 0) -> 0 | N2: =IF(H2 < 0, H2, 0) -> 0 | O2: =IF(N2 < 0, 1, 0) -> 0 | P2: =C2-((ABS(SUM(PL!H2:J2)))*0.125) -> 0 | Q2: =D2-((ABS(SUM(PL!K2:M2)))*0.125) -> 0 | R2: =E2-((ABS(SUM(PL!N2:P2)))*0.125) -> 0 | S2: =F2-((ABS(SUM(PL!Q2:S2)))*0.125) -> 0 | T2: =G2-((ABS(SUM(PL!T2:V2)))*0.125) -> 0 | U2: =P2 + Q2 + R2 + S2 + T2 -> 0 | V2: =IF(P2 < 0, P2, 0) -> 0 | W2: =IF(Q2 < 0, Q2, 0) -> 0 | X2: =IF(R2 < 0, R2, 0) -> 0 | Y2: =IF(S2 < 0, S2, 0) -> 0 | Z2: =IF(T2 < 0, T2, 0) -> 0 | AA2: =IF(U2 < 0, U2, 0) -> 0 | AB2: =IF(AA2 < 0, 1, 0) -> 0 | AC2: =IF(H2<0,1,0) -> 0 | AD2: =IF(AC2=1,H2,0) -> 0 | AE2: =IF(H2>0,1,0) -> 0 | AF2: =IF(AE2=1,H2,0) -> 0 | AG2: =IF(AD2<-20000000.0/100,1,0) -> 0 | AH2: =IF(AF2>20000000.0/100,1,0) -> 0 | AI2: =IF(U2<0,1,0) -> 0 | AJ2: =IF(AI2=1,U2,0) -> 0 | AK2: =IF(U2>0,1,0) -> 0 | AL2: =IF(AK2=1,U2,0) -> 0 | AM2: =IF(AJ2<-20000000.0/100,1,0) -> 0 | AN2: =IF(AL2>20000000.0/100,1,0) -> 0
A3: 45293 | B3: Tuesday | C3: =SUM(PL!H3:J3) -> 0 | D3: =SUM(PL!K3:M3) -> 0 | E3: =SUM(PL!N3:P3) -> 0 | F3: =SUM(PL!Q3:S3) -> 0 | G3: =SUM(PL!T3:V3) -> 0 | H3: =SUM(C3:G3) -> 0 | I3: =IF(C3 + I2 < 0, C3 + I2, 0) -> 0 | J3: =IF(D3 + J2 < 0, D3 + J2, 0) -> 0 | K3: =IF(E3 + K2 < 0, E3 + K2, 0) -> 0 | L3: =IF(F3 + L2 < 0, F3 + L2, 0) -> 0 | M3: =IF(G3 + M2 < 0, G3 + M2, 0) -> 0 | N3: =IF(H3 + N2 < 0, H3 + N2, 0) -> 0 | O3: =IF(N3 < 0, 1 + O2, 0) -> 0 | P3: =C3-((ABS(SUM(PL!H3:J3)))*0.125) -> 0 | Q3: =D3-((ABS(SUM(PL!K3:M3)))*0.125) -> 0 | R3: =E3-((ABS(SUM(PL!N3:P3)))*0.125) -> 0 | S3: =F3-((ABS(SUM(PL!Q3:S3)))*0.125) -> 0 | T3: =G3-((ABS(SUM(PL!T3:V3)))*0.125) -> 0 | U3: =P3 + Q3 + R3 + S3 + T3 -> 0 | V3: =IF(P3 + V2 < 0, P3 + V2, 0) -> 0 | W3: =IF(Q3 + W2 < 0, Q3 + W2, 0) -> 0 | X3: =IF(R3 + X2 < 0, R3 + X2, 0) -> 0 | Y3: =IF(S3 + Y2 < 0, S3 + Y2, 0) -> 0 | Z3: =IF(T3 + Z2 < 0, T3 + Z2, 0) -> 0 | AA3: =IF(U3 + AA2 < 0, U3 + AA2, 0) -> 0 | AB3: =IF(AA3 < 0, 1 + AB2, 0) -> 0 | AC3: =IF(H3<0,1,0) -> 0 | AD3: =IF(AC3=1,H3,0) -> 0 | AE3: =IF(H3>0,1,0) -> 0 | AF3: =IF(AE3=1,H3,0) -> 0 | AG3: =IF(AD3<-20000000.0/100,1,0) -> 0 | AH3: =IF(AF3>20000000.0/100,1,0) -> 0 | AI3: =IF(U3<0,1,0) -> 0 | AJ3: =IF(AI3=1,U3,0) -> 0 | AK3: =IF(U3>0,1,0) -> 0 | AL3: =IF(AK3=1,U3,0) -> 0 | AM3: =IF(AJ3<-20000000.0/100,1,0) -> 0 | AN3: =IF(AL3>20000000.0/100,1,0) -> 0
A4: 45294 | B4: Wednesday | C4: =SUM(PL!H4:J4) -> 0 | D4: =SUM(PL!K4:M4) -> 0 | E4: =SUM(PL!N4:P4) -> 0 | F4: =SUM(PL!Q4:S4) -> 0 | G4: =SUM(PL!T4:V4) -> 0 | H4: =SUM(C4:G4) -> 0 | I4: =IF(C4 + I3 < 0, C4 + I3, 0) -> 0 | J4: =IF(D4 + J3 < 0, D4 + J3, 0) -> 0 | K4: =IF(E4 + K3 < 0, E4 + K3, 0) -> 0 | L4: =IF(F4 + L3 < 0, F4 + L3, 0) -> 0 | M4: =IF(G4 + M3 < 0, G4 + M3, 0) -> 0 | N4: =IF(H4 + N3 < 0, H4 + N3, 0) -> 0 | O4: =IF(N4 < 0, 1 + O3, 0) -> 0 | P4: =C4-((ABS(SUM(PL!H4:J4)))*0.125) -> 0 | Q4: =D4-((ABS(SUM(PL!K4:M4)))*0.125) -> 0 | R4: =E4-((ABS(SUM(PL!N4:P4)))*0.125) -> 0 | S4: =F4-((ABS(SUM(PL!Q4:S4)))*0.125) -> 0 | T4: =G4-((ABS(SUM(PL!T4:V4)))*0.125) -> 0 | U4: =P4 + Q4 + R4 + S4 + T4 -> 0 | V4: =IF(P4 + V3 < 0, P4 + V3, 0) -> 0 | W4: =IF(Q4 + W3 < 0, Q4 + W3, 0) -> 0 | X4: =IF(R4 + X3 < 0, R4 + X3, 0) -> 0 | Y4: =IF(S4 + Y3 < 0, S4 + Y3, 0) -> 0 | Z4: =IF(T4 + Z3 < 0, T4 + Z3, 0) -> 0 | AA4: =IF(U4 + AA3 < 0, U4 + AA3, 0) -> 0 | AB4: =IF(AA4 < 0, 1 + AB3, 0) -> 0 | AC4: =IF(H4<0,1,0) -> 0 | AD4: =IF(AC4=1,H4,0) -> 0 | AE4: =IF(H4>0,1,0) -> 0 | AF4: =IF(AE4=1,H4,0) -> 0 | AG4: =IF(AD4<-20000000.0/100,1,0) -> 0 | AH4: =IF(AF4>20000000.0/100,1,0) -> 0 | AI4: =IF(U4<0,1,0) -> 0 | AJ4: =IF(AI4=1,U4,0) -> 0 | AK4: =IF(U4>0,1,0) -> 0 | AL4: =IF(AK4=1,U4,0) -> 0 | AM4: =IF(AJ4<-20000000.0/100,1,0) -> 0 | AN4: =IF(AL4>20000000.0/100,1,0) -> 0
A5: 45295 | B5: Thursday | C5: =SUM(PL!H5:J5) -> 0 | D5: =SUM(PL!K5:M5) -> 0 | E5: =SUM(PL!N5:P5) -> 0 | F5: =SUM(PL!Q5:S5) -> 0 | G5: =SUM(PL!T5:V5) -> 0 | H5: =SUM(C5:G5) -> 0 | I5: =IF(C5 + I4 < 0, C5 + I4, 0) -> 0 | J5: =IF(D5 + J4 < 0, D5 + J4, 0) -> 0 | K5: =IF(E5 + K4 < 0, E5 + K4, 0) -> 0 | L5: =IF(F5 + L4 < 0, F5 + L4, 0) -> 0 | M5: =IF(G5 + M4 < 0, G5 + M4, 0) -> 0 | N5: =IF(H5 + N4 < 0, H5 + N4, 0) -> 0 | O5: =IF(N5 < 0, 1 + O4, 0) -> 0 | P5: =C5-((ABS(SUM(PL!H5:J5)))*0.125) -> 0 | Q5: =D5-((ABS(SUM(PL!K5:M5)))*0.125) -> 0 | R5: =E5-((ABS(SUM(PL!N5:P5)))*0.125) -> 0 | S5: =F5-((ABS(SUM(PL!Q5:S5)))*0.125) -> 0 | T5: =G5-((ABS(SUM(PL!T5:V5)))*0.125) -> 0 | U5: =P5 + Q5 + R5 + S5 + T5 -> 0 | V5: =IF(P5 + V4 < 0, P5 + V4, 0) -> 0 | W5: =IF(Q5 + W4 < 0, Q5 + W4, 0) -> 0 | X5: =IF(R5 + X4 < 0, R5 + X4, 0) -> 0 | Y5: =IF(S5 + Y4 < 0, S5 + Y4, 0) -> 0 | Z5: =IF(T5 + Z4 < 0, T5 + Z4, 0) -> 0 | AA5: =IF(U5 + AA4 < 0, U5 + AA4, 0) -> 0 | AB5: =IF(AA5 < 0, 1 + AB4, 0) -> 0 | AC5: =IF(H5<0,1,0) -> 0 | AD5: =IF(AC5=1,H5,0) -> 0 | AE5: =IF(H5>0,1,0) -> 0 | AF5: =IF(AE5=1,H5,0) -> 0 | AG5: =IF(AD5<-20000000.0/100,1,0) -> 0 | AH5: =IF(AF5>20000000.0/100,1,0) -> 0 | AI5: =IF(U5<0,1,0) -> 0 | AJ5: =IF(AI5=1,U5,0) -> 0 | AK5: =IF(U5>0,1,0) -> 0 | AL5: =IF(AK5=1,U5,0) -> 0 | AM5: =IF(AJ5<-20000000.0/100,1,0) -> 0 | AN5: =IF(AL5>20000000.0/100,1,0) -> 0
A6: 45296 | B6: Friday | C6: =SUM(PL!H6:J6) -> 0 | D6: =SUM(PL!K6:M6) -> 0 | E6: =SUM(PL!N6:P6) -> 0 | F6: =SUM(PL!Q6:S6) -> 0 | G6: =SUM(PL!T6:V6) -> 0 | H6: =SUM(C6:G6) -> 0 | I6: =IF(C6 + I5 < 0, C6 + I5, 0) -> 0 | J6: =IF(D6 + J5 < 0, D6 + J5, 0) -> 0 | K6: =IF(E6 + K5 < 0, E6 + K5, 0) -> 0 | L6: =IF(F6 + L5 < 0, F6 + L5, 0) -> 0 | M6: =IF(G6 + M5 < 0, G6 + M5, 0) -> 0 | N6: =IF(H6 + N5 < 0, H6 + N5, 0) -> 0 | O6: =IF(N6 < 0, 1 + O5, 0) -> 0 | P6: =C6-((ABS(SUM(PL!H6:J6)))*0.125) -> 0 | Q6: =D6-((ABS(SUM(PL!K6:M6)))*0.125) -> 0 | R6: =E6-((ABS(SUM(PL!N6:P6)))*0.125) -> 0 | S6: =F6-((ABS(SUM(PL!Q6:S6)))*0.125) -> 0 | T6: =G6-((ABS(SUM(PL!T6:V6)))*0.125) -> 0 | U6: =P6 + Q6 + R6 + S6 + T6 -> 0 | V6: =IF(P6 + V5 < 0, P6 + V5, 0) -> 0 | W6: =IF(Q6 + W5 < 0, Q6 + W5, 0) -> 0 | X6: =IF(R6 + X5 < 0, R6 + X5, 0) -> 0 | Y6: =IF(S6 + Y5 < 0, S6 + Y5, 0) -> 0 | Z6: =IF(T6 + Z5 < 0, T6 + Z5, 0) -> 0 | AA6: =IF(U6 + AA5 < 0, U6 + AA5, 0) -> 0 | AB6: =IF(AA6 < 0, 1 + AB5, 0) -> 0 | AC6: =IF(H6<0,1,0) -> 0 | AD6: =IF(AC6=1,H6,0) -> 0 | AE6: =IF(H6>0,1,0) -> 0 | AF6: =IF(AE6=1,H6,0) -> 0 | AG6: =IF(AD6<-20000000.0/100,1,0) -> 0 | AH6: =IF(AF6>20000000.0/100,1,0) -> 0 | AI6: =IF(U6<0,1,0) -> 0 | AJ6: =IF(AI6=1,U6,0) -> 0 | AK6: =IF(U6>0,1,0) -> 0 | AL6: =IF(AK6=1,U6,0) -> 0 | AM6: =IF(AJ6<-20000000.0/100,1,0) -> 0 | AN6: =IF(AL6>20000000.0/100,1,0) -> 0
A7: 45299 | B7: Monday | C7: =SUM(PL!H7:J7) -> 0 | D7: =SUM(PL!K7:M7) -> 0 | E7: =SUM(PL!N7:P7) -> 0 | F7: =SUM(PL!Q7:S7) -> 0 | G7: =SUM(PL!T7:V7) -> 0 | H7: =SUM(C7:G7) -> 0 | I7: =IF(C7 + I6 < 0, C7 + I6, 0) -> 0 | J7: =IF(D7 + J6 < 0, D7 + J6, 0) -> 0 | K7: =IF(E7 + K6 < 0, E7 + K6, 0) -> 0 | L7: =IF(F7 + L6 < 0, F7 + L6, 0) -> 0 | M7: =IF(G7 + M6 < 0, G7 + M6, 0) -> 0 | N7: =IF(H7 + N6 < 0, H7 + N6, 0) -> 0 | O7: =IF(N7 < 0, 1 + O6, 0) -> 0 | P7: =C7-((ABS(SUM(PL!H7:J7)))*0.125) -> 0 | Q7: =D7-((ABS(SUM(PL!K7:M7)))*0.125) -> 0 | R7: =E7-((ABS(SUM(PL!N7:P7)))*0.125) -> 0 | S7: =F7-((ABS(SUM(PL!Q7:S7)))*0.125) -> 0 | T7: =G7-((ABS(SUM(PL!T7:V7)))*0.125) -> 0 | U7: =P7 + Q7 + R7 + S7 + T7 -> 0 | V7: =IF(P7 + V6 < 0, P7 + V6, 0) -> 0 | W7: =IF(Q7 + W6 < 0, Q7 + W6, 0) -> 0 | X7: =IF(R7 + X6 < 0, R7 + X6, 0) -> 0 | Y7: =IF(S7 + Y6 < 0, S7 + Y6, 0) -> 0 | Z7: =IF(T7 + Z6 < 0, T7 + Z6, 0) -> 0 | AA7: =IF(U7 + AA6 < 0, U7 + AA6, 0) -> 0 | AB7: =IF(AA7 < 0, 1 + AB6, 0) -> 0 | AC7: =IF(H7<0,1,0) -> 0 | AD7: =IF(AC7=1,H7,0) -> 0 | AE7: =IF(H7>0,1,0) -> 0 | AF7: =IF(AE7=1,H7,0) -> 0 | AG7: =IF(AD7<-20000000.0/100,1,0) -> 0 | AH7: =IF(AF7>20000000.0/100,1,0) -> 0 | AI7: =IF(U7<0,1,0) -> 0 | AJ7: =IF(AI7=1,U7,0) -> 0 | AK7: =IF(U7>0,1,0) -> 0 | AL7: =IF(AK7=1,U7,0) -> 0 | AM7: =IF(AJ7<-20000000.0/100,1,0) -> 0 | AN7: =IF(AL7>20000000.0/100,1,0) -> 0
A8: 45300 | B8: Tuesday | C8: =SUM(PL!H8:J8) -> 0 | D8: =SUM(PL!K8:M8) -> 0 | E8: =SUM(PL!N8:P8) -> 0 | F8: =SUM(PL!Q8:S8) -> 0 | G8: =SUM(PL!T8:V8) -> 0 | H8: =SUM(C8:G8) -> 0 | I8: =IF(C8 + I7 < 0, C8 + I7, 0) -> 0 | J8: =IF(D8 + J7 < 0, D8 + J7, 0) -> 0 | K8: =IF(E8 + K7 < 0, E8 + K7, 0) -> 0 | L8: =IF(F8 + L7 < 0, F8 + L7, 0) -> 0 | M8: =IF(G8 + M7 < 0, G8 + M7, 0) -> 0 | N8: =IF(H8 + N7 < 0, H8 + N7, 0) -> 0 | O8: =IF(N8 < 0, 1 + O7, 0) -> 0 | P8: =C8-((ABS(SUM(PL!H8:J8)))*0.125) -> 0 | Q8: =D8-((ABS(SUM(PL!K8:M8)))*0.125) -> 0 | R8: =E8-((ABS(SUM(PL!N8:P8)))*0.125) -> 0 | S8: =F8-((ABS(SUM(PL!Q8:S8)))*0.125) -> 0 | T8: =G8-((ABS(SUM(PL!T8:V8)))*0.125) -> 0 | U8: =P8 + Q8 + R8 + S8 + T8 -> 0 | V8: =IF(P8 + V7 < 0, P8 + V7, 0) -> 0 | W8: =IF(Q8 + W7 < 0, Q8 + W7, 0) -> 0 | X8: =IF(R8 + X7 < 0, R8 + X7, 0) -> 0 | Y8: =IF(S8 + Y7 < 0, S8 + Y7, 0) -> 0 | Z8: =IF(T8 + Z7 < 0, T8 + Z7, 0) -> 0 | AA8: =IF(U8 + AA7 < 0, U8 + AA7, 0) -> 0 | AB8: =IF(AA8 < 0, 1 + AB7, 0) -> 0 | AC8: =IF(H8<0,1,0) -> 0 | AD8: =IF(AC8=1,H8,0) -> 0 | AE8: =IF(H8>0,1,0) -> 0 | AF8: =IF(AE8=1,H8,0) -> 0 | AG8: =IF(AD8<-20000000.0/100,1,0) -> 0 | AH8: =IF(AF8>20000000.0/100,1,0) -> 0 | AI8: =IF(U8<0,1,0) -> 0 | AJ8: =IF(AI8=1,U8,0) -> 0 | AK8: =IF(U8>0,1,0) -> 0 | AL8: =IF(AK8=1,U8,0) -> 0 | AM8: =IF(AJ8<-20000000.0/100,1,0) -> 0 | AN8: =IF(AL8>20000000.0/100,1,0) -> 0
A9: 45301 | B9: Wednesday | C9: =SUM(PL!H9:J9) -> 0 | D9: =SUM(PL!K9:M9) -> 0 | E9: =SUM(PL!N9:P9) -> 0 | F9: =SUM(PL!Q9:S9) -> 0 | G9: =SUM(PL!T9:V9) -> 0 | H9: =SUM(C9:G9) -> 0 | I9: =IF(C9 + I8 < 0, C9 + I8, 0) -> 0 | J9: =IF(D9 + J8 < 0, D9 + J8, 0) -> 0 | K9: =IF(E9 + K8 < 0, E9 + K8, 0) -> 0 | L9: =IF(F9 + L8 < 0, F9 + L8, 0) -> 0 | M9: =IF(G9 + M8 < 0, G9 + M8, 0) -> 0 | N9: =IF(H9 + N8 < 0, H9 + N8, 0) -> 0 | O9: =IF(N9 < 0, 1 + O8, 0) -> 0 | P9: =C9-((ABS(SUM(PL!H9:J9)))*0.125) -> 0 | Q9: =D9-((ABS(SUM(PL!K9:M9)))*0.125) -> 0 | R9: =E9-((ABS(SUM(PL!N9:P9)))*0.125) -> 0 | S9: =F9-((ABS(SUM(PL!Q9:S9)))*0.125) -> 0 | T9: =G9-((ABS(SUM(PL!T9:V9)))*0.125) -> 0 | U9: =P9 + Q9 + R9 + S9 + T9 -> 0 | V9: =IF(P9 + V8 < 0, P9 + V8, 0) -> 0 | W9: =IF(Q9 + W8 < 0, Q9 + W8, 0) -> 0 | X9: =IF(R9 + X8 < 0, R9 + X8, 0) -> 0 | Y9: =IF(S9 + Y8 < 0, S9 + Y8, 0) -> 0 | Z9: =IF(T9 + Z8 < 0, T9 + Z8, 0) -> 0 | AA9: =IF(U9 + AA8 < 0, U9 + AA8, 0) -> 0 | AB9: =IF(AA9 < 0, 1 + AB8, 0) -> 0 | AC9: =IF(H9<0,1,0) -> 0 | AD9: =IF(AC9=1,H9,0) -> 0 | AE9: =IF(H9>0,1,0) -> 0 | AF9: =IF(AE9=1,H9,0) -> 0 | AG9: =IF(AD9<-20000000.0/100,1,0) -> 0 | AH9: =IF(AF9>20000000.0/100,1,0) -> 0 | AI9: =IF(U9<0,1,0) -> 0 | AJ9: =IF(AI9=1,U9,0) -> 0 | AK9: =IF(U9>0,1,0) -> 0 | AL9: =IF(AK9=1,U9,0) -> 0 | AM9: =IF(AJ9<-20000000.0/100,1,0) -> 0 | AN9: =IF(AL9>20000000.0/100,1,0) -> 0
A10: 45302 | B10: Thursday | C10: =SUM(PL!H10:J10) -> 0 | D10: =SUM(PL!K10:M10) -> 0 | E10: =SUM(PL!N10:P10) -> 0 | F10: =SUM(PL!Q10:S10) -> 0 | G10: =SUM(PL!T10:V10) -> 0 | H10: =SUM(C10:G10) -> 0 | I10: =IF(C10 + I9 < 0, C10 + I9, 0) -> 0 | J10: =IF(D10 + J9 < 0, D10 + J9, 0) -> 0 | K10: =IF(E10 + K9 < 0, E10 + K9, 0) -> 0 | L10: =IF(F10 + L9 < 0, F10 + L9, 0) -> 0 | M10: =IF(G10 + M9 < 0, G10 + M9, 0) -> 0 | N10: =IF(H10 + N9 < 0, H10 + N9, 0) -> 0 | O10: =IF(N10 < 0, 1 + O9, 0) -> 0 | P10: =C10-((ABS(SUM(PL!H10:J10)))*0.125) -> 0 | Q10: =D10-((ABS(SUM(PL!K10:M10)))*0.125) -> 0 | R10: =E10-((ABS(SUM(PL!N10:P10)))*0.125) -> 0 | S10: =F10-((ABS(SUM(PL!Q10:S10)))*0.125) -> 0 | T10: =G10-((ABS(SUM(PL!T10:V10)))*0.125) -> 0 | U10: =P10 + Q10 + R10 + S10 + T10 -> 0 | V10: =IF(P10 + V9 < 0, P10 + V9, 0) -> 0 | W10: =IF(Q10 + W9 < 0, Q10 + W9, 0) -> 0 | X10: =IF(R10 + X9 < 0, R10 + X9, 0) -> 0 | Y10: =IF(S10 + Y9 < 0, S10 + Y9, 0) -> 0 | Z10: =IF(T10 + Z9 < 0, T10 + Z9, 0) -> 0 | AA10: =IF(U10 + AA9 < 0, U10 + AA9, 0) -> 0 | AB10: =IF(AA10 < 0, 1 + AB9, 0) -> 0 | AC10: =IF(H10<0,1,0) -> 0 | AD10: =IF(AC10=1,H10,0) -> 0 | AE10: =IF(H10>0,1,0) -> 0 | AF10: =IF(AE10=1,H10,0) -> 0 | AG10: =IF(AD10<-20000000.0/100,1,0) -> 0 | AH10: =IF(AF10>20000000.0/100,1,0) -> 0 | AI10: =IF(U10<0,1,0) -> 0 | AJ10: =IF(AI10=1,U10,0) -> 0 | AK10: =IF(U10>0,1,0) -> 0 | AL10: =IF(AK10=1,U10,0) -> 0 | AM10: =IF(AJ10<-20000000.0/100,1,0) -> 0 | AN10: =IF(AL10>20000000.0/100,1,0) -> 0
A11: 45303 | B11: Friday | C11: =SUM(PL!H11:J11) -> 0 | D11: =SUM(PL!K11:M11) -> 0 | E11: =SUM(PL!N11:P11) -> 0 | F11: =SUM(PL!Q11:S11) -> 0 | G11: =SUM(PL!T11:V11) -> 0 | H11: =SUM(C11:G11) -> 0 | I11: =IF(C11 + I10 < 0, C11 + I10, 0) -> 0 | J11: =IF(D11 + J10 < 0, D11 + J10, 0) -> 0 | K11: =IF(E11 + K10 < 0, E11 + K10, 0) -> 0 | L11: =IF(F11 + L10 < 0, F11 + L10, 0) -> 0 | M11: =IF(G11 + M10 < 0, G11 + M10, 0) -> 0 | N11: =IF(H11 + N10 < 0, H11 + N10, 0) -> 0 | O11: =IF(N11 < 0, 1 + O10, 0) -> 0 | P11: =C11-((ABS(SUM(PL!H11:J11)))*0.125) -> 0 | Q11: =D11-((ABS(SUM(PL!K11:M11)))*0.125) -> 0 | R11: =E11-((ABS(SUM(PL!N11:P11)))*0.125) -> 0 | S11: =F11-((ABS(SUM(PL!Q11:S11)))*0.125) -> 0 | T11: =G11-((ABS(SUM(PL!T11:V11)))*0.125) -> 0 | U11: =P11 + Q11 + R11 + S11 + T11 -> 0 | V11: =IF(P11 + V10 < 0, P11 + V10, 0) -> 0 | W11: =IF(Q11 + W10 < 0, Q11 + W10, 0) -> 0 | X11: =IF(R11 + X10 < 0, R11 + X10, 0) -> 0 | Y11: =IF(S11 + Y10 < 0, S11 + Y10, 0) -> 0 | Z11: =IF(T11 + Z10 < 0, T11 + Z10, 0) -> 0 | AA11: =IF(U11 + AA10 < 0, U11 + AA10, 0) -> 0 | AB11: =IF(AA11 < 0, 1 + AB10, 0) -> 0 | AC11: =IF(H11<0,1,0) -> 0 | AD11: =IF(AC11=1,H11,0) -> 0 | AE11: =IF(H11>0,1,0) -> 0 | AF11: =IF(AE11=1,H11,0) -> 0 | AG11: =IF(AD11<-20000000.0/100,1,0) -> 0 | AH11: =IF(AF11>20000000.0/100,1,0) -> 0 | AI11: =IF(U11<0,1,0) -> 0 | AJ11: =IF(AI11=1,U11,0) -> 0 | AK11: =IF(U11>0,1,0) -> 0 | AL11: =IF(AK11=1,U11,0) -> 0 | AM11: =IF(AJ11<-20000000.0/100,1,0) -> 0 | AN11: =IF(AL11>20000000.0/100,1,0) -> 0
A12: 45306 | B12: Monday | C12: =SUM(PL!H12:J12) -> 0 | D12: =SUM(PL!K12:M12) -> 0 | E12: =SUM(PL!N12:P12) -> 0 | F12: =SUM(PL!Q12:S12) -> 0 | G12: =SUM(PL!T12:V12) -> 0 | H12: =SUM(C12:G12) -> 0 | I12: =IF(C12 + I11 < 0, C12 + I11, 0) -> 0 | J12: =IF(D12 + J11 < 0, D12 + J11, 0) -> 0 | K12: =IF(E12 + K11 < 0, E12 + K11, 0) -> 0 | L12: =IF(F12 + L11 < 0, F12 + L11, 0) -> 0 | M12: =IF(G12 + M11 < 0, G12 + M11, 0) -> 0 | N12: =IF(H12 + N11 < 0, H12 + N11, 0) -> 0 | O12: =IF(N12 < 0, 1 + O11, 0) -> 0 | P12: =C12-((ABS(SUM(PL!H12:J12)))*0.125) -> 0 | Q12: =D12-((ABS(SUM(PL!K12:M12)))*0.125) -> 0 | R12: =E12-((ABS(SUM(PL!N12:P12)))*0.125) -> 0 | S12: =F12-((ABS(SUM(PL!Q12:S12)))*0.125) -> 0 | T12: =G12-((ABS(SUM(PL!T12:V12)))*0.125) -> 0 | U12: =P12 + Q12 + R12 + S12 + T12 -> 0 | V12: =IF(P12 + V11 < 0, P12 + V11, 0) -> 0 | W12: =IF(Q12 + W11 < 0, Q12 + W11, 0) -> 0 | X12: =IF(R12 + X11 < 0, R12 + X11, 0) -> 0 | Y12: =IF(S12 + Y11 < 0, S12 + Y11, 0) -> 0 | Z12: =IF(T12 + Z11 < 0, T12 + Z11, 0) -> 0 | AA12: =IF(U12 + AA11 < 0, U12 + AA11, 0) -> 0 | AB12: =IF(AA12 < 0, 1 + AB11, 0) -> 0 | AC12: =IF(H12<0,1,0) -> 0 | AD12: =IF(AC12=1,H12,0) -> 0 | AE12: =IF(H12>0,1,0) -> 0 | AF12: =IF(AE12=1,H12,0) -> 0 | AG12: =IF(AD12<-20000000.0/100,1,0) -> 0 | AH12: =IF(AF12>20000000.0/100,1,0) -> 0 | AI12: =IF(U12<0,1,0) -> 0 | AJ12: =IF(AI12=1,U12,0) -> 0 | AK12: =IF(U12>0,1,0) -> 0 | AL12: =IF(AK12=1,U12,0) -> 0 | AM12: =IF(AJ12<-20000000.0/100,1,0) -> 0 | AN12: =IF(AL12>20000000.0/100,1,0) -> 0
A13: 45307 | B13: Tuesday | C13: =SUM(PL!H13:J13) -> 0 | D13: =SUM(PL!K13:M13) -> 0 | E13: =SUM(PL!N13:P13) -> 0 | F13: =SUM(PL!Q13:S13) -> 0 | G13: =SUM(PL!T13:V13) -> 0 | H13: =SUM(C13:G13) -> 0 | I13: =IF(C13 + I12 < 0, C13 + I12, 0) -> 0 | J13: =IF(D13 + J12 < 0, D13 + J12, 0) -> 0 | K13: =IF(E13 + K12 < 0, E13 + K12, 0) -> 0 | L13: =IF(F13 + L12 < 0, F13 + L12, 0) -> 0 | M13: =IF(G13 + M12 < 0, G13 + M12, 0) -> 0 | N13: =IF(H13 + N12 < 0, H13 + N12, 0) -> 0 | O13: =IF(N13 < 0, 1 + O12, 0) -> 0 | P13: =C13-((ABS(SUM(PL!H13:J13)))*0.125) -> 0 | Q13: =D13-((ABS(SUM(PL!K13:M13)))*0.125) -> 0 | R13: =E13-((ABS(SUM(PL!N13:P13)))*0.125) -> 0 | S13: =F13-((ABS(SUM(PL!Q13:S13)))*0.125) -> 0 | T13: =G13-((ABS(SUM(PL!T13:V13)))*0.125) -> 0 | U13: =P13 + Q13 + R13 + S13 + T13 -> 0 | V13: =IF(P13 + V12 < 0, P13 + V12, 0) -> 0 | W13: =IF(Q13 + W12 < 0, Q13 + W12, 0) -> 0 | X13: =IF(R13 + X12 < 0, R13 + X12, 0) -> 0 | Y13: =IF(S13 + Y12 < 0, S13 + Y12, 0) -> 0 | Z13: =IF(T13 + Z12 < 0, T13 + Z12, 0) -> 0 | AA13: =IF(U13 + AA12 < 0, U13 + AA12, 0) -> 0 | AB13: =IF(AA13 < 0, 1 + AB12, 0) -> 0 | AC13: =IF(H13<0,1,0) -> 0 | AD13: =IF(AC13=1,H13,0) -> 0 | AE13: =IF(H13>0,1,0) -> 0 | AF13: =IF(AE13=1,H13,0) -> 0 | AG13: =IF(AD13<-20000000.0/100,1,0) -> 0 | AH13: =IF(AF13>20000000.0/100,1,0) -> 0 | AI13: =IF(U13<0,1,0) -> 0 | AJ13: =IF(AI13=1,U13,0) -> 0 | AK13: =IF(U13>0,1,0) -> 0 | AL13: =IF(AK13=1,U13,0) -> 0 | AM13: =IF(AJ13<-20000000.0/100,1,0) -> 0 | AN13: =IF(AL13>20000000.0/100,1,0) -> 0
A14: 45308 | B14: Wednesday | C14: =SUM(PL!H14:J14) -> 0 | D14: =SUM(PL!K14:M14) -> 0 | E14: =SUM(PL!N14:P14) -> 0 | F14: =SUM(PL!Q14:S14) -> 0 | G14: =SUM(PL!T14:V14) -> 0 | H14: =SUM(C14:G14) -> 0 | I14: =IF(C14 + I13 < 0, C14 + I13, 0) -> 0 | J14: =IF(D14 + J13 < 0, D14 + J13, 0) -> 0 | K14: =IF(E14 + K13 < 0, E14 + K13, 0) -> 0 | L14: =IF(F14 + L13 < 0, F14 + L13, 0) -> 0 | M14: =IF(G14 + M13 < 0, G14 + M13, 0) -> 0 | N14: =IF(H14 + N13 < 0, H14 + N13, 0) -> 0 | O14: =IF(N14 < 0, 1 + O13, 0) -> 0 | P14: =C14-((ABS(SUM(PL!H14:J14)))*0.125) -> 0 | Q14: =D14-((ABS(SUM(PL!K14:M14)))*0.125) -> 0 | R14: =E14-((ABS(SUM(PL!N14:P14)))*0.125) -> 0 | S14: =F14-((ABS(SUM(PL!Q14:S14)))*0.125) -> 0 | T14: =G14-((ABS(SUM(PL!T14:V14)))*0.125) -> 0 | U14: =P14 + Q14 + R14 + S14 + T14 -> 0 | V14: =IF(P14 + V13 < 0, P14 + V13, 0) -> 0 | W14: =IF(Q14 + W13 < 0, Q14 + W13, 0) -> 0 | X14: =IF(R14 + X13 < 0, R14 + X13, 0) -> 0 | Y14: =IF(S14 + Y13 < 0, S14 + Y13, 0) -> 0 | Z14: =IF(T14 + Z13 < 0, T14 + Z13, 0) -> 0 | AA14: =IF(U14 + AA13 < 0, U14 + AA13, 0) -> 0 | AB14: =IF(AA14 < 0, 1 + AB13, 0) -> 0 | AC14: =IF(H14<0,1,0) -> 0 | AD14: =IF(AC14=1,H14,0) -> 0 | AE14: =IF(H14>0,1,0) -> 0 | AF14: =IF(AE14=1,H14,0) -> 0 | AG14: =IF(AD14<-20000000.0/100,1,0) -> 0 | AH14: =IF(AF14>20000000.0/100,1,0) -> 0 | AI14: =IF(U14<0,1,0) -> 0 | AJ14: =IF(AI14=1,U14,0) -> 0 | AK14: =IF(U14>0,1,0) -> 0 | AL14: =IF(AK14=1,U14,0) -> 0 | AM14: =IF(AJ14<-20000000.0/100,1,0) -> 0 | AN14: =IF(AL14>20000000.0/100,1,0) -> 0
... A510: 46044 | B510: Thursday | C510: =SUM(PL!H510:J510) -> 0 | D510: =SUM(PL!K510:M510) -> 0 | E510: =SUM(PL!N510:P510) -> 0 | F510: =SUM(PL!Q510:S510) -> 0 | G510: =SUM(PL!T510:V510) -> 0 | H510: =SUM(C510:G510) -> 0 | I510: =IF(C510 + I509 < 0, C510 + I509, 0) -> 0 | J510: =IF(D510 + J509 < 0, D510 + J509, 0) -> 0 | K510: =IF(E510 + K509 < 0, E510 + K509, 0) -> 0 | L510: =IF(F510 + L509 < 0, F510 + L509, 0) -> 0 | M510: =IF(G510 + M509 < 0, G510 + M509, 0) -> 0 | N510: =IF(H510 + N509 < 0, H510 + N509, 0) -> 0 | O510: =IF(N510 < 0, 1 + O509, 0) -> 0 | P510: =C510-((ABS(SUM(PL!H510:J510)))*0.125) -> 0 | Q510: =D510-((ABS(SUM(PL!K510:M510)))*0.125) -> 0 | R510: =E510-((ABS(SUM(PL!N510:P510)))*0.125) -> 0 | S510: =F510-((ABS(SUM(PL!Q510:S510)))*0.125) -> 0 | T510: =G510-((ABS(SUM(PL!T510:V510)))*0.125) -> 0 | U510: =P510 + Q510 + R510 + S510 + T510 -> 0 | V510: =IF(P510 + V509 < 0, P510 + V509, 0) -> 0 | W510: =IF(Q510 + W509 < 0, Q510 + W509, 0) -> 0 | X510: =IF(R510 + X509 < 0, R510 + X509, 0) -> 0 | Y510: =IF(S510 + Y509 < 0, S510 + Y509, 0) -> 0 | Z510: =IF(T510 + Z509 < 0, T510 + Z509, 0) -> 0 | AA510: =IF(U510 + AA509 < 0, U510 + AA509, 0) -> 0 | AB510: =IF(AA510 < 0, 1 + AB509, 0) -> 0 | AC510: =IF(H510<0,1,0) -> 0 | AD510: =IF(AC510=1,H510,0) -> 0 | AE510: =IF(H510>0,1,0) -> 0 | AF510: =IF(AE510=1,H510,0) -> 0 | AG510: =IF(AD510<-20000000.0/100,1,0) -> 0 | AH510: =IF(AF510>20000000.0/100,1,0) -> 0 | AI510: =IF(U510<0,1,0) -> 0 | AJ510: =IF(AI510=1,U510,0) -> 0 | AK510: =IF(U510>0,1,0) -> 0 | AL510: =IF(AK510=1,U510,0) -> 0 | AM510: =IF(AJ510<-20000000.0/100,1,0) -> 0 | AN510: =IF(AL510>20000000.0/100,1,0) -> 0
A511: Total | C511: =SUM(C2:C510) -> 0 | D511: =SUM(D2:D510) -> 0 | E511: =SUM(E2:E510) -> 0 | F511: =SUM(F2:F510) -> 0 | G511: =SUM(G2:G510) -> 0 | H511: =SUM(H2:H510) -> 0 | I511: =MIN(I2:I510) -> 0 | J511: =MIN(J2:J510) -> 0 | K511: =MIN(K2:K510) -> 0 | L511: =MIN(L2:L510) -> 0 | M511: =MIN(M2:M510) -> 0 | N511: =MIN(N2:N510) -> 0 | O511: =MAX(O2:O510) -> 0 | P511: =SUM(P2:P510) -> 0 | Q511: =SUM(Q2:Q510) -> 0 | R511: =SUM(R2:R510) -> 0 | S511: =SUM(S2:S510) -> 0 | T511: =SUM(T2:T510) -> 0 | U511: =SUM(U2:U510) -> 0 | V511: =MIN(V2:V510) -> 0 | W511: =MIN(W2:W510) -> 0 | X511: =MIN(X2:X510) -> 0 | Y511: =MIN(Y2:Y510) -> 0 | Z511: =MIN(Z2:Z510) -> 0 | AA511: =MIN(AA2:AA510) -> 0 | AB511: =MAX(AB2:AB510) -> 0 | AC511: =SUM(AC2:AC510) -> 0 | AD511: =SUM(AD2:AD510) -> 0 | AE511: =SUM(AE2:AE510) -> 0 | AF511: =SUM(AF2:AF510) -> 0 | AG511: =SUM(AG2:AG510) -> 0 | AH511: =SUM(AH2:AH510) -> 0 | AI511: =SUM(AI2:AI510) -> 0 | AJ511: =SUM(AJ2:AJ510) -> 0 | ... AN511: =SUM(AN2:AN510) -> 0
A512: Months | C512: 24.72 | D512: 24.72 | E512: 24.72 | F512: 24.72 | G512: 24.72 | P512: 24.72 | Q512: 24.72 | R512: 24.72 | S512: 24.72 | T512: 24.72 | AD512: =AD511/AC511 -> 0 | AF512: =AF511/AE511 -> 0 | AJ512: =AJ511/AI511 -> 0 | AL512: =AL511/AK511 -> 0
A513: Per Month | C513: =C511/C512 -> 0 | D513: =D511/D512 -> 0 | E513: =E511/E512 -> 0 | F513: =F511/F512 -> 0 | G513: =G511/G512 -> 0 | H513: =C513+D513+E513+F513+G513 -> 0 | P513: =P511/P512 -> 0 | Q513: =Q511/Q512 -> 0 | R513: =R511/R512 -> 0 | S513: =S511/S512 -> 0 | T513: =T511/T512 -> 0 | U513: =P513+Q513+R513+S513+T513 -> 0 | AF513: =AF512/AD512*-1 -> 0 | AL513: =AL512/AJ512*-1 -> 0
