Workbook

Sheet PL
A1: Date | B1: Day | C1: NF DTE | D1: SX DTE | E1: NF NRE_CC_1 | F1: NF NRE_CC_2 | G1: NF NRE_CC_3 | H1: NF SRE_PREMIUM_SHIFT_1 | I1: NF SRE_PREMIUM_SHIFT_2 | J1: NF SRE_PREMIUM_SHIFT_3 | K1: NF SRE_PREMIUM_SHIFT_4 | L1: NF SRE_PREMIUM_SHIFT_5 | M1: NF SRE_PREMIUM_SHIFT_6 | N1: NF SRE_PREMIUM_SHIFT_7 | O1: NF SRE_PREMIUM_SHIFT_8 | P1: NF SRE_PREMIUM_SHIFT_9 | Q1: NF SRE_PREMIUM_SHIFT_10 | R1: NF SRE_PREMIUM_SHIFT_11 | S1: NF SRE_PREMIUM_SHIFT_12 | T1: NF SRE_PREMIUM_SHIFT_13 | U1: NF SRE_PREMIUM_SHIFT_14 | V1: NF SRE_PREMIUM_SHIFT_15 | W1: NF SRE_PREMIUM_SHIFT_16 | X1: NF SRE_PREMIUM_SHIFT_17 | Y1: NF SRE_PREMIUM_SHIFT_18 | Z1: NF SRE_PREMIUM_SHIFT_19 | AA1: NF SRE_PREMIUM_SHIFT_20 | AB1: NF SRE_PREMIUM_SHIFT_21 | AC1: NF SRE_PREMIUM_SHIFT_22 | AD1: NF SRE_PREMIUM_SHIFT_23 | AE1: NF SRE_PREMIUM_SHIFT_24 | AF1: NF SRE_PREMIUM_SHIFT_25 | AG1: NF SRE_PREMIUM_SHIFT_26 | AH1: NF SRE_PREMIUM_SHIFT_27 | AI1: NF SRE_PREMIUM_SHIFT_28 | AJ1: NF SRE_PREMIUM_SHIFT_29 | AK1: NF SRE_PREMIUM_SHIFT_30 | AL1: NF SRE_SEPARATE_LEG_SL_1 | AM1: NF SRE_SEPARATE_LEG_SL_2 | AN1: NF SRE_SEPARATE_LEG_SL_3 | AO1: SX NRE_CC_1 | AP1: SX NRE_CC_2 | AQ1: SX NRE_CC_3 | AR1: SX SRE_PREMIUM_SHIFT_1 | AS1: SX SRE_PREMIUM_SHIFT_2 | AT1: SX SRE_PREMIUM_SHIFT_3 | AU1: SX SRE_PREMIUM_SHIFT_4 | AV1: SX SRE_PREMIUM_SHIFT_5 | AW1: SX SRE_PREMIUM_SHIFT_6 | AX1: SX SRE_PREMIUM_SHIFT_7 | AY1: SX SRE_PREMIUM_SHIFT_8 | AZ1: SX SRE_PREMIUM_SHIFT_9 | BA1: SX SRE_PREMIUM_SHIFT_10 | BB1: SX SRE_PREMIUM_SHIFT_11 | BC1: SX SRE_PREMIUM_SHIFT_12 | BD1: SX SRE_PREMIUM_SHIFT_13 | BE1: SX SRE_PREMIUM_SHIFT_14 | BF1: SX SRE_PREMIUM_SHIFT_15 | BG1: SX SRE_PREMIUM_SHIFT_16 | BH1: SX SRE_PREMIUM_SHIFT_17 | BI1: SX SRE_PREMIUM_SHIFT_18 | BJ1: SX SRE_PREMIUM_SHIFT_19 | BK1: SX SRE_PREMIUM_SHIFT_20 | BL1: SX SRE_PREMIUM_SHIFT_21 | BM1: SX SRE_PREMIUM_SHIFT_22 | BN1: SX SRE_PREMIUM_SHIFT_23 | BO1: SX SRE_PREMIUM_SHIFT_24 | BP1: SX SRE_PREMIUM_SHIFT_25 | BQ1: SX SRE_PREMIUM_SHIFT_26 | BR1: SX SRE_PREMIUM_SHIFT_27 | BS1: SX SRE_PREMIUM_SHIFT_28 | BT1: SX SRE_PREMIUM_SHIFT_29 | BU1: SX SRE_PREMIUM_SHIFT_30 | BV1: SX SRE_SEPARATE_LEG_SL_1 | BW1: SX SRE_SEPARATE_LEG_SL_2 | BX1: SX SRE_SEPARATE_LEG_SL_3
A2: 45292 | B2: Monday | C2: 4 | D2: 5 | E2: 0 | F2: 0 | G2: 0 | H2: 0 | I2: 0 | J2: 0 | K2: 0 | L2: 0 | M2: 0 | N2: 0 | O2: 0 | P2: 0 | Q2: 0 | R2: 0 | S2: 0 | T2: 0 | U2: 0 | V2: 0 | W2: 0 | X2: 0 | Y2: 0 | Z2: 0 | AA2: 0 | AB2: 0 | AC2: 0 | AD2: 0 | AE2: 0 | AF2: 0 | AG2: 0 | AH2: 0 | AI2: 0 | AJ2: 0 | AK2: 0 | AL2: 0 | AM2: 0 | AN2: 0 | AO2: 0 | AP2: 0 | AQ2: 0 | AR2: 0 | AS2: 0 | AT2: 0 | AU2: 0 | AV2: 0 | AW2: 0 | AX2: 0 | AY2: 0 | AZ2: 0 | BA2: 0 | BB2: 0 | BC2: 0 | BD2: 0 | BE2: 0 | BF2: 0 | BG2: 0 | BH2: 0 | BI2: 0 | BJ2: 0 | BK2: 0 | BL2: 0 | BM2: 0 | BN2: 0 | BO2: 0 | BP2: 0 | BQ2: 0 | BR2: 0 | BS2: 0 | BT2: 0 | BU2: 0 | BV2: 0 | BW2: 0 | BX2: 0
A3: 45293 | B3: Tuesday | C3: 3 | D3: 4 | E3: 27719.818 | F3: 7586.2108 | G3: 179.48891 | H3: 0 | I3: 0 | J3: 0 | K3: 0 | L3: 0 | M3: 0 | N3: 0 | O3: 0 | P3: 0 | Q3: 0 | R3: 0 | S3: 0 | T3: 0 | U3: 0 | V3: 0 | W3: 0 | X3: 0 | Y3: 0 | Z3: 0 | AA3: 0 | AB3: 0 | AC3: 0 | AD3: 0 | AE3: 0 | AF3: 0 | AG3: 0 | AH3: 0 | AI3: 0 | AJ3: 0 | AK3: 0 | AL3: -206082.96 | AM3: -203332.48 | AN3: -198809.3 | AO3: 0 | AP3: 0 | AQ3: 0 | AR3: 0 | AS3: 0 | AT3: 0 | AU3: 0 | AV3: 0 | AW3: 0 | AX3: 0 | AY3: 0 | AZ3: 0 | BA3: 0 | BB3: 0 | BC3: 0 | BD3: 0 | BE3: 0 | BF3: 0 | BG3: 0 | BH3: 0 | BI3: 0 | BJ3: 0 | BK3: 0 | BL3: 0 | BM3: 0 | BN3: 0 | BO3: 0 | BP3: 0 | BQ3: 0 | BR3: 0 | BS3: 0 | BT3: 0 | BU3: 0 | BV3: 0 | BW3: 0 | BX3: 0
A4: 45294 | B4: Wednesday | C4: 2 | D4: 3 | E4: 18699.793 | F4: 38528.63 | G4: 40947.607 | H4: 0 | I4: 0 | J4: 0 | K4: 0 | L4: 0 | M4: 0 | N4: 0 | O4: 0 | P4: 0 | Q4: 0 | R4: 0 | S4: 0 | T4: 0 | U4: 0 | V4: 0 | W4: 0 | X4: 0 | Y4: 0 | Z4: 0 | AA4: 0 | AB4: 0 | AC4: 0 | AD4: 0 | AE4: 0 | AF4: 0 | AG4: 0 | AH4: 0 | AI4: 0 | AJ4: 0 | AK4: 0 | AL4: 98259.448 | AM4: 93634.836 | AN4: 83157.201 | AO4: 0 | AP4: 0 | AQ4: 0 | AR4: 0 | AS4: 0 | AT4: 0 | AU4: 0 | AV4: 0 | AW4: 0 | AX4: 0 | AY4: 0 | AZ4: 0 | BA4: 0 | BB4: 0 | BC4: 0 | BD4: 0 | BE4: 0 | BF4: 0 | BG4: 0 | BH4: 0 | BI4: 0 | BJ4: 0 | BK4: 0 | BL4: 0 | BM4: 0 | BN4: 0 | BO4: 0 | BP4: 0 | BQ4: 0 | BR4: 0 | BS4: 0 | BT4: 0 | BU4: 0 | BV4: 0 | BW4: 0 | BX4: 0
A5: 45295 | B5: Thursday | C5: 1 | D5: 2 | E5: 148233.98 | F5: 152181.42 | G5: 154697.02 | H5: 10096.894 | I5: 19066.377 | J5: 18015.938 | K5: 16888.527 | L5: 16218.419 | M5: 15367.201 | N5: 16082.586 | O5: 15009.508 | P5: 14606.538 | Q5: 13959.069 | R5: 10096.894 | S5: 19066.377 | T5: 18015.938 | U5: 16888.527 | V5: 16218.419 | W5: 15367.201 | X5: 16082.586 | Y5: 15009.508 | Z5: 14606.538 | AA5: 13959.069 | AB5: 15892.421 | AC5: 9635.0629 | AD5: 8806.4837 | AE5: 8177.1258 | AF5: 7842.0719 | AG5: 7507.018 | AH5: 7842.0719 | AI5: 15009.508 | AJ5: 14606.538 | AK5: 13959.069 | AL5: 0 | AM5: 0 | AN5: 0 | AO5: 99722.7 | AP5: 85132.787 | AQ5: 91321.54 | AR5: 0 | AS5: 0 | AT5: 0 | AU5: 0 | AV5: 0 | AW5: 0 | AX5: 0 | AY5: 0 | AZ5: 0 | BA5: 0 | BB5: 0 | BC5: 0 | BD5: 0 | BE5: 0 | BF5: 0 | BG5: 0 | BH5: 0 | BI5: 0 | BJ5: 0 | BK5: 0 | BL5: 0 | BM5: 0 | BN5: 0 | BO5: 0 | BP5: 0 | BQ5: 0 | BR5: 0 | BS5: 0 | BT5: 0 | BU5: 0 | BV5: 99287.371 | BW5: 96130.935 | BX5: 72110.526
A6: 45296 | B6: Friday | C6: 5 | D6: 1 | E6: 0 | F6: 0 | G6: 0 | H6: 0 | I6: 0 | J6: 0 | K6: 0 | L6: 0 | M6: 0 | N6: 0 | O6: 0 | P6: 0 | Q6: 0 | R6: 0 | S6: 0 | T6: 0 | U6: 0 | V6: 0 | W6: 0 | X6: 0 | Y6: 0 | Z6: 0 | AA6: 0 | AB6: 0 | AC6: 0 | AD6: 0 | AE6: 0 | AF6: 0 | AG6: 0 | AH6: 0 | AI6: 0 | AJ6: 0 | AK6: 0 | AL6: 0 | AM6: 0 | AN6: 0 | AO6: 94223.067 | AP6: 71910.051 | AQ6: 64767.473 | AR6: 23030.179 | AS6: 22520.392 | AT6: 22024.198 | AU6: 22735.182 | AV6: 23051.93 | AW6: 23251.767 | AX6: 23582.11 | AY6: 23461.12 | AZ6: 23527.732 | BA6: 19042.958 | BB6: 23030.179 | BC6: 22520.392 | BD6: 22024.198 | BE6: 22735.182 | BF6: 23051.93 | BG6: 23251.767 | BH6: 23582.11 | BI6: 23461.12 | BJ6: 23527.732 | BK6: 19042.958 | BL6: 17533.986 | BM6: 16929.038 | BN6: 16620.446 | BO6: 17084.013 | BP6: 17184.611 | BQ6: 17345.024 | BR6: 17553.018 | BS6: 17607.395 | BT6: 17553.018 | BU6: 17761.011 | BV6: 0 | BW6: 0 | BX6: 0
A7: 45299 | B7: Monday | C7: 4 | D7: 5 | E7: 0 | F7: 0 | G7: 0 | H7: 0 | I7: 0 | J7: 0 | K7: 0 | L7: 0 | M7: 0 | N7: 0 | O7: 0 | P7: 0 | Q7: 0 | R7: 0 | S7: 0 | T7: 0 | U7: 0 | V7: 0 | W7: 0 | X7: 0 | Y7: 0 | Z7: 0 | AA7: 0 | AB7: 0 | AC7: 0 | AD7: 0 | AE7: 0 | AF7: 0 | AG7: 0 | AH7: 0 | AI7: 0 | AJ7: 0 | AK7: 0 | AL7: 0 | AM7: 0 | AN7: 0 | AO7: 0 | AP7: 0 | AQ7: 0 | AR7: 0 | AS7: 0 | AT7: 0 | AU7: 0 | AV7: 0 | AW7: 0 | AX7: 0 | AY7: 0 | AZ7: 0 | BA7: 0 | BB7: 0 | BC7: 0 | BD7: 0 | BE7: 0 | BF7: 0 | BG7: 0 | BH7: 0 | BI7: 0 | BJ7: 0 | BK7: 0 | BL7: 0 | BM7: 0 | BN7: 0 | BO7: 0 | BP7: 0 | BQ7: 0 | BR7: 0 | BS7: 0 | BT7: 0 | BU7: 0 | BV7: 0 | BW7: 0 | BX7: 0
A8: 45300 | B8: Tuesday | C8: 3 | D8: 4 | E8: -22301.663 | F8: -46647.691 | G8: -76683.496 | H8: 0 | I8: 0 | J8: 0 | K8: 0 | L8: 0 | M8: 0 | N8: 0 | O8: 0 | P8: 0 | Q8: 0 | R8: 0 | S8: 0 | T8: 0 | U8: 0 | V8: 0 | W8: 0 | X8: 0 | Y8: 0 | Z8: 0 | AA8: 0 | AB8: 0 | AC8: 0 | AD8: 0 | AE8: 0 | AF8: 0 | AG8: 0 | AH8: 0 | AI8: 0 | AJ8: 0 | AK8: 0 | AL8: -119232.85 | AM8: -66016.084 | AN8: -57852.173 | AO8: 0 | AP8: 0 | AQ8: 0 | AR8: 0 | AS8: 0 | AT8: 0 | AU8: 0 | AV8: 0 | AW8: 0 | AX8: 0 | AY8: 0 | AZ8: 0 | BA8: 0 | BB8: 0 | BC8: 0 | BD8: 0 | BE8: 0 | BF8: 0 | BG8: 0 | BH8: 0 | BI8: 0 | BJ8: 0 | BK8: 0 | BL8: 0 | BM8: 0 | BN8: 0 | BO8: 0 | BP8: 0 | BQ8: 0 | BR8: 0 | BS8: 0 | BT8: 0 | BU8: 0 | BV8: 0 | BW8: 0 | BX8: 0
A9: 45301 | B9: Wednesday | C9: 2 | D9: 3 | E9: -98317.301 | F9: -130952.58 | G9: -106881.19 | H9: 0 | I9: 0 | J9: 0 | K9: 0 | L9: 0 | M9: 0 | N9: 0 | O9: 0 | P9: 0 | Q9: 0 | R9: 0 | S9: 0 | T9: 0 | U9: 0 | V9: 0 | W9: 0 | X9: 0 | Y9: 0 | Z9: 0 | AA9: 0 | AB9: 0 | AC9: 0 | AD9: 0 | AE9: 0 | AF9: 0 | AG9: 0 | AH9: 0 | AI9: 0 | AJ9: 0 | AK9: 0 | AL9: -92161.777 | AM9: -41438.521 | AN9: -4789.9244 | AO9: 0 | AP9: 0 | AQ9: 0 | AR9: 0 | AS9: 0 | AT9: 0 | AU9: 0 | AV9: 0 | AW9: 0 | AX9: 0 | AY9: 0 | AZ9: 0 | BA9: 0 | BB9: 0 | BC9: 0 | BD9: 0 | BE9: 0 | BF9: 0 | BG9: 0 | BH9: 0 | BI9: 0 | BJ9: 0 | BK9: 0 | BL9: 0 | BM9: 0 | BN9: 0 | BO9: 0 | BP9: 0 | BQ9: 0 | BR9: 0 | BS9: 0 | BT9: 0 | BU9: 0 | BV9: 0 | BW9: 0 | BX9: 0
A10: 45302 | B10: Thursday | C10: 1 | D10: 2 | E10: 83634.654 | F10: 28126.971 | G10: 30469.947 | H10: 9146.6162 | I10: 9705.3258 | J10: 10128.864 | K10: 9124.0876 | L10: 19032.171 | M10: 18896.999 | N10: 19122.285 | O10: 6790.1235 | P10: 6587.366 | Q10: 9502.5683 | R10: 9146.6162 | S10: 9705.3258 | T10: 10128.864 | U10: 9124.0876 | V10: 19032.171 | W10: 18896.999 | X10: 19122.285 | Y10: 6790.1235 | Z10: 6587.366 | AA10: 9502.5683 | AB10: -1459.854 | AC10: -1464.3597 | AD10: -1468.8655 | AE10: -1459.854 | AF10: -1459.854 | AG10: -1459.854 | AH10: -1464.3597 | AI10: 6790.1235 | AJ10: 6587.366 | AK10: -1473.3712 | AL10: 0 | AM10: 0 | AN10: 0 | AO10: 29148.628 | AP10: 27072.546 | AQ10: 3451.9008 | AR10: 0 | AS10: 0 | AT10: 0 | AU10: 0 | AV10: 0 | AW10: 0 | AX10: 0 | AY10: 0 | AZ10: 0 | BA10: 0 | BB10: 0 | BC10: 0 | BD10: 0 | BE10: 0 | BF10: 0 | BG10: 0 | BH10: 0 | BI10: 0 | BJ10: 0 | BK10: 0 | BL10: 0 | BM10: 0 | BN10: 0 | BO10: 0 | BP10: 0 | BQ10: 0 | BR10: 0 | BS10: 0 | BT10: 0 | BU10: 0 | BV10: -23838.148 | BW10: 85658.674 | BX10: 63765.58
A11: 45303 | B11: Friday | C11: 5 | D11: 1 | E11: 0 | F11: 0 | G11: 0 | H11: 0 | I11: 0 | J11: 0 | K11: 0 | L11: 0 | M11: 0 | N11: 0 | O11: 0 | P11: 0 | Q11: 0 | R11: 0 | S11: 0 | T11: 0 | U11: 0 | V11: 0 | W11: 0 | X11: 0 | Y11: 0 | Z11: 0 | AA11: 0 | AB11: 0 | AC11: 0 | AD11: 0 | AE11: 0 | AF11: 0 | AG11: 0 | AH11: 0 | AI11: 0 | AJ11: 0 | AK11: 0 | AL11: 0 | AM11: 0 | AN11: 0 | AO11: 157755.87 | AP11: 134220.84 | AQ11: 108321.17 | AR11: -17939.191 | AS11: -17931.025 | AT11: -14982.018 | AU11: -15466.02 | AV11: -14982.869 | AW11: -14975.128 | AX11: -12203.985 | AY11: -15433.441 | AZ11: -15284.498 | BA11: -15514.079 | BB11: -17939.191 | BC11: -17931.025 | BD11: -14982.018 | BE11: -15466.02 | BF11: -14982.869 | BG11: -14975.128 | BH11: -12203.985 | BI11: -15433.441 | BJ11: -15284.498 | BK11: -15514.079 | BL11: -15319.288 | BM11: -16265.175 | BN11: -16235.233 | BO11: -16263.814 | BP11: -16236.594 | BQ11: -16236.594 | BR11: -16261.092 | BS11: -16263.814 | BT11: -18629.212 | BU11: -16266.536 | BV11: 0 | BW11: 0 | BX11: 0
A12: 45306 | B12: Monday | C12: 4 | D12: 5 | E12: 0 | F12: 0 | G12: 0 | H12: 0 | I12: 0 | J12: 0 | K12: 0 | L12: 0 | M12: 0 | N12: 0 | O12: 0 | P12: 0 | Q12: 0 | R12: 0 | S12: 0 | T12: 0 | U12: 0 | V12: 0 | W12: 0 | X12: 0 | Y12: 0 | Z12: 0 | AA12: 0 | AB12: 0 | AC12: 0 | AD12: 0 | AE12: 0 | AF12: 0 | AG12: 0 | AH12: 0 | AI12: 0 | AJ12: 0 | AK12: 0 | AL12: 0 | AM12: 0 | AN12: 0 | AO12: 0 | AP12: 0 | AQ12: 0 | AR12: 0 | AS12: 0 | AT12: 0 | AU12: 0 | AV12: 0 | AW12: 0 | AX12: 0 | AY12: 0 | AZ12: 0 | BA12: 0 | BB12: 0 | BC12: 0 | BD12: 0 | BE12: 0 | BF12: 0 | BG12: 0 | BH12: 0 | BI12: 0 | BJ12: 0 | BK12: 0 | BL12: 0 | BM12: 0 | BN12: 0 | BO12: 0 | BP12: 0 | BQ12: 0 | BR12: 0 | BS12: 0 | BT12: 0 | BU12: 0 | BV12: 0 | BW12: 0 | BX12: 0
A13: 45307 | B13: Tuesday | C13: 3 | D13: 4 | E13: -71815.109 | F13: -57245.617 | G13: -43614.122 | H13: 0 | I13: 0 | J13: 0 | K13: 0 | L13: 0 | M13: 0 | N13: 0 | O13: 0 | P13: 0 | Q13: 0 | R13: 0 | S13: 0 | T13: 0 | U13: 0 | V13: 0 | W13: 0 | X13: 0 | Y13: 0 | Z13: 0 | AA13: 0 | AB13: 0 | AC13: 0 | AD13: 0 | AE13: 0 | AF13: 0 | AG13: 0 | AH13: 0 | AI13: 0 | AJ13: 0 | AK13: 0 | AL13: 132098.93 | AM13: 119475.16 | AN13: 87638.204 | AO13: 0 | AP13: 0 | AQ13: 0 | AR13: 0 | AS13: 0 | AT13: 0 | AU13: 0 | AV13: 0 | AW13: 0 | AX13: 0 | AY13: 0 | AZ13: 0 | BA13: 0 | BB13: 0 | BC13: 0 | BD13: 0 | BE13: 0 | BF13: 0 | BG13: 0 | BH13: 0 | BI13: 0 | BJ13: 0 | BK13: 0 | BL13: 0 | BM13: 0 | BN13: 0 | BO13: 0 | BP13: 0 | BQ13: 0 | BR13: 0 | BS13: 0 | BT13: 0 | BU13: 0 | BV13: 0 | BW13: 0 | BX13: 0
... A511: 46045 | B511: Friday | C511: 2 | D511: 4 | E511: 19567.936 | F511: 22783.789 | G511: 2421.5472 | H511: 0 | I511: 0 | J511: 0 | K511: 0 | L511: 0 | M511: 0 | N511: 0 | O511: 0 | P511: 0 | Q511: 0 | R511: 0 | S511: 0 | T511: 0 | U511: 0 | V511: 0 | W511: 0 | X511: 0 | Y511: 0 | Z511: 0 | AA511: 0 | AB511: 0 | AC511: 0 | AD511: 0 | AE511: 0 | AF511: 0 | AG511: 0 | AH511: 0 | AI511: 0 | AJ511: 0 | AK511: 0 | AL511: -121543.63 | AM511: -198931.32 | AN511: -164595.16 | AO511: 0 | AP511: 0 | AQ511: 0 | AR511: 0 | AS511: 0 | AT511: 0 | AU511: 0 | AV511: 0 | AW511: 0 | AX511: 0 | AY511: 0 | AZ511: 0 | BA511: 0 | BB511: 0 | BC511: 0 | BD511: 0 | BE511: 0 | BF511: 0 | BG511: 0 | BH511: 0 | BI511: 0 | BJ511: 0 | BK511: 0 | BL511: 0 | BM511: 0 | BN511: 0 | BO511: 0 | BP511: 0 | BQ511: 0 | BR511: 0 | BS511: 0 | BT511: 0 | BU511: 0 | BV511: 0 | BW511: 0 | BX511: 0

Sheet Exit Times
A1: Date | B1: NIFTY | C1: NF NRE_CC_1 | D1: NF NRE_CC_2 | E1: NF NRE_CC_3 | F1: NF SRE_PREMIUM_SHIFT_1 | G1: NF SRE_PREMIUM_SHIFT_2 | H1: NF SRE_PREMIUM_SHIFT_3 | I1: NF SRE_PREMIUM_SHIFT_4 | J1: NF SRE_PREMIUM_SHIFT_5 | K1: NF SRE_PREMIUM_SHIFT_6 | L1: NF SRE_PREMIUM_SHIFT_7 | M1: NF SRE_PREMIUM_SHIFT_8 | N1: NF SRE_PREMIUM_SHIFT_9 | O1: NF SRE_PREMIUM_SHIFT_10 | P1: NF SRE_PREMIUM_SHIFT_11 | Q1: NF SRE_PREMIUM_SHIFT_12 | R1: NF SRE_PREMIUM_SHIFT_13 | S1: NF SRE_PREMIUM_SHIFT_14 | T1: NF SRE_PREMIUM_SHIFT_15 | U1: NF SRE_PREMIUM_SHIFT_16 | V1: NF SRE_PREMIUM_SHIFT_17 | W1: NF SRE_PREMIUM_SHIFT_18 | X1: NF SRE_PREMIUM_SHIFT_19 | Y1: NF SRE_PREMIUM_SHIFT_20 | Z1: NF SRE_PREMIUM_SHIFT_21 | AA1: NF SRE_PREMIUM_SHIFT_22 | AB1: NF SRE_PREMIUM_SHIFT_23 | AC1: NF SRE_PREMIUM_SHIFT_24 | AD1: NF SRE_PREMIUM_SHIFT_25 | AE1: NF SRE_PREMIUM_SHIFT_26 | AF1: NF SRE_PREMIUM_SHIFT_27 | AG1: NF SRE_PREMIUM_SHIFT_28 | AH1: NF SRE_PREMIUM_SHIFT_29 | AI1: NF SRE_PREMIUM_SHIFT_30 | AJ1: NF SRE_SEPARATE_LEG_SL_1 | AK1: NF SRE_SEPARATE_LEG_SL_2 | AL1: NF SRE_SEPARATE_LEG_SL_3 | AM1: SENSEX | AN1: SX NRE_CC_1 | AO1: SX NRE_CC_2 | AP1: SX NRE_CC_3 | AQ1: SX SRE_PREMIUM_SHIFT_1 | AR1: SX SRE_PREMIUM_SHIFT_2 | AS1: SX SRE_PREMIUM_SHIFT_3 | AT1: SX SRE_PREMIUM_SHIFT_4 | AU1: SX SRE_PREMIUM_SHIFT_5 | AV1: SX SRE_PREMIUM_SHIFT_6 | AW1: SX SRE_PREMIUM_SHIFT_7 | AX1: SX SRE_PREMIUM_SHIFT_8 | AY1: SX SRE_PREMIUM_SHIFT_9 | AZ1: SX SRE_PREMIUM_SHIFT_10 | BA1: SX SRE_PREMIUM_SHIFT_11 | BB1: SX SRE_PREMIUM_SHIFT_12 | BC1: SX SRE_PREMIUM_SHIFT_13 | BD1: SX SRE_PREMIUM_SHIFT_14 | BE1: SX SRE_PREMIUM_SHIFT_15 | BF1: SX SRE_PREMIUM_SHIFT_16 | BG1: SX SRE_PREMIUM_SHIFT_17 | BH1: SX SRE_PREMIUM_SHIFT_18 | BI1: SX SRE_PREMIUM_SHIFT_19 | BJ1: SX SRE_PREMIUM_SHIFT_20 | BK1: SX SRE_PREMIUM_SHIFT_21 | BL1: SX SRE_PREMIUM_SHIFT_22 | BM1: SX SRE_PREMIUM_SHIFT_23 | BN1: SX SRE_PREMIUM_SHIFT_24 | BO1: SX SRE_PREMIUM_SHIFT_25 | BP1: SX SRE_PREMIUM_SHIFT_26 | BQ1: SX SRE_PREMIUM_SHIFT_27 | BR1: SX SRE_PREMIUM_SHIFT_28 | BS1: SX SRE_PREMIUM_SHIFT_29 | BT1: SX SRE_PREMIUM_SHIFT_30 | BU1: SX SRE_SEPARATE_LEG_SL_1 | BV1: SX SRE_SEPARATE_LEG_SL_2 | BW1: SX SRE_SEPARATE_LEG_SL_3
A2: 45292 | B2: 15:29:00 | C2: 0 | D2: 0 | E2: 0 | F2: 0 | G2: 0 | H2: 0 | I2: 0 | J2: 0 | K2: 0 | L2: 0 | M2: 0 | N2: 0 | O2: 0 | P2: 0 | Q2: 0 | R2: 0 | S2: 0 | T2: 0 | U2: 0 | V2: 0 | W2: 0 | X2: 0 | Y2: 0 | Z2: 0 | AA2: 0 | AB2: 0 | AC2: 0 | AD2: 0 | AE2: 0 | AF2: 0 | AG2: 0 | AH2: 0 | AI2: 0 | AJ2: 0 | AK2: 0 | AL2: 0 | AM2: 15:29:00 | AN2: 0 | AO2: 0 | AP2: 0 | AQ2: 0 | AR2: 0 | AS2: 0 | AT2: 0 | AU2: 0 | AV2: 0 | AW2: 0 | AX2: 0 | AY2: 0 | AZ2: 0 | BA2: 0 | BB2: 0 | BC2: 0 | BD2: 0 | BE2: 0 | BF2: 0 | BG2: 0 | BH2: 0 | BI2: 0 | BJ2: 0 | BK2: 0 | BL2: 0 | BM2: 0 | BN2: 0 | BO2: 0 | BP2: 0 | BQ2: 0 | BR2: 0 | BS2: 0 | BT2: 0 | BU2: 0 | BV2: 0 | BW2: 0
A3: 45293 | B3: 15:29:00 | C3: 15:29:00 | D3: 15:29:00 | E3: 15:29:00 | F3: 0 | G3: 0 | H3: 0 | I3: 0 | J3: 0 | K3: 0 | L3: 0 | M3: 0 | N3: 0 | O3: 0 | P3: 0 | Q3: 0 | R3: 0 | S3: 0 | T3: 0 | U3: 0 | V3: 0 | W3: 0 | X3: 0 | Y3: 0 | Z3: 0 | AA3: 0 | AB3: 0 | AC3: 0 | AD3: 0 | AE3: 0 | AF3: 0 | AG3: 0 | AH3: 0 | AI3: 0 | AJ3: 10:36:00 | AK3: 10:36:00 | AL3: 10:38:00 | AM3: 15:29:00 | AN3: 0 | AO3: 0 | AP3: 0 | AQ3: 0 | AR3: 0 | AS3: 0 | AT3: 0 | AU3: 0 | AV3: 0 | AW3: 0 | AX3: 0 | AY3: 0 | AZ3: 0 | BA3: 0 | BB3: 0 | BC3: 0 | BD3: 0 | BE3: 0 | BF3: 0 | BG3: 0 | BH3: 0 | BI3: 0 | BJ3: 0 | BK3: 0 | BL3: 0 | BM3: 0 | BN3: 0 | BO3: 0 | BP3: 0 | BQ3: 0 | BR3: 0 | BS3: 0 | BT3: 0 | BU3: 0 | BV3: 0 | BW3: 0
A4: 45294 | B4: 15:29:00 | C4: 15:29:00 | D4: 15:29:00 | E4: 15:29:00 | F4: 0 | G4: 0 | H4: 0 | I4: 0 | J4: 0 | K4: 0 | L4: 0 | M4: 0 | N4: 0 | O4: 0 | P4: 0 | Q4: 0 | R4: 0 | S4: 0 | T4: 0 | U4: 0 | V4: 0 | W4: 0 | X4: 0 | Y4: 0 | Z4: 0 | AA4: 0 | AB4: 0 | AC4: 0 | AD4: 0 | AE4: 0 | AF4: 0 | AG4: 0 | AH4: 0 | AI4: 0 | AJ4: 15:29:00 | AK4: 15:29:00 | AL4: 15:29:00 | AM4: 15:29:00 | AN4: 0 | AO4: 0 | AP4: 0 | AQ4: 0 | AR4: 0 | AS4: 0 | AT4: 0 | AU4: 0 | AV4: 0 | AW4: 0 | AX4: 0 | AY4: 0 | AZ4: 0 | BA4: 0 | BB4: 0 | BC4: 0 | BD4: 0 | BE4: 0 | BF4: 0 | BG4: 0 | BH4: 0 | BI4: 0 | BJ4: 0 | BK4: 0 | BL4: 0 | BM4: 0 | BN4: 0 | BO4: 0 | BP4: 0 | BQ4: 0 | BR4: 0 | BS4: 0 | BT4: 0 | BU4: 0 | BV4: 0 | BW4: 0
A5: 45295 | B5: 15:29:00 | C5: 15:29:00 | D5: 15:29:00 | E5: 15:29:00 | F5: 15:29:00 | G5: 15:29:00 | H5: 15:29:00 | I5: 15:29:00 | J5: 15:29:00 | K5: 15:29:00 | L5: 15:29:00 | M5: 15:29:00 | N5: 15:29:00 | O5: 15:29:00 | P5: 15:29:00 | Q5: 15:29:00 | R5: 15:29:00 | S5: 15:29:00 | T5: 15:29:00 | U5: 15:29:00 | V5: 15:29:00 | W5: 15:29:00 | X5: 15:29:00 | Y5: 15:29:00 | Z5: 15:29:00 | AA5: 15:29:00 | AB5: 15:29:00 | AC5: 15:29:00 | AD5: 15:29:00 | AE5: 15:29:00 | AF5: 15:29:00 | AG5: 15:29:00 | AH5: 15:29:00 | AI5: 15:29:00 | AJ5: 0 | AK5: 0 | AL5: 0 | AM5: 15:29:00 | AN5: 15:29:00 | AO5: 15:29:00 | AP5: 15:29:00 | AQ5: 0 | AR5: 0 | AS5: 0 | AT5: 0 | AU5: 0 | AV5: 0 | AW5: 0 | AX5: 0 | AY5: 0 | AZ5: 0 | BA5: 0 | BB5: 0 | BC5: 0 | BD5: 0 | BE5: 0 | BF5: 0 | BG5: 0 | BH5: 0 | BI5: 0 | BJ5: 0 | BK5: 0 | BL5: 0 | BM5: 0 | BN5: 0 | BO5: 0 | BP5: 0 | BQ5: 0 | BR5: 0 | BS5: 0 | BT5: 0 | BU5: 15:29:00 | BV5: 15:29:00 | BW5: 15:29:00
A6: 45296 | B6: 15:29:00 | C6: 0 | D6: 0 | E6: 0 | F6: 0 | G6: 0 | H6: 0 | I6: 0 | J6: 0 | K6: 0 | L6: 0 | M6: 0 | N6: 0 | O6: 0 | P6: 0 | Q6: 0 | R6: 0 | S6: 0 | T6: 0 | U6: 0 | V6: 0 | W6: 0 | X6: 0 | Y6: 0 | Z6: 0 | AA6: 0 | AB6: 0 | AC6: 0 | AD6: 0 | AE6: 0 | AF6: 0 | AG6: 0 | AH6: 0 | AI6: 0 | AJ6: 0 | AK6: 0 | AL6: 0 | AM6: 15:29:00 | AN6: 15:29:00 | AO6: 15:29:00 | AP6: 15:29:00 | AQ6: 15:29:00 | AR6: 15:29:00 | AS6: 15:29:00 | AT6: 15:29:00 | AU6: 15:29:00 | AV6: 15:29:00 | AW6: 15:29:00 | AX6: 15:29:00 | AY6: 15:29:00 | AZ6: 15:29:00 | BA6: 15:29:00 | BB6: 15:29:00 | BC6: 15:29:00 | BD6: 15:29:00 | BE6: 15:29:00 | BF6: 15:29:00 | BG6: 15:29:00 | BH6: 15:29:00 | BI6: 15:29:00 | BJ6: 15:29:00 | BK6: 15:29:00 | BL6: 15:29:00 | BM6: 15:29:00 | BN6: 15:29:00 | BO6: 15:29:00 | BP6: 15:29:00 | BQ6: 15:29:00 | BR6: 15:29:00 | BS6: 15:29:00 | BT6: 15:29:00 | BU6: 0 | BV6: 0 | BW6: 0
A7: 45299 | B7: 15:29:00 | C7: 0 | D7: 0 | E7: 0 | F7: 0 | G7: 0 | H7: 0 | I7: 0 | J7: 0 | K7: 0 | L7: 0 | M7: 0 | N7: 0 | O7: 0 | P7: 0 | Q7: 0 | R7: 0 | S7: 0 | T7: 0 | U7: 0 | V7: 0 | W7: 0 | X7: 0 | Y7: 0 | Z7: 0 | AA7: 0 | AB7: 0 | AC7: 0 | AD7: 0 | AE7: 0 | AF7: 0 | AG7: 0 | AH7: 0 | AI7: 0 | AJ7: 0 | AK7: 0 | AL7: 0 | AM7: 15:29:00 | AN7: 0 | AO7: 0 | AP7: 0 | AQ7: 0 | AR7: 0 | AS7: 0 | AT7: 0 | AU7: 0 | AV7: 0 | AW7: 0 | AX7: 0 | AY7: 0 | AZ7: 0 | BA7: 0 | BB7: 0 | BC7: 0 | BD7: 0 | BE7: 0 | BF7: 0 | BG7: 0 | BH7: 0 | BI7: 0 | BJ7: 0 | BK7: 0 | BL7: 0 | BM7: 0 | BN7: 0 | BO7: 0 | BP7: 0 | BQ7: 0 | BR7: 0 | BS7: 0 | BT7: 0 | BU7: 0 | BV7: 0 | BW7: 0
A8: 45300 | B8: 15:29:00 | C8: 15:29:00 | D8: 15:29:00 | E8: 15:29:00 | F8: 0 | G8: 0 | H8: 0 | I8: 0 | J8: 0 | K8: 0 | L8: 0 | M8: 0 | N8: 0 | O8: 0 | P8: 0 | Q8: 0 | R8: 0 | S8: 0 | T8: 0 | U8: 0 | V8: 0 | W8: 0 | X8: 0 | Y8: 0 | Z8: 0 | AA8: 0 | AB8: 0 | AC8: 0 | AD8: 0 | AE8: 0 | AF8: 0 | AG8: 0 | AH8: 0 | AI8: 0 | AJ8: 15:29:00 | AK8: 15:29:00 | AL8: 15:29:00 | AM8: 15:29:00 | AN8: 0 | AO8: 0 | AP8: 0 | AQ8: 0 | AR8: 0 | AS8: 0 | AT8: 0 | AU8: 0 | AV8: 0 | AW8: 0 | AX8: 0 | AY8: 0 | AZ8: 0 | BA8: 0 | BB8: 0 | BC8: 0 | BD8: 0 | BE8: 0 | BF8: 0 | BG8: 0 | BH8: 0 | BI8: 0 | BJ8: 0 | BK8: 0 | BL8: 0 | BM8: 0 | BN8: 0 | BO8: 0 | BP8: 0 | BQ8: 0 | BR8: 0 | BS8: 0 | BT8: 0 | BU8: 0 | BV8: 0 | BW8: 0
A9: 45301 | B9: 15:29:00 | C9: 15:29:00 | D9: 15:29:00 | E9: 15:29:00 | F9: 0 | G9: 0 | H9: 0 | I9: 0 | J9: 0 | K9: 0 | L9: 0 | M9: 0 | N9: 0 | O9: 0 | P9: 0 | Q9: 0 | R9: 0 | S9: 0 | T9: 0 | U9: 0 | V9: 0 | W9: 0 | X9: 0 | Y9: 0 | Z9: 0 | AA9: 0 | AB9: 0 | AC9: 0 | AD9: 0 | AE9: 0 | AF9: 0 | AG9: 0 | AH9: 0 | AI9: 0 | AJ9: 15:29:00 | AK9: 15:29:00 | AL9: 15:29:00 | AM9: 15:29:00 | AN9: 0 | AO9: 0 | AP9: 0 | AQ9: 0 | AR9: 0 | AS9: 0 | AT9: 0 | AU9: 0 | AV9: 0 | AW9: 0 | AX9: 0 | AY9: 0 | AZ9: 0 | BA9: 0 | BB9: 0 | BC9: 0 | BD9: 0 | BE9: 0 | BF9: 0 | BG9: 0 | BH9: 0 | BI9: 0 | BJ9: 0 | BK9: 0 | BL9: 0 | BM9: 0 | BN9: 0 | BO9: 0 | BP9: 0 | BQ9: 0 | BR9: 0 | BS9: 0 | BT9: 0 | BU9: 0 | BV9: 0 | BW9: 0
A10: 45302 | B10: 15:29:00 | C10: 15:29:00 | D10: 15:29:00 | E10: 15:29:00 | F10: 15:29:00 | G10: 15:29:00 | H10: 15:29:00 | I10: 15:29:00 | J10: 15:29:00 | K10: 15:29:00 | L10: 15:29:00 | M10: 15:29:00 | N10: 15:29:00 | O10: 15:29:00 | P10: 15:29:00 | Q10: 15:29:00 | R10: 15:29:00 | S10: 15:29:00 | T10: 15:29:00 | U10: 15:29:00 | V10: 15:29:00 | W10: 15:29:00 | X10: 15:29:00 | Y10: 15:29:00 | Z10: 15:29:00 | AA10: 15:29:00 | AB10: 15:29:00 | AC10: 15:29:00 | AD10: 15:29:00 | AE10: 15:29:00 | AF10: 15:29:00 | AG10: 15:29:00 | AH10: 15:29:00 | AI10: 15:29:00 | AJ10: 0 | AK10: 0 | AL10: 0 | AM10: 15:29:00 | AN10: 15:29:00 | AO10: 15:29:00 | AP10: 15:29:00 | AQ10: 0 | AR10: 0 | AS10: 0 | AT10: 0 | AU10: 0 | AV10: 0 | AW10: 0 | AX10: 0 | AY10: 0 | AZ10: 0 | BA10: 0 | BB10: 0 | BC10: 0 | BD10: 0 | BE10: 0 | BF10: 0 | BG10: 0 | BH10: 0 | BI10: 0 | BJ10: 0 | BK10: 0 | BL10: 0 | BM10: 0 | BN10: 0 | BO10: 0 | BP10: 0 | BQ10: 0 | BR10: 0 | BS10: 0 | BT10: 0 | BU10: 15:29:00 | BV10: 15:29:00 | BW10: 15:29:00
A11: 45303 | B11: 15:29:00 | C11: 0 | D11: 0 | E11: 0 | F11: 0 | G11: 0 | H11: 0 | I11: 0 | J11: 0 | K11: 0 | L11: 0 | M11: 0 | N11: 0 | O11: 0 | P11: 0 | Q11: 0 | R11: 0 | S11: 0 | T11: 0 | U11: 0 | V11: 0 | W11: 0 | X11: 0 | Y11: 0 | Z11: 0 | AA11: 0 | AB11: 0 | AC11: 0 | AD11: 0 | AE11: 0 | AF11: 0 | AG11: 0 | AH11: 0 | AI11: 0 | AJ11: 0 | AK11: 0 | AL11: 0 | AM11: 15:29:00 | AN11: 15:29:00 | AO11: 15:29:00 | AP11: 15:29:00 | AQ11: 10:07:00 | AR11: 10:07:00 | AS11: 10:07:00 | AT11: 10:07:00 | AU11: 10:07:00 | AV11: 10:07:00 | AW11: 15:29:00 | AX11: 10:07:00 | AY11: 10:07:00 | AZ11: 10:07:00 | BA11: 10:07:00 | BB11: 10:07:00 | BC11: 10:07:00 | BD11: 10:07:00 | BE11: 10:07:00 | BF11: 10:07:00 | BG11: 15:29:00 | BH11: 10:07:00 | BI11: 10:07:00 | BJ11: 10:07:00 | BK11: 10:07:00 | BL11: 15:29:00 | BM11: 15:29:00 | BN11: 15:29:00 | BO11: 15:29:00 | BP11: 15:29:00 | BQ11: 15:29:00 | BR11: 15:29:00 | BS11: 10:58:00 | BT11: 15:29:00 | BU11: 0 | BV11: 0 | BW11: 0
A12: 45306 | B12: 15:29:00 | C12: 0 | D12: 0 | E12: 0 | F12: 0 | G12: 0 | H12: 0 | I12: 0 | J12: 0 | K12: 0 | L12: 0 | M12: 0 | N12: 0 | O12: 0 | P12: 0 | Q12: 0 | R12: 0 | S12: 0 | T12: 0 | U12: 0 | V12: 0 | W12: 0 | X12: 0 | Y12: 0 | Z12: 0 | AA12: 0 | AB12: 0 | AC12: 0 | AD12: 0 | AE12: 0 | AF12: 0 | AG12: 0 | AH12: 0 | AI12: 0 | AJ12: 0 | AK12: 0 | AL12: 0 | AM12: 15:29:00 | AN12: 0 | AO12: 0 | AP12: 0 | AQ12: 0 | AR12: 0 | AS12: 0 | AT12: 0 | AU12: 0 | AV12: 0 | AW12: 0 | AX12: 0 | AY12: 0 | AZ12: 0 | BA12: 0 | BB12: 0 | BC12: 0 | BD12: 0 | BE12: 0 | BF12: 0 | BG12: 0 | BH12: 0 | BI12: 0 | BJ12: 0 | BK12: 0 | BL12: 0 | BM12: 0 | BN12: 0 | BO12: 0 | BP12: 0 | BQ12: 0 | BR12: 0 | BS12: 0 | BT12: 0 | BU12: 0 | BV12: 0 | BW12: 0
A13: 45307 | B13: 15:29:00 | C13: 15:29:00 | D13: 15:29:00 | E13: 15:29:00 | F13: 0 | G13: 0 | H13: 0 | I13: 0 | J13: 0 | K13: 0 | L13: 0 | M13: 0 | N13: 0 | O13: 0 | P13: 0 | Q13: 0 | R13: 0 | S13: 0 | T13: 0 | U13: 0 | V13: 0 | W13: 0 | X13: 0 | Y13: 0 | Z13: 0 | AA13: 0 | AB13: 0 | AC13: 0 | AD13: 0 | AE13: 0 | AF13: 0 | AG13: 0 | AH13: 0 | AI13: 0 | AJ13: 15:29:00 | AK13: 15:29:00 | AL13: 15:29:00 | AM13: 15:29:00 | AN13: 0 | AO13: 0 | AP13: 0 | AQ13: 0 | AR13: 0 | AS13: 0 | AT13: 0 | AU13: 0 | AV13: 0 | AW13: 0 | AX13: 0 | AY13: 0 | AZ13: 0 | BA13: 0 | BB13: 0 | BC13: 0 | BD13: 0 | BE13: 0 | BF13: 0 | BG13: 0 | BH13: 0 | BI13: 0 | BJ13: 0 | BK13: 0 | BL13: 0 | BM13: 0 | BN13: 0 | BO13: 0 | BP13: 0 | BQ13: 0 | BR13: 0 | BS13: 0 | BT13: 0 | BU13: 0 | BV13: 0 | BW13: 0
A14: 45308 | B14: 15:29:00 | C14: 15:29:00 | D14: 15:29:00 | E14: 15:29:00 | F14: 0 | G14: 0 | H14: 0 | I14: 0 | J14: 0 | K14: 0 | L14: 0 | M14: 0 | N14: 0 | O14: 0 | P14: 0 | Q14: 0 | R14: 0 | S14: 0 | T14: 0 | U14: 0 | V14: 0 | W14: 0 | X14: 0 | Y14: 0 | Z14: 0 | AA14: 0 | AB14: 0 | AC14: 0 | AD14: 0 | AE14: 0 | AF14: 0 | AG14: 0 | AH14: 0 | AI14: 0 | AJ14: 15:29:00 | AK14: 12:03:00 | AL14: 12:05:00 | AM14: 15:29:00 | AN14: 0 | AO14: 0 | AP14: 0 | AQ14: 0 | AR14: 0 | AS14: 0 | AT14: 0 | AU14: 0 | AV14: 0 | AW14: 0 | AX14: 0 | AY14: 0 | AZ14: 0 | BA14: 0 | BB14: 0 | BC14: 0 | BD14: 0 | BE14: 0 | BF14: 0 | BG14: 0 | BH14: 0 | BI14: 0 | BJ14: 0 | BK14: 0 | BL14: 0 | BM14: 0 | BN14: 0 | BO14: 0 | BP14: 0 | BQ14: 0 | BR14: 0 | BS14: 0 | BT14: 0 | BU14: 0 | BV14: 0 | BW14: 0
A15: 45309 | B15: 15:29:00 | C15: 15:29:00 | D15: 15:29:00 | E15: 15:29:00 | F15: 10:08:00 | G15: 15:29:00 | H15: 15:29:00 | I15: 15:29:00 | J15: 10:08:00 | K15: 10:08:00 | L15: 10:08:00 | M15: 15:29:00 | N15: 15:29:00 | O15: 15:29:00 | P15: 10:08:00 | Q15: 15:29:00 | R15: 15:29:00 | S15: 15:29:00 | T15: 10:08:00 | U15: 10:08:00 | V15: 10:08:00 | W15: 15:29:00 | X15: 15:29:00 | Y15: 15:29:00 | Z15: 15:29:00 | AA15: 15:29:00 | AB15: 15:29:00 | AC15: 15:29:00 | AD15: 15:29:00 | AE15: 15:29:00 | AF15: 15:29:00 | AG15: 10:09:00 | AH15: 10:09:00 | AI15: 15:29:00 | AJ15: 0 | AK15: 0 | AL15: 0 | AM15: 15:29:00 | AN15: 15:29:00 | AO15: 15:29:00 | AP15: 15:29:00 | AQ15: 0 | AR15: 0 | AS15: 0 | AT15: 0 | AU15: 0 | AV15: 0 | AW15: 0 | AX15: 0 | AY15: 0 | AZ15: 0 | BA15: 0 | BB15: 0 | BC15: 0 | BD15: 0 | BE15: 0 | BF15: 0 | BG15: 0 | BH15: 0 | BI15: 0 | BJ15: 0 | BK15: 0 | BL15: 0 | BM15: 0 | BN15: 0 | BO15: 0 | BP15: 0 | BQ15: 0 | BR15: 0 | BS15: 0 | BT15: 0 | BU15: 15:29:00 | BV15: 15:29:00 | BW15: 15:29:00
A16: 45310 | B16: 15:29:00 | C16: 0 | D16: 0 | E16: 0 | F16: 0 | G16: 0 | H16: 0 | I16: 0 | J16: 0 | K16: 0 | L16: 0 | M16: 0 | N16: 0 | O16: 0 | P16: 0 | Q16: 0 | R16: 0 | S16: 0 | T16: 0 | U16: 0 | V16: 0 | W16: 0 | X16: 0 | Y16: 0 | Z16: 0 | AA16: 0 | AB16: 0 | AC16: 0 | AD16: 0 | AE16: 0 | AF16: 0 | AG16: 0 | AH16: 0 | AI16: 0 | AJ16: 0 | AK16: 0 | AL16: 0 | AM16: 15:29:00 | AN16: 15:29:00 | AO16: 15:29:00 | AP16: 15:29:00 | AQ16: 15:29:00 | AR16: 15:29:00 | AS16: 15:29:00 | AT16: 15:29:00 | AU16: 15:29:00 | AV16: 15:29:00 | AW16: 15:29:00 | AX16: 15:29:00 | AY16: 15:29:00 | AZ16: 15:29:00 | BA16: 15:29:00 | BB16: 15:29:00 | BC16: 15:29:00 | BD16: 15:29:00 | BE16: 15:29:00 | BF16: 15:29:00 | BG16: 15:29:00 | BH16: 15:29:00 | BI16: 15:29:00 | BJ16: 15:29:00 | BK16: 15:29:00 | BL16: 15:29:00 | BM16: 15:29:00 | BN16: 15:29:00 | BO16: 15:29:00 | BP16: 15:29:00 | BQ16: 15:29:00 | BR16: 15:29:00 | BS16: 15:29:00 | BT16: 15:29:00 | BU16: 0 | BV16: 0 | BW16: 0
A17: 45311 | B17: 15:29:00 | C17: 0 | D17: 0 | E17: 0 | F17: 0 | G17: 0 | H17: 0 | I17: 0 | J17: 0 | K17: 0 | L17: 0 | M17: 0 | N17: 0 | O17: 0 | P17: 0 | Q17: 0 | R17: 0 | S17: 0 | T17: 0 | U17: 0 | V17: 0 | W17: 0 | X17: 0 | Y17: 0 | Z17: 0 | AA17: 0 | AB17: 0 | AC17: 0 | AD17: 0 | AE17: 0 | AF17: 0 | AG17: 0 | AH17: 0 | AI17: 0 | AJ17: 0 | AK17: 0 | AL17: 0 | AM17: 15:29:00 | AN17: 0 | AO17: 0 | AP17: 0 | AQ17: 0 | AR17: 0 | AS17: 0 | AT17: 0 | AU17: 0 | AV17: 0 | AW17: 0 | AX17: 0 | AY17: 0 | AZ17: 0 | BA17: 0 | BB17: 0 | BC17: 0 | BD17: 0 | BE17: 0 | BF17: 0 | BG17: 0 | BH17: 0 | BI17: 0 | BJ17: 0 | BK17: 0 | BL17: 0 | BM17: 0 | BN17: 0 | BO17: 0 | BP17: 0 | BQ17: 0 | BR17: 0 | BS17: 0 | BT17: 0 | BU17: 0 | BV17: 0 | BW17: 0
A18: 45314 | B18: 15:29:00 | C18: 15:29:00 | D18: 15:29:00 | E18: 15:29:00 | F18: 0 | G18: 0 | H18: 0 | I18: 0 | J18: 0 | K18: 0 | L18: 0 | M18: 0 | N18: 0 | O18: 0 | P18: 0 | Q18: 0 | R18: 0 | S18: 0 | T18: 0 | U18: 0 | V18: 0 | W18: 0 | X18: 0 | Y18: 0 | Z18: 0 | AA18: 0 | AB18: 0 | AC18: 0 | AD18: 0 | AE18: 0 | AF18: 0 | AG18: 0 | AH18: 0 | AI18: 0 | AJ18: 10:27:00 | AK18: 10:27:00 | AL18: 10:38:00 | AM18: 15:29:00 | AN18: 0 | AO18: 0 | AP18: 0 | AQ18: 0 | AR18: 0 | AS18: 0 | AT18: 0 | AU18: 0 | AV18: 0 | AW18: 0 | AX18: 0 | AY18: 0 | AZ18: 0 | BA18: 0 | BB18: 0 | BC18: 0 | BD18: 0 | BE18: 0 | BF18: 0 | BG18: 0 | BH18: 0 | BI18: 0 | BJ18: 0 | BK18: 0 | BL18: 0 | BM18: 0 | BN18: 0 | BO18: 0 | BP18: 0 | BQ18: 0 | BR18: 0 | BS18: 0 | BT18: 0 | BU18: 0 | BV18: 0 | BW18: 0
A19: 45315 | B19: 15:29:00 | C19: 15:29:00 | D19: 15:29:00 | E19: 15:29:00 | F19: 0 | G19: 0 | H19: 0 | I19: 0 | J19: 0 | K19: 0 | L19: 0 | M19: 0 | N19: 0 | O19: 0 | P19: 0 | Q19: 0 | R19: 0 | S19: 0 | T19: 0 | U19: 0 | V19: 0 | W19: 0 | X19: 0 | Y19: 0 | Z19: 0 | AA19: 0 | AB19: 0 | AC19: 0 | AD19: 0 | AE19: 0 | AF19: 0 | AG19: 0 | AH19: 0 | AI19: 0 | AJ19: 15:29:00 | AK19: 09:58:00 | AL19: 15:29:00 | AM19: 15:29:00 | AN19: 15:29:00 | AO19: 15:29:00 | AP19: 15:29:00 | AQ19: 0 | AR19: 0 | AS19: 0 | AT19: 0 | AU19: 0 | AV19: 0 | AW19: 0 | AX19: 0 | AY19: 0 | AZ19: 0 | BA19: 0 | BB19: 0 | BC19: 0 | BD19: 0 | BE19: 0 | BF19: 0 | BG19: 0 | BH19: 0 | BI19: 0 | BJ19: 0 | BK19: 0 | BL19: 0 | BM19: 0 | BN19: 0 | BO19: 0 | BP19: 0 | BQ19: 0 | BR19: 0 | BS19: 0 | BT19: 0 | BU19: 15:29:00 | BV19: 10:00:00 | BW19: 15:29:00
A20: 45316 | B20: 15:29:00 | C20: 15:29:00 | D20: 15:29:00 | E20: 15:29:00 | F20: 10:55:00 | G20: 10:59:00 | H20: 15:29:00 | I20: 15:29:00 | J20: 15:29:00 | K20: 15:29:00 | L20: 10:23:00 | M20: 10:22:00 | N20: 15:29:00 | O20: 15:29:00 | P20: 10:55:00 | Q20: 10:59:00 | R20: 15:29:00 | S20: 15:29:00 | T20: 15:29:00 | U20: 15:29:00 | V20: 10:23:00 | W20: 10:22:00 | X20: 15:29:00 | Y20: 15:29:00 | Z20: 15:29:00 | AA20: 15:29:00 | AB20: 15:29:00 | AC20: 15:29:00 | AD20: 15:29:00 | AE20: 15:29:00 | AF20: 15:29:00 | AG20: 15:29:00 | AH20: 15:29:00 | AI20: 15:29:00 | AJ20: 0 | AK20: 0 | AL20: 0 | AM20: 15:29:00 | AN20: 15:29:00 | AO20: 15:29:00 | AP20: 15:29:00 | AQ20: 10:20:00 | AR20: 10:19:00 | AS20: 10:21:00 | AT20: 10:20:00 | AU20: 15:29:00 | AV20: 15:29:00 | AW20: 10:20:00 | AX20: 10:19:00 | AY20: 10:20:00 | AZ20: 10:20:00 | BA20: 10:20:00 | BB20: 10:19:00 | BC20: 10:20:00 | BD20: 10:20:00 | BE20: 15:29:00 | BF20: 15:29:00 | BG20: 10:21:00 | BH20: 10:19:00 | BI20: 10:20:00 | BJ20: 10:20:00 | BK20: 11:39:00 | BL20: 10:57:00 | BM20: 11:40:00 | BN20: 10:21:00 | BO20: 15:29:00 | BP20: 15:29:00 | BQ20: 11:50:00 | BR20: 10:21:00 | BS20: 10:21:00 | BT20: 10:21:00 | BU20: 0 | BV20: 0 | BW20: 0
A21: 45320 | B21: 15:29:00 | C21: 0 | D21: 0 | E21: 0 | F21: 0 | G21: 0 | H21: 0 | I21: 0 | J21: 0 | K21: 0 | L21: 0 | M21: 0 | N21: 0 | O21: 0 | P21: 0 | Q21: 0 | R21: 0 | S21: 0 | T21: 0 | U21: 0 | V21: 0 | W21: 0 | X21: 0 | Y21: 0 | Z21: 0 | AA21: 0 | AB21: 0 | AC21: 0 | AD21: 0 | AE21: 0 | AF21: 0 | AG21: 0 | AH21: 0 | AI21: 0 | AJ21: 0 | AK21: 0 | AL21: 0 | AM21: 15:29:00 | AN21: 0 | AO21: 0 | AP21: 0 | AQ21: 0 | AR21: 0 | AS21: 0 | AT21: 0 | AU21: 0 | AV21: 0 | AW21: 0 | AX21: 0 | AY21: 0 | AZ21: 0 | BA21: 0 | BB21: 0 | BC21: 0 | BD21: 0 | BE21: 0 | BF21: 0 | BG21: 0 | BH21: 0 | BI21: 0 | BJ21: 0 | BK21: 0 | BL21: 0 | BM21: 0 | BN21: 0 | BO21: 0 | BP21: 0 | BQ21: 0 | BR21: 0 | BS21: 0 | BT21: 0 | BU21: 0 | BV21: 0 | BW21: 0
A22: 45321 | B22: 15:29:00 | C22: 15:29:00 | D22: 15:29:00 | E22: 15:29:00 | F22: 0 | G22: 0 | H22: 0 | I22: 0 | J22: 0 | K22: 0 | L22: 0 | M22: 0 | N22: 0 | O22: 0 | P22: 0 | Q22: 0 | R22: 0 | S22: 0 | T22: 0 | U22: 0 | V22: 0 | W22: 0 | X22: 0 | Y22: 0 | Z22: 0 | AA22: 0 | AB22: 0 | AC22: 0 | AD22: 0 | AE22: 0 | AF22: 0 | AG22: 0 | AH22: 0 | AI22: 0 | AJ22: 15:29:00 | AK22: 15:29:00 | AL22: 15:29:00 | AM22: 15:29:00 | AN22: 0 | AO22: 0 | AP22: 0 | AQ22: 0 | AR22: 0 | AS22: 0 | AT22: 0 | AU22: 0 | AV22: 0 | AW22: 0 | AX22: 0 | AY22: 0 | AZ22: 0 | BA22: 0 | BB22: 0 | BC22: 0 | BD22: 0 | BE22: 0 | BF22: 0 | BG22: 0 | BH22: 0 | BI22: 0 | BJ22: 0 | BK22: 0 | BL22: 0 | BM22: 0 | BN22: 0 | BO22: 0 | BP22: 0 | BQ22: 0 | BR22: 0 | BS22: 0 | BT22: 0 | BU22: 0 | BV22: 0 | BW22: 0
A23: 45322 | B23: 15:29:00 | C23: 15:29:00 | D23: 15:29:00 | E23: 15:29:00 | F23: 0 | G23: 0 | H23: 0 | I23: 0 | J23: 0 | K23: 0 | L23: 0 | M23: 0 | N23: 0 | O23: 0 | P23: 0 | Q23: 0 | R23: 0 | S23: 0 | T23: 0 | U23: 0 | V23: 0 | W23: 0 | X23: 0 | Y23: 0 | Z23: 0 | AA23: 0 | AB23: 0 | AC23: 0 | AD23: 0 | AE23: 0 | AF23: 0 | AG23: 0 | AH23: 0 | AI23: 0 | AJ23: 15:29:00 | AK23: 15:29:00 | AL23: 15:29:00 | AM23: 15:29:00 | AN23: 0 | AO23: 0 | AP23: 0 | AQ23: 0 | AR23: 0 | AS23: 0 | AT23: 0 | AU23: 0 | AV23: 0 | AW23: 0 | AX23: 0 | AY23: 0 | AZ23: 0 | BA23: 0 | BB23: 0 | BC23: 0 | BD23: 0 | BE23: 0 | BF23: 0 | BG23: 0 | BH23: 0 | BI23: 0 | BJ23: 0 | BK23: 0 | BL23: 0 | BM23: 0 | BN23: 0 | BO23: 0 | BP23: 0 | BQ23: 0 | BR23: 0 | BS23: 0 | BT23: 0 | BU23: 0 | BV23: 0 | BW23: 0
A24: 45323 | B24: 15:29:00 | C24: 15:29:00 | D24: 15:29:00 | E24: 15:29:00 | F24: 15:29:00 | G24: 14:24:00 | H24: 14:30:00 | I24: 15:00:00 | J24: 15:29:00 | K24: 15:29:00 | L24: 15:29:00 | M24: 15:29:00 | N24: 15:29:00 | O24: 15:29:00 | P24: 15:29:00 | Q24: 15:29:00 | R24: 15:29:00 | S24: 15:29:00 | T24: 15:29:00 | U24: 15:29:00 | V24: 15:29:00 | W24: 15:29:00 | X24: 15:29:00 | Y24: 15:29:00 | Z24: 15:29:00 | AA24: 15:29:00 | AB24: 15:29:00 | AC24: 15:29:00 | AD24: 15:29:00 | AE24: 15:29:00 | AF24: 15:29:00 | AG24: 15:29:00 | AH24: 11:18:00 | AI24: 11:16:00 | AJ24: 0 | AK24: 0 | AL24: 0 | AM24: 13:42:00 | AN24: 15:29:00 | AO24: 15:29:00 | AP24: 15:29:00 | AQ24: 0 | AR24: 0 | AS24: 0 | AT24: 0 | AU24: 0 | AV24: 0 | AW24: 0 | AX24: 0 | AY24: 0 | AZ24: 0 | BA24: 0 | BB24: 0 | BC24: 0 | BD24: 0 | BE24: 0 | BF24: 0 | BG24: 0 | BH24: 0 | BI24: 0 | BJ24: 0 | BK24: 0 | BL24: 0 | BM24: 0 | BN24: 0 | BO24: 0 | BP24: 0 | BQ24: 0 | BR24: 0 | BS24: 0 | BT24: 0 | BU24: 15:29:00 | BV24: 15:29:00 | BW24: 15:29:00
A25: 45324 | B25: 15:29:00 | C25: 0 | D25: 0 | E25: 0 | F25: 0 | G25: 0 | H25: 0 | I25: 0 | J25: 0 | K25: 0 | L25: 0 | M25: 0 | N25: 0 | O25: 0 | P25: 0 | Q25: 0 | R25: 0 | S25: 0 | T25: 0 | U25: 0 | V25: 0 | W25: 0 | X25: 0 | Y25: 0 | Z25: 0 | AA25: 0 | AB25: 0 | AC25: 0 | AD25: 0 | AE25: 0 | AF25: 0 | AG25: 0 | AH25: 0 | AI25: 0 | AJ25: 0 | AK25: 0 | AL25: 0 | AM25: 15:29:00 | AN25: 12:33:00 | AO25: 12:29:00 | AP25: 12:27:00 | AQ25: 09:20:00 | AR25: 11:13:00 | AS25: 11:14:00 | AT25: 11:14:00 | AU25: 11:40:00 | AV25: 11:31:00 | AW25: 11:31:00 | AX25: 11:31:00 | AY25: 11:14:00 | AZ25: 11:13:00 | BA25: 11:13:00 | BB25: 11:14:00 | BC25: 11:40:00 | BD25: 11:31:00 | BE25: 11:40:00 | BF25: 11:40:00 | BG25: 11:31:00 | BH25: 11:31:00 | BI25: 11:31:00 | BJ25: 15:29:00 | BK25: 15:29:00 | BL25: 11:14:00 | BM25: 11:40:00 | BN25: 11:40:00 | BO25: 11:31:00 | BP25: 11:31:00 | BQ25: 11:31:00 | BR25: 11:31:00 | BS25: 11:31:00 | BT25: 11:13:00 | BU25: 0 | BV25: 0 | BW25: 0
A26: 45327 | B26: 15:29:00 | C26: 0 | D26: 0 | E26: 0 | F26: 0 | G26: 0 | H26: 0 | I26: 0 | J26: 0 | K26: 0 | L26: 0 | M26: 0 | N26: 0 | O26: 0 | P26: 0 | Q26: 0 | R26: 0 | S26: 0 | T26: 0 | U26: 0 | V26: 0 | W26: 0 | X26: 0 | Y26: 0 | Z26: 0 | AA26: 0 | AB26: 0 | AC26: 0 | AD26: 0 | AE26: 0 | AF26: 0 | AG26: 0 | AH26: 0 | AI26: 0 | AJ26: 0 | AK26: 0 | AL26: 0 | AM26: 15:29:00 | AN26: 0 | AO26: 0 | AP26: 0 | AQ26: 0 | AR26: 0 | AS26: 0 | AT26: 0 | AU26: 0 | AV26: 0 | AW26: 0 | AX26: 0 | AY26: 0 | AZ26: 0 | BA26: 0 | BB26: 0 | BC26: 0 | BD26: 0 | BE26: 0 | BF26: 0 | BG26: 0 | BH26: 0 | BI26: 0 | BJ26: 0 | BK26: 0 | BL26: 0 | BM26: 0 | BN26: 0 | BO26: 0 | BP26: 0 | BQ26: 0 | BR26: 0 | BS26: 0 | BT26: 0 | BU26: 0 | BV26: 0 | BW26: 0
A27: 45328 | B27: 15:29:00 | C27: 15:29:00 | D27: 15:29:00 | E27: 15:29:00 | F27: 0 | G27: 0 | H27: 0 | I27: 0 | J27: 0 | K27: 0 | L27: 0 | M27: 0 | N27: 0 | O27: 0 | P27: 0 | Q27: 0 | R27: 0 | S27: 0 | T27: 0 | U27: 0 | V27: 0 | W27: 0 | X27: 0 | Y27: 0 | Z27: 0 | AA27: 0 | AB27: 0 | AC27: 0 | AD27: 0 | AE27: 0 | AF27: 0 | AG27: 0 | AH27: 0 | AI27: 0 | AJ27: 15:29:00 | AK27: 15:29:00 | AL27: 15:29:00 | AM27: 15:29:00 | AN27: 0 | AO27: 0 | AP27: 0 | AQ27: 0 | AR27: 0 | AS27: 0 | AT27: 0 | AU27: 0 | AV27: 0 | AW27: 0 | AX27: 0 | AY27: 0 | AZ27: 0 | BA27: 0 | BB27: 0 | BC27: 0 | BD27: 0 | BE27: 0 | BF27: 0 | BG27: 0 | BH27: 0 | BI27: 0 | BJ27: 0 | BK27: 0 | BL27: 0 | BM27: 0 | BN27: 0 | BO27: 0 | BP27: 0 | BQ27: 0 | BR27: 0 | BS27: 0 | BT27: 0 | BU27: 0 | BV27: 0 | BW27: 0
A28: 45329 | B28: 15:29:00 | C28: 15:29:00 | D28: 15:29:00 | E28: 15:29:00 | F28: 0 | G28: 0 | H28: 0 | I28: 0 | J28: 0 | K28: 0 | L28: 0 | M28: 0 | N28: 0 | O28: 0 | P28: 0 | Q28: 0 | R28: 0 | S28: 0 | T28: 0 | U28: 0 | V28: 0 | W28: 0 | X28: 0 | Y28: 0 | Z28: 0 | AA28: 0 | AB28: 0 | AC28: 0 | AD28: 0 | AE28: 0 | AF28: 0 | AG28: 0 | AH28: 0 | AI28: 0 | AJ28: 15:29:00 | AK28: 15:29:00 | AL28: 15:29:00 | AM28: 15:29:00 | AN28: 0 | AO28: 0 | AP28: 0 | AQ28: 0 | AR28: 0 | AS28: 0 | AT28: 0 | AU28: 0 | AV28: 0 | AW28: 0 | AX28: 0 | AY28: 0 | AZ28: 0 | BA28: 0 | BB28: 0 | BC28: 0 | BD28: 0 | BE28: 0 | BF28: 0 | BG28: 0 | BH28: 0 | BI28: 0 | BJ28: 0 | BK28: 0 | BL28: 0 | BM28: 0 | BN28: 0 | BO28: 0 | BP28: 0 | BQ28: 0 | BR28: 0 | BS28: 0 | BT28: 0 | BU28: 0 | BV28: 0 | BW28: 0
A29: 45330 | B29: 15:29:00 | C29: 15:29:00 | D29: 15:29:00 | E29: 15:29:00 | F29: 11:02:00 | G29: 11:02:00 | H29: 11:02:00 | I29: 11:02:00 | J29: 11:02:00 | K29: 11:02:00 | L29: 11:02:00 | M29: 11:02:00 | N29: 11:02:00 | O29: 11:02:00 | P29: 11:02:00 | Q29: 11:02:00 | R29: 11:02:00 | S29: 11:02:00 | T29: 11:02:00 | U29: 11:02:00 | V29: 11:02:00 | W29: 11:02:00 | X29: 11:02:00 | Y29: 11:02:00 | Z29: 11:02:00 | AA29: 11:02:00 | AB29: 11:02:00 | AC29: 11:02:00 | AD29: 11:02:00 | AE29: 11:02:00 | AF29: 11:02:00 | AG29: 11:02:00 | AH29: 11:02:00 | AI29: 11:02:00 | AJ29: 0 | AK29: 0 | AL29: 0 | AM29: 15:29:00 | AN29: 15:29:00 | AO29: 15:29:00 | AP29: 15:29:00 | AQ29: 0 | AR29: 0 | AS29: 0 | AT29: 0 | AU29: 0 | AV29: 0 | AW29: 0 | AX29: 0 | AY29: 0 | AZ29: 0 | BA29: 0 | BB29: 0 | BC29: 0 | BD29: 0 | BE29: 0 | BF29: 0 | BG29: 0 | BH29: 0 | BI29: 0 | BJ29: 0 | BK29: 0 | BL29: 0 | BM29: 0 | BN29: 0 | BO29: 0 | BP29: 0 | BQ29: 0 | BR29: 0 | BS29: 0 | BT29: 0 | BU29: 15:29:00 | BV29: 11:02:00 | BW29: 11:03:00
A30: 45331 | B30: 15:29:00 | C30: 0 | D30: 0 | E30: 0 | F30: 0 | G30: 0 | H30: 0 | I30: 0 | J30: 0 | K30: 0 | L30: 0 | M30: 0 | N30: 0 | O30: 0 | P30: 0 | Q30: 0 | R30: 0 | S30: 0 | T30: 0 | U30: 0 | V30: 0 | W30: 0 | X30: 0 | Y30: 0 | Z30: 0 | AA30: 0 | AB30: 0 | AC30: 0 | AD30: 0 | AE30: 0 | AF30: 0 | AG30: 0 | AH30: 0 | AI30: 0 | AJ30: 0 | AK30: 0 | AL30: 0 | AM30: 15:29:00 | AN30: 15:29:00 | AO30: 15:29:00 | AP30: 15:29:00 | AQ30: 09:21:00 | AR30: 09:21:00 | AS30: 09:21:00 | AT30: 15:29:00 | AU30: 15:29:00 | AV30: 15:29:00 | AW30: 15:29:00 | AX30: 15:29:00 | AY30: 15:29:00 | AZ30: 15:29:00 | BA30: 09:21:00 | BB30: 09:21:00 | BC30: 09:21:00 | BD30: 15:29:00 | BE30: 15:29:00 | BF30: 15:29:00 | BG30: 15:29:00 | BH30: 15:29:00 | BI30: 15:29:00 | BJ30: 15:29:00 | BK30: 15:29:00 | BL30: 15:29:00 | BM30: 15:29:00 | BN30: 15:29:00 | BO30: 15:29:00 | BP30: 15:29:00 | BQ30: 15:29:00 | BR30: 15:29:00 | BS30: 15:29:00 | BT30: 15:29:00 | BU30: 0 | BV30: 0 | BW30: 0
A31: 45334 | B31: 15:29:00 | C31: 0 | D31: 0 | E31: 0 | F31: 0 | G31: 0 | H31: 0 | I31: 0 | J31: 0 | K31: 0 | L31: 0 | M31: 0 | N31: 0 | O31: 0 | P31: 0 | Q31: 0 | R31: 0 | S31: 0 | T31: 0 | U31: 0 | V31: 0 | W31: 0 | X31: 0 | Y31: 0 | Z31: 0 | AA31: 0 | AB31: 0 | AC31: 0 | AD31: 0 | AE31: 0 | AF31: 0 | AG31: 0 | AH31: 0 | AI31: 0 | AJ31: 0 | AK31: 0 | AL31: 0 | AM31: 15:29:00 | AN31: 0 | AO31: 0 | AP31: 0 | AQ31: 0 | AR31: 0 | AS31: 0 | AT31: 0 | AU31: 0 | AV31: 0 | AW31: 0 | AX31: 0 | AY31: 0 | AZ31: 0 | BA31: 0 | BB31: 0 | BC31: 0 | BD31: 0 | BE31: 0 | BF31: 0 | BG31: 0 | BH31: 0 | BI31: 0 | BJ31: 0 | BK31: 0 | BL31: 0 | BM31: 0 | BN31: 0 | BO31: 0 | BP31: 0 | BQ31: 0 | BR31: 0 | BS31: 0 | BT31: 0 | BU31: 0 | BV31: 0 | BW31: 0
A32: 45335 | B32: 15:29:00 | C32: 15:29:00 | D32: 15:29:00 | E32: 15:29:00 | F32: 0 | G32: 0 | H32: 0 | I32: 0 | J32: 0 | K32: 0 | L32: 0 | M32: 0 | N32: 0 | O32: 0 | P32: 0 | Q32: 0 | R32: 0 | S32: 0 | T32: 0 | U32: 0 | V32: 0 | W32: 0 | X32: 0 | Y32: 0 | Z32: 0 | AA32: 0 | AB32: 0 | AC32: 0 | AD32: 0 | AE32: 0 | AF32: 0 | AG32: 0 | AH32: 0 | AI32: 0 | AJ32: 15:29:00 | AK32: 15:29:00 | AL32: 15:29:00 | AM32: 15:29:00 | AN32: 0 | AO32: 0 | AP32: 0 | AQ32: 0 | AR32: 0 | AS32: 0 | AT32: 0 | AU32: 0 | AV32: 0 | AW32: 0 | AX32: 0 | AY32: 0 | AZ32: 0 | BA32: 0 | BB32: 0 | BC32: 0 | BD32: 0 | BE32: 0 | BF32: 0 | BG32: 0 | BH32: 0 | BI32: 0 | BJ32: 0 | BK32: 0 | BL32: 0 | BM32: 0 | BN32: 0 | BO32: 0 | BP32: 0 | BQ32: 0 | BR32: 0 | BS32: 0 | BT32: 0 | BU32: 0 | BV32: 0 | BW32: 0
A33: 45336 | B33: 15:29:00 | C33: 15:29:00 | D33: 15:29:00 | E33: 15:29:00 | F33: 0 | G33: 0 | H33: 0 | I33: 0 | J33: 0 | K33: 0 | L33: 0 | M33: 0 | N33: 0 | O33: 0 | P33: 0 | Q33: 0 | R33: 0 | S33: 0 | T33: 0 | U33: 0 | V33: 0 | W33: 0 | X33: 0 | Y33: 0 | Z33: 0 | AA33: 0 | AB33: 0 | AC33: 0 | AD33: 0 | AE33: 0 | AF33: 0 | AG33: 0 | AH33: 0 | AI33: 0 | AJ33: 15:29:00 | AK33: 14:24:00 | AL33: 15:29:00 | AM33: 15:29:00 | AN33: 0 | AO33: 0 | AP33: 0 | AQ33: 0 | AR33: 0 | AS33: 0 | AT33: 0 | AU33: 0 | AV33: 0 | AW33: 0 | AX33: 0 | AY33: 0 | AZ33: 0 | BA33: 0 | BB33: 0 | BC33: 0 | BD33: 0 | BE33: 0 | BF33: 0 | BG33: 0 | BH33: 0 | BI33: 0 | BJ33: 0 | BK33: 0 | BL33: 0 | BM33: 0 | BN33: 0 | BO33: 0 | BP33: 0 | BQ33: 0 | BR33: 0 | BS33: 0 | BT33: 0 | BU33: 0 | BV33: 0 | BW33: 0
A34: 45337 | B34: 15:29:00 | C34: 15:29:00 | D34: 15:29:00 | E34: 15:29:00 | F34: 15:29:00 | G34: 15:29:00 | H34: 15:29:00 | I34: 15:29:00 | J34: 15:29:00 | K34: 15:29:00 | L34: 15:29:00 | M34: 15:29:00 | N34: 15:29:00 | O34: 15:29:00 | P34: 15:29:00 | Q34: 15:29:00 | R34: 15:29:00 | S34: 15:29:00 | T34: 15:29:00 | U34: 15:29:00 | V34: 15:29:00 | W34: 15:29:00 | X34: 15:29:00 | Y34: 15:29:00 | Z34: 10:07:00 | AA34: 10:07:00 | AB34: 09:59:00 | AC34: 09:59:00 | AD34: 10:07:00 | AE34: 10:01:00 | AF34: 15:29:00 | AG34: 10:07:00 | AH34: 15:29:00 | AI34: 15:29:00 | AJ34: 0 | AK34: 0 | AL34: 0 | AM34: 15:29:00 | AN34: 15:29:00 | AO34: 15:29:00 | AP34: 15:29:00 | AQ34: 0 | AR34: 0 | AS34: 0 | AT34: 0 | AU34: 0 | AV34: 0 | AW34: 0 | AX34: 0 | AY34: 0 | AZ34: 0 | BA34: 0 | BB34: 0 | BC34: 0 | BD34: 0 | BE34: 0 | BF34: 0 | BG34: 0 | BH34: 0 | BI34: 0 | BJ34: 0 | BK34: 0 | BL34: 0 | BM34: 0 | BN34: 0 | BO34: 0 | BP34: 0 | BQ34: 0 | BR34: 0 | BS34: 0 | BT34: 0 | BU34: 15:29:00 | BV34: 15:29:00 | BW34: 15:29:00
A35: 45338 | B35: 15:29:00 | C35: 0 | D35: 0 | E35: 0 | F35: 0 | G35: 0 | H35: 0 | I35: 0 | J35: 0 | K35: 0 | L35: 0 | M35: 0 | N35: 0 | O35: 0 | P35: 0 | Q35: 0 | R35: 0 | S35: 0 | T35: 0 | U35: 0 | V35: 0 | W35: 0 | X35: 0 | Y35: 0 | Z35: 0 | AA35: 0 | AB35: 0 | AC35: 0 | AD35: 0 | AE35: 0 | AF35: 0 | AG35: 0 | AH35: 0 | AI35: 0 | AJ35: 0 | AK35: 0 | AL35: 0 | AM35: 15:08:00 | AN35: 15:29:00 | AO35: 15:29:00 | AP35: 15:29:00 | AQ35: 15:29:00 | AR35: 15:29:00 | AS35: 15:29:00 | AT35: 15:29:00 | AU35: 15:29:00 | AV35: 15:29:00 | AW35: 15:29:00 | AX35: 15:29:00 | AY35: 15:29:00 | AZ35: 15:29:00 | BA35: 15:29:00 | BB35: 15:29:00 | BC35: 15:29:00 | BD35: 15:29:00 | BE35: 15:29:00 | BF35: 15:29:00 | BG35: 15:29:00 | BH35: 15:29:00 | BI35: 15:29:00 | BJ35: 15:29:00 | BK35: 15:29:00 | BL35: 15:29:00 | BM35: 15:29:00 | BN35: 15:29:00 | BO35: 15:29:00 | BP35: 15:29:00 | BQ35: 15:29:00 | BR35: 15:29:00 | BS35: 15:29:00 | BT35: 15:29:00 | BU35: 0 | BV35: 0 | BW35: 0
A36: 45341 | B36: 15:29:00 | C36: 0 | D36: 0 | E36: 0 | F36: 0 | G36: 0 | H36: 0 | I36: 0 | J36: 0 | K36: 0 | L36: 0 | M36: 0 | N36: 0 | O36: 0 | P36: 0 | Q36: 0 | R36: 0 | S36: 0 | T36: 0 | U36: 0 | V36: 0 | W36: 0 | X36: 0 | Y36: 0 | Z36: 0 | AA36: 0 | AB36: 0 | AC36: 0 | AD36: 0 | AE36: 0 | AF36: 0 | AG36: 0 | AH36: 0 | AI36: 0 | AJ36: 0 | AK36: 0 | AL36: 0 | AM36: 15:29:00 | AN36: 0 | AO36: 0 | AP36: 0 | AQ36: 0 | AR36: 0 | AS36: 0 | AT36: 0 | AU36: 0 | AV36: 0 | AW36: 0 | AX36: 0 | AY36: 0 | AZ36: 0 | BA36: 0 | BB36: 0 | BC36: 0 | BD36: 0 | BE36: 0 | BF36: 0 | BG36: 0 | BH36: 0 | BI36: 0 | BJ36: 0 | BK36: 0 | BL36: 0 | BM36: 0 | BN36: 0 | BO36: 0 | BP36: 0 | BQ36: 0 | BR36: 0 | BS36: 0 | BT36: 0 | BU36: 0 | BV36: 0 | BW36: 0
A37: 45342 | B37: 15:29:00 | C37: 15:29:00 | D37: 15:29:00 | E37: 15:29:00 | F37: 0 | G37: 0 | H37: 0 | I37: 0 | J37: 0 | K37: 0 | L37: 0 | M37: 0 | N37: 0 | O37: 0 | P37: 0 | Q37: 0 | R37: 0 | S37: 0 | T37: 0 | U37: 0 | V37: 0 | W37: 0 | X37: 0 | Y37: 0 | Z37: 0 | AA37: 0 | AB37: 0 | AC37: 0 | AD37: 0 | AE37: 0 | AF37: 0 | AG37: 0 | AH37: 0 | AI37: 0 | AJ37: 15:29:00 | AK37: 15:29:00 | AL37: 15:29:00 | AM37: 15:29:00 | AN37: 0 | AO37: 0 | AP37: 0 | AQ37: 0 | AR37: 0 | AS37: 0 | AT37: 0 | AU37: 0 | AV37: 0 | AW37: 0 | AX37: 0 | AY37: 0 | AZ37: 0 | BA37: 0 | BB37: 0 | BC37: 0 | BD37: 0 | BE37: 0 | BF37: 0 | BG37: 0 | BH37: 0 | BI37: 0 | BJ37: 0 | BK37: 0 | BL37: 0 | BM37: 0 | BN37: 0 | BO37: 0 | BP37: 0 | BQ37: 0 | BR37: 0 | BS37: 0 | BT37: 0 | BU37: 0 | BV37: 0 | BW37: 0
A38: 45343 | B38: 15:29:00 | C38: 15:29:00 | D38: 15:29:00 | E38: 15:29:00 | F38: 0 | G38: 0 | H38: 0 | I38: 0 | J38: 0 | K38: 0 | L38: 0 | M38: 0 | N38: 0 | O38: 0 | P38: 0 | Q38: 0 | R38: 0 | S38: 0 | T38: 0 | U38: 0 | V38: 0 | W38: 0 | X38: 0 | Y38: 0 | Z38: 0 | AA38: 0 | AB38: 0 | AC38: 0 | AD38: 0 | AE38: 0 | AF38: 0 | AG38: 0 | AH38: 0 | AI38: 0 | AJ38: 15:29:00 | AK38: 14:40:00 | AL38: 15:29:00 | AM38: 15:29:00 | AN38: 0 | AO38: 0 | AP38: 0 | AQ38: 0 | AR38: 0 | AS38: 0 | AT38: 0 | AU38: 0 | AV38: 0 | AW38: 0 | AX38: 0 | AY38: 0 | AZ38: 0 | BA38: 0 | BB38: 0 | BC38: 0 | BD38: 0 | BE38: 0 | BF38: 0 | BG38: 0 | BH38: 0 | BI38: 0 | BJ38: 0 | BK38: 0 | BL38: 0 | BM38: 0 | BN38: 0 | BO38: 0 | BP38: 0 | BQ38: 0 | BR38: 0 | BS38: 0 | BT38: 0 | BU38: 0 | BV38: 0 | BW38: 0
A39: 45344 | B39: 15:29:00 | C39: 15:29:00 | D39: 15:29:00 | E39: 15:29:00 | F39: 10:00:00 | G39: 10:00:00 | H39: 10:00:00 | I39: 10:00:00 | J39: 10:00:00 | K39: 10:01:00 | L39: 10:01:00 | M39: 10:05:00 | N39: 15:29:00 | O39: 15:29:00 | P39: 10:00:00 | Q39: 10:00:00 | R39: 10:00:00 | S39: 10:00:00 | T39: 10:00:00 | U39: 10:01:00 | V39: 10:01:00 | W39: 10:05:00 | X39: 15:29:00 | Y39: 15:29:00 | Z39: 09:59:00 | AA39: 09:59:00 | AB39: 10:05:00 | AC39: 10:05:00 | AD39: 10:05:00 | AE39: 10:05:00 | AF39: 10:05:00 | AG39: 15:29:00 | AH39: 15:29:00 | AI39: 15:29:00 | AJ39: 0 | AK39: 0 | AL39: 0 | AM39: 15:29:00 | AN39: 15:29:00 | AO39: 15:29:00 | AP39: 15:29:00 | AQ39: 0 | AR39: 0 | AS39: 0 | AT39: 0 | AU39: 0 | AV39: 0 | AW39: 0 | AX39: 0 | AY39: 0 | AZ39: 0 | BA39: 0 | BB39: 0 | BC39: 0 | BD39: 0 | BE39: 0 | BF39: 0 | BG39: 0 | BH39: 0 | BI39: 0 | BJ39: 0 | BK39: 0 | BL39: 0 | BM39: 0 | BN39: 0 | BO39: 0 | BP39: 0 | BQ39: 0 | BR39: 0 | BS39: 0 | BT39: 0 | BU39: 15:29:00 | BV39: 15:29:00 | BW39: 15:29:00
A40: 45345 | B40: 15:29:00 | C40: 0 | D40: 0 | E40: 0 | F40: 0 | G40: 0 | H40: 0 | I40: 0 | J40: 0 | K40: 0 | L40: 0 | M40: 0 | N40: 0 | O40: 0 | P40: 0 | Q40: 0 | R40: 0 | S40: 0 | T40: 0 | U40: 0 | V40: 0 | W40: 0 | X40: 0 | Y40: 0 | Z40: 0 | AA40: 0 | AB40: 0 | AC40: 0 | AD40: 0 | AE40: 0 | AF40: 0 | AG40: 0 | AH40: 0 | AI40: 0 | AJ40: 0 | AK40: 0 | AL40: 0 | AM40: 15:29:00 | AN40: 15:29:00 | AO40: 15:29:00 | AP40: 15:29:00 | AQ40: 15:29:00 | AR40: 15:29:00 | AS40: 15:29:00 | AT40: 15:29:00 | AU40: 15:29:00 | AV40: 15:29:00 | AW40: 15:29:00 | AX40: 15:29:00 | AY40: 15:29:00 | AZ40: 15:29:00 | BA40: 15:29:00 | BB40: 15:29:00 | BC40: 15:29:00 | BD40: 15:29:00 | BE40: 15:29:00 | BF40: 15:29:00 | BG40: 15:29:00 | BH40: 15:29:00 | BI40: 15:29:00 | BJ40: 15:29:00 | BK40: 15:29:00 | BL40: 15:29:00 | BM40: 15:29:00 | BN40: 15:29:00 | BO40: 15:29:00 | BP40: 15:29:00 | BQ40: 15:29:00 | BR40: 15:29:00 | BS40: 15:29:00 | BT40: 15:29:00 | BU40: 0 | BV40: 0 | BW40: 0
...

Sheet StgWiseDD
A1: Date | B1: Day | C1: NF DTE | D1: SX DTE | E1: NF NRE_CC_1 | F1: DD NF NRE_CC_1 | G1: NF NRE_CC_2 | H1: DD NF NRE_CC_2 | I1: NF NRE_CC_3 | J1: DD NF NRE_CC_3 | K1: NF SRE_PREMIUM_SHIFT_1 | L1: DD NF SRE_PREMIUM_SHIFT_1 | M1: NF SRE_PREMIUM_SHIFT_2 | N1: DD NF SRE_PREMIUM_SHIFT_2 | O1: NF SRE_PREMIUM_SHIFT_3 | P1: DD NF SRE_PREMIUM_SHIFT_3 | Q1: NF SRE_PREMIUM_SHIFT_4 | R1: DD NF SRE_PREMIUM_SHIFT_4 | S1: NF SRE_PREMIUM_SHIFT_5 | T1: DD NF SRE_PREMIUM_SHIFT_5 | U1: NF SRE_PREMIUM_SHIFT_6 | V1: DD NF SRE_PREMIUM_SHIFT_6 | W1: NF SRE_PREMIUM_SHIFT_7 | X1: DD NF SRE_PREMIUM_SHIFT_7 | Y1: NF SRE_PREMIUM_SHIFT_8 | Z1: DD NF SRE_PREMIUM_SHIFT_8 | AA1: NF SRE_PREMIUM_SHIFT_9 | AB1: DD NF SRE_PREMIUM_SHIFT_9 | AC1: NF SRE_PREMIUM_SHIFT_10 | AD1: DD NF SRE_PREMIUM_SHIFT_10 | AE1: NF SRE_PREMIUM_SHIFT_11 | AF1: DD NF SRE_PREMIUM_SHIFT_11 | AG1: NF SRE_PREMIUM_SHIFT_12 | AH1: DD NF SRE_PREMIUM_SHIFT_12 | AI1: NF SRE_PREMIUM_SHIFT_13 | AJ1: DD NF SRE_PREMIUM_SHIFT_13 | AK1: NF SRE_PREMIUM_SHIFT_14 | AL1: DD NF SRE_PREMIUM_SHIFT_14 | AM1: NF SRE_PREMIUM_SHIFT_15 | AN1: DD NF SRE_PREMIUM_SHIFT_15 | AO1: NF SRE_PREMIUM_SHIFT_16 | AP1: DD NF SRE_PREMIUM_SHIFT_16 | AQ1: NF SRE_PREMIUM_SHIFT_17 | AR1: DD NF SRE_PREMIUM_SHIFT_17 | AS1: NF SRE_PREMIUM_SHIFT_18 | AT1: DD NF SRE_PREMIUM_SHIFT_18 | AU1: NF SRE_PREMIUM_SHIFT_19 | AV1: DD NF SRE_PREMIUM_SHIFT_19 | AW1: NF SRE_PREMIUM_SHIFT_20 | AX1: DD NF SRE_PREMIUM_SHIFT_20 | AY1: NF SRE_PREMIUM_SHIFT_21 | AZ1: DD NF SRE_PREMIUM_SHIFT_21 | BA1: NF SRE_PREMIUM_SHIFT_22 | BB1: DD NF SRE_PREMIUM_SHIFT_22 | BC1: NF SRE_PREMIUM_SHIFT_23 | BD1: DD NF SRE_PREMIUM_SHIFT_23 | BE1: NF SRE_PREMIUM_SHIFT_24 | BF1: DD NF SRE_PREMIUM_SHIFT_24 | BG1: NF SRE_PREMIUM_SHIFT_25 | BH1: DD NF SRE_PREMIUM_SHIFT_25 | BI1: NF SRE_PREMIUM_SHIFT_26 | BJ1: DD NF SRE_PREMIUM_SHIFT_26 | BK1: NF SRE_PREMIUM_SHIFT_27 | BL1: DD NF SRE_PREMIUM_SHIFT_27 | BM1: NF SRE_PREMIUM_SHIFT_28 | BN1: DD NF SRE_PREMIUM_SHIFT_28 | BO1: NF SRE_PREMIUM_SHIFT_29 | BP1: DD NF SRE_PREMIUM_SHIFT_29 | BQ1: NF SRE_PREMIUM_SHIFT_30 | BR1: DD NF SRE_PREMIUM_SHIFT_30 | BS1: NF SRE_SEPARATE_LEG_SL_1 | BT1: DD NF SRE_SEPARATE_LEG_SL_1 | BU1: NF SRE_SEPARATE_LEG_SL_2 | BV1: DD NF SRE_SEPARATE_LEG_SL_2 | BW1: NF SRE_SEPARATE_LEG_SL_3 | BX1: DD NF SRE_SEPARATE_LEG_SL_3 | BY1: SX NRE_CC_1 | BZ1: DD SX NRE_CC_1 | CA1: SX NRE_CC_2 | CB1: DD SX NRE_CC_2 | CC1: SX NRE_CC_3 | CD1: DD SX NRE_CC_3 | CE1: SX SRE_PREMIUM_SHIFT_1 | CF1: DD SX SRE_PREMIUM_SHIFT_1 | CG1: SX SRE_PREMIUM_SHIFT_2 | CH1: DD SX SRE_PREMIUM_SHIFT_2 | CI1: SX SRE_PREMIUM_SHIFT_3 | CJ1: DD SX SRE_PREMIUM_SHIFT_3 | CK1: SX SRE_PREMIUM_SHIFT_4 | CL1: DD SX SRE_PREMIUM_SHIFT_4 | CM1: SX SRE_PREMIUM_SHIFT_5 | CN1: DD SX SRE_PREMIUM_SHIFT_5 | CO1: SX SRE_PREMIUM_SHIFT_6 | CP1: DD SX SRE_PREMIUM_SHIFT_6 | CQ1: SX SRE_PREMIUM_SHIFT_7 | CR1: DD SX SRE_PREMIUM_SHIFT_7 | CS1: SX SRE_PREMIUM_SHIFT_8 | CT1: DD SX SRE_PREMIUM_SHIFT_8 | CU1: SX SRE_PREMIUM_SHIFT_9 | CV1: DD SX SRE_PREMIUM_SHIFT_9 | CW1: SX SRE_PREMIUM_SHIFT_10 | CX1: DD SX SRE_PREMIUM_SHIFT_10 | CY1: SX SRE_PREMIUM_SHIFT_11 | CZ1: DD SX SRE_PREMIUM_SHIFT_11 | DA1: SX SRE_PREMIUM_SHIFT_12 | DB1: DD SX SRE_PREMIUM_SHIFT_12 | DC1: SX SRE_PREMIUM_SHIFT_13 | DD1: DD SX SRE_PREMIUM_SHIFT_13 | DE1: SX SRE_PREMIUM_SHIFT_14 | DF1: DD SX SRE_PREMIUM_SHIFT_14 | DG1: SX SRE_PREMIUM_SHIFT_15 | DH1: DD SX SRE_PREMIUM_SHIFT_15 | DI1: SX SRE_PREMIUM_SHIFT_16 | DJ1: DD SX SRE_PREMIUM_SHIFT_16 | DK1: SX SRE_PREMIUM_SHIFT_17 | DL1: DD SX SRE_PREMIUM_SHIFT_17 | DM1: SX SRE_PREMIUM_SHIFT_18 | DN1: DD SX SRE_PREMIUM_SHIFT_18 | DO1: SX SRE_PREMIUM_SHIFT_19 | DP1: DD SX SRE_PREMIUM_SHIFT_19 | DQ1: SX SRE_PREMIUM_SHIFT_20 | DR1: DD SX SRE_PREMIUM_SHIFT_20 | DS1: SX SRE_PREMIUM_SHIFT_21 | DT1: DD SX SRE_PREMIUM_SHIFT_21 | DU1: SX SRE_PREMIUM_SHIFT_22 | DV1: DD SX SRE_PREMIUM_SHIFT_22 | DW1: SX SRE_PREMIUM_SHIFT_23 | DX1: DD SX SRE_PREMIUM_SHIFT_23 | DY1: SX SRE_PREMIUM_SHIFT_24 | DZ1: DD SX SRE_PREMIUM_SHIFT_24 | EA1: SX SRE_PREMIUM_SHIFT_25 | EB1: DD SX SRE_PREMIUM_SHIFT_25 | EC1: SX SRE_PREMIUM_SHIFT_26 | ED1: DD SX SRE_PREMIUM_SHIFT_26 | EE1: SX SRE_PREMIUM_SHIFT_27 | EF1: DD SX SRE_PREMIUM_SHIFT_27 | EG1: SX SRE_PREMIUM_SHIFT_28 | EH1: DD SX SRE_PREMIUM_SHIFT_28 | EI1: SX SRE_PREMIUM_SHIFT_29 | EJ1: DD SX SRE_PREMIUM_SHIFT_29 | EK1: SX SRE_PREMIUM_SHIFT_30 | EL1: DD SX SRE_PREMIUM_SHIFT_30 | EM1: SX SRE_SEPARATE_LEG_SL_1 | EN1: DD SX SRE_SEPARATE_LEG_SL_1 | EO1: SX SRE_SEPARATE_LEG_SL_2 | EP1: DD SX SRE_SEPARATE_LEG_SL_2 | EQ1: SX SRE_SEPARATE_LEG_SL_3 | ER1: DD SX SRE_SEPARATE_LEG_SL_3
A2: 45292 | B2: Monday | C2: 4 | D2: 5 | E2: 0 | F2: =IF(E2 < 0, E2, 0) -> 0 | G2: 0 | H2: =IF(G2 < 0, G2, 0) -> 0 | I2: 0 | J2: =IF(I2 < 0, I2, 0) -> 0 | K2: 0 | L2: =IF(K2 < 0, K2, 0) -> 0 | M2: 0 | N2: =IF(M2 < 0, M2, 0) -> 0 | O2: 0 | P2: =IF(O2 < 0, O2, 0) -> 0 | Q2: 0 | R2: =IF(Q2 < 0, Q2, 0) -> 0 | S2: 0 | T2: =IF(S2 < 0, S2, 0) -> 0 | U2: 0 | V2: =IF(U2 < 0, U2, 0) -> 0 | W2: 0 | X2: =IF(W2 < 0, W2, 0) -> 0 | Y2: 0 | Z2: =IF(Y2 < 0, Y2, 0) -> 0 | AA2: 0 | AB2: =IF(AA2 < 0, AA2, 0) -> 0 | AC2: 0 | AD2: =IF(AC2 < 0, AC2, 0) -> 0 | AE2: 0 | AF2: =IF(AE2 < 0, AE2, 0) -> 0 | AG2: 0 | AH2: =IF(AG2 < 0, AG2, 0) -> 0 | AI2: 0 | AJ2: =IF(AI2 < 0, AI2, 0) -> 0 | AK2: 0 | AL2: =IF(AK2 < 0, AK2, 0) -> 0 | AM2: 0 | AN2: =IF(AM2 < 0, AM2, 0) -> 0 | AO2: 0 | AP2: =IF(AO2 < 0, AO2, 0) -> 0 | AQ2: 0 | AR2: =IF(AQ2 < 0, AQ2, 0) -> 0 | AS2: 0 | AT2: =IF(AS2 < 0, AS2, 0) -> 0 | AU2: 0 | AV2: =IF(AU2 < 0, AU2, 0) -> 0 | AW2: 0 | AX2: =IF(AW2 < 0, AW2, 0) -> 0 | AY2: 0 | AZ2: =IF(AY2 < 0, AY2, 0) -> 0 | BA2: 0 | BB2: =IF(BA2 < 0, BA2, 0) -> 0 | BC2: 0 | BD2: =IF(BC2 < 0, BC2, 0) -> 0 | BE2: 0 | BF2: =IF(BE2 < 0, BE2, 0) -> 0 | BG2: 0 | BH2: =IF(BG2 < 0, BG2, 0) -> 0 | BI2: 0 | BJ2: =IF(BI2 < 0, BI2, 0) -> 0 | BK2: 0 | BL2: =IF(BK2 < 0, BK2, 0) -> 0 | BM2: 0 | BN2: =IF(BM2 < 0, BM2, 0) -> 0 | BO2: 0 | BP2: =IF(BO2 < 0, BO2, 0) -> 0 | BQ2: 0 | BR2: =IF(BQ2 < 0, BQ2, 0) -> 0 | BS2: 0 | BT2: =IF(BS2 < 0, BS2, 0) -> 0 | BU2: 0 | BV2: =IF(BU2 < 0, BU2, 0) -> 0 | BW2: 0 | BX2: =IF(BW2 < 0, BW2, 0) -> 0 | BY2: 0 | BZ2: =IF(BY2 < 0, BY2, 0) -> 0 | CA2: 0 | CB2: =IF(CA2 < 0, CA2, 0) -> 0 | CC2: 0 | CD2: =IF(CC2 < 0, CC2, 0) -> 0 | CE2: 0 | CF2: =IF(CE2 < 0, CE2, 0) -> 0 | CG2: 0 | CH2: =IF(CG2 < 0, CG2, 0) -> 0 | CI2: 0 | CJ2: =IF(CI2 < 0, CI2, 0) -> 0 | CK2: 0 | CL2: =IF(CK2 < 0, CK2, 0) -> 0 | CM2: 0 | CN2: =IF(CM2 < 0, CM2, 0) -> 0 | CO2: 0 | CP2: =IF(CO2 < 0, CO2, 0) -> 0 | CQ2: 0 | CR2: =IF(CQ2 < 0, CQ2, 0) -> 0 | CS2: 0 | CT2: =IF(CS2 < 0, CS2, 0) -> 0 | CU2: 0 | CV2: =IF(CU2 < 0, CU2, 0) -> 0 | CW2: 0 | CX2: =IF(CW2 < 0, CW2, 0) -> 0 | CY2: 0 | CZ2: =IF(CY2 < 0, CY2, 0) -> 0 | DA2: 0 | DB2: =IF(DA2 < 0, DA2, 0) -> 0 | DC2: 0 | DD2: =IF(DC2 < 0, DC2, 0) -> 0 | DE2: 0 | DF2: =IF(DE2 < 0, DE2, 0) -> 0 | DG2: 0 | DH2: =IF(DG2 < 0, DG2, 0) -> 0 | DI2: 0 | DJ2: =IF(DI2 < 0, DI2, 0) -> 0 | DK2: 0 | DL2: =IF(DK2 < 0, DK2, 0) -> 0 | DM2: 0 | DN2: =IF(DM2 < 0, DM2, 0) -> 0 | DO2: 0 | DP2: =IF(DO2 < 0, DO2, 0) -> 0 | DQ2: 0 | DR2: =IF(DQ2 < 0, DQ2, 0) -> 0 | DS2: 0 | DT2: =IF(DS2 < 0, DS2, 0) -> 0 | DU2: 0 | DV2: =IF(DU2 < 0, DU2, 0) -> 0 | DW2: 0 | DX2: =IF(DW2 < 0, DW2, 0) -> 0 | DY2: 0 | DZ2: =IF(DY2 < 0, DY2, 0) -> 0 | EA2: 0 | EB2: =IF(EA2 < 0, EA2, 0) -> 0 | EC2: 0 | ED2: =IF(EC2 < 0, EC2, 0) -> 0 | EE2: 0 | EF2: =IF(EE2 < 0, EE2, 0) -> 0 | EG2: 0 | EH2: =IF(EG2 < 0, EG2, 0) -> 0 | EI2: 0 | EJ2: =IF(EI2 < 0, EI2, 0) -> 0 | EK2: 0 | EL2: =IF(EK2 < 0, EK2, 0) -> 0 | EM2: 0 | EN2: =IF(EM2 < 0, EM2, 0) -> 0 | EO2: 0 | EP2: =IF(EO2 < 0, EO2, 0) -> 0 | EQ2: 0 | ER2: =IF(EQ2 < 0, EQ2, 0) -> 0
A3: 45293 | B3: Tuesday | C3: 3 | D3: 4 | E3: 27719.818 | F3: =IF(E3 + F2 < 0, E3 + F2, 0) -> 0 | G3: 7586.2108 | H3: =IF(G3 + H2 < 0, G3 + H2, 0) -> 0 | I3: 179.48891 | J3: =IF(I3 + J2 < 0, I3 + J2, 0) -> 0 | K3: 0 | L3: =IF(K3 + L2 < 0, K3 + L2, 0) -> 0 | M3: 0 | N3: =IF(M3 + N2 < 0, M3 + N2, 0) -> 0 | O3: 0 | P3: =IF(O3 + P2 < 0, O3 + P2, 0) -> 0 | Q3: 0 | R3: =IF(Q3 + R2 < 0, Q3 + R2, 0) -> 0 | S3: 0 | T3: =IF(S3 + T2 < 0, S3 + T2, 0) -> 0 | U3: 0 | V3: =IF(U3 + V2 < 0, U3 + V2, 0) -> 0 | W3: 0 | X3: =IF(W3 + X2 < 0, W3 + X2, 0) -> 0 | Y3: 0 | Z3: =IF(Y3 + Z2 < 0, Y3 + Z2, 0) -> 0 | AA3: 0 | AB3: =IF(AA3 + AB2 < 0, AA3 + AB2, 0) -> 0 | AC3: 0 | AD3: =IF(AC3 + AD2 < 0, AC3 + AD2, 0) -> 0 | AE3: 0 | AF3: =IF(AE3 + AF2 < 0, AE3 + AF2, 0) -> 0 | AG3: 0 | AH3: =IF(AG3 + AH2 < 0, AG3 + AH2, 0) -> 0 | AI3: 0 | AJ3: =IF(AI3 + AJ2 < 0, AI3 + AJ2, 0) -> 0 | AK3: 0 | AL3: =IF(AK3 + AL2 < 0, AK3 + AL2, 0) -> 0 | AM3: 0 | AN3: =IF(AM3 + AN2 < 0, AM3 + AN2, 0) -> 0 | AO3: 0 | AP3: =IF(AO3 + AP2 < 0, AO3 + AP2, 0) -> 0 | AQ3: 0 | AR3: =IF(AQ3 + AR2 < 0, AQ3 + AR2, 0) -> 0 | AS3: 0 | AT3: =IF(AS3 + AT2 < 0, AS3 + AT2, 0) -> 0 | AU3: 0 | AV3: =IF(AU3 + AV2 < 0, AU3 + AV2, 0) -> 0 | AW3: 0 | AX3: =IF(AW3 + AX2 < 0, AW3 + AX2, 0) -> 0 | AY3: 0 | AZ3: =IF(AY3 + AZ2 < 0, AY3 + AZ2, 0) -> 0 | BA3: 0 | BB3: =IF(BA3 + BB2 < 0, BA3 + BB2, 0) -> 0 | BC3: 0 | BD3: =IF(BC3 + BD2 < 0, BC3 + BD2, 0) -> 0 | BE3: 0 | BF3: =IF(BE3 + BF2 < 0, BE3 + BF2, 0) -> 0 | BG3: 0 | BH3: =IF(BG3 + BH2 < 0, BG3 + BH2, 0) -> 0 | BI3: 0 | BJ3: =IF(BI3 + BJ2 < 0, BI3 + BJ2, 0) -> 0 | BK3: 0 | BL3: =IF(BK3 + BL2 < 0, BK3 + BL2, 0) -> 0 | BM3: 0 | BN3: =IF(BM3 + BN2 < 0, BM3 + BN2, 0) -> 0 | BO3: 0 | BP3: =IF(BO3 + BP2 < 0, BO3 + BP2, 0) -> 0 | BQ3: 0 | BR3: =IF(BQ3 + BR2 < 0, BQ3 + BR2, 0) -> 0 | BS3: -206082.96 | BT3: =IF(BS3 + BT2 < 0, BS3 + BT2, 0) -> 0 | BU3: -203332.48 | BV3: =IF(BU3 + BV2 < 0, BU3 + BV2, 0) -> 0 | BW3: -198809.3 | BX3: =IF(BW3 + BX2 < 0, BW3 + BX2, 0) -> 0 | BY3: 0 | BZ3: =IF(BY3 + BZ2 < 0, BY3 + BZ2, 0) -> 0 | CA3: 0 | CB3: =IF(CA3 + CB2 < 0, CA3 + CB2, 0) -> 0 | CC3: 0 | CD3: =IF(CC3 + CD2 < 0, CC3 + CD2, 0) -> 0 | CE3: 0 | CF3: =IF(CE3 + CF2 < 0, CE3 + CF2, 0) -> 0 | CG3: 0 | CH3: =IF(CG3 + CH2 < 0, CG3 + CH2, 0) -> 0 | CI3: 0 | CJ3: =IF(CI3 + CJ2 < 0, CI3 + CJ2, 0) -> 0 | CK3: 0 | CL3: =IF(CK3 + CL2 < 0, CK3 + CL2, 0) -> 0 | CM3: 0 | CN3: =IF(CM3 + CN2 < 0, CM3 + CN2, 0) -> 0 | CO3: 0 | CP3: =IF(CO3 + CP2 < 0, CO3 + CP2, 0) -> 0 | CQ3: 0 | CR3: =IF(CQ3 + CR2 < 0, CQ3 + CR2, 0) -> 0 | CS3: 0 | CT3: =IF(CS3 + CT2 < 0, CS3 + CT2, 0) -> 0 | CU3: 0 | CV3: =IF(CU3 + CV2 < 0, CU3 + CV2, 0) -> 0 | CW3: 0 | CX3: =IF(CW3 + CX2 < 0, CW3 + CX2, 0) -> 0 | CY3: 0 | CZ3: =IF(CY3 + CZ2 < 0, CY3 + CZ2, 0) -> 0 | DA3: 0 | DB3: =IF(DA3 + DB2 < 0, DA3 + DB2, 0) -> 0 | DC3: 0 | DD3: =IF(DC3 + DD2 < 0, DC3 + DD2, 0) -> 0 | DE3: 0 | DF3: =IF(DE3 + DF2 < 0, DE3 + DF2, 0) -> 0 | DG3: 0 | DH3: =IF(DG3 + DH2 < 0, DG3 + DH2, 0) -> 0 | DI3: 0 | DJ3: =IF(DI3 + DJ2 < 0, DI3 + DJ2, 0) -> 0 | DK3: 0 | DL3: =IF(DK3 + DL2 < 0, DK3 + DL2, 0) -> 0 | DM3: 0 | DN3: =IF(DM3 + DN2 < 0, DM3 + DN2, 0) -> 0 | DO3: 0 | DP3: =IF(DO3 + DP2 < 0, DO3 + DP2, 0) -> 0 | DQ3: 0 | DR3: =IF(DQ3 + DR2 < 0, DQ3 + DR2, 0) -> 0 | DS3: 0 | DT3: =IF(DS3 + DT2 < 0, DS3 + DT2, 0) -> 0 | DU3: 0 | DV3: =IF(DU3 + DV2 < 0, DU3 + DV2, 0) -> 0 | DW3: 0 | DX3: =IF(DW3 + DX2 < 0, DW3 + DX2, 0) -> 0 | DY3: 0 | DZ3: =IF(DY3 + DZ2 < 0, DY3 + DZ2, 0) -> 0 | EA3: 0 | EB3: =IF(EA3 + EB2 < 0, EA3 + EB2, 0) -> 0 | EC3: 0 | ED3: =IF(EC3 + ED2 < 0, EC3 + ED2, 0) -> 0 | EE3: 0 | EF3: =IF(EE3 + EF2 < 0, EE3 + EF2, 0) -> 0 | EG3: 0 | EH3: =IF(EG3 + EH2 < 0, EG3 + EH2, 0) -> 0 | EI3: 0 | EJ3: =IF(EI3 + EJ2 < 0, EI3 + EJ2, 0) -> 0 | EK3: 0 | EL3: =IF(EK3 + EL2 < 0, EK3 + EL2, 0) -> 0 | EM3: 0 | EN3: =IF(EM3 + EN2 < 0, EM3 + EN2, 0) -> 0 | EO3: 0 | EP3: =IF(EO3 + EP2 < 0, EO3 + EP2, 0) -> 0 | EQ3: 0 | ER3: =IF(EQ3 + ER2 < 0, EQ3 + ER2, 0) -> 0
